2020-03-22 15:04:01,758 ERROR __main__ 2uml
Traceback (most recent call last):
  File "/Users/chenjiadong/Documents/funnyCode/PythonRepo/pyuml/main.py", line 82, in do_2uml
    dot_string = self._parse_to_dot(splitargs.Input)
  File "/Users/chenjiadong/Documents/funnyCode/PythonRepo/pyuml/main.py", line 136, in _parse_to_dot
    tree = ast3.parse(code_string)
  File "/Users/chenjiadong/Documents/funnyCode/PythonRepo/pyuml/venv/lib/python3.7/site-packages/typed_ast/ast3.py", line 62, in parse
    return _ast3._parse(source, filename, mode, feature_version)
TypeError: parse() arg 1 must be a string or bytes object
2020-03-22 15:05:53,564 ERROR __main__ 2uml_from_binary
Traceback (most recent call last):
  File "/Users/chenjiadong/Documents/funnyCode/PythonRepo/pyuml/main.py", line 117, in do_2uml_from_binary
    splitargs = parser.parse_args(shlex.split(args))
  File "/usr/local/Cellar/python/3.7.7/Frameworks/Python.framework/Versions/3.7/lib/python3.7/argparse.py", line 1755, in parse_args
    args, argv = self.parse_known_args(args, namespace)
  File "/usr/local/Cellar/python/3.7.7/Frameworks/Python.framework/Versions/3.7/lib/python3.7/argparse.py", line 1787, in parse_known_args
    namespace, args = self._parse_known_args(args, namespace)
  File "/usr/local/Cellar/python/3.7.7/Frameworks/Python.framework/Versions/3.7/lib/python3.7/argparse.py", line 2022, in _parse_known_args
    ', '.join(required_actions))
  File "/usr/local/Cellar/python/3.7.7/Frameworks/Python.framework/Versions/3.7/lib/python3.7/argparse.py", line 2508, in error
    self.exit(2, _('%(prog)s: error: %(message)s\n') % args)
  File "/usr/local/Cellar/python/3.7.7/Frameworks/Python.framework/Versions/3.7/lib/python3.7/argparse.py", line 2495, in exit
    _sys.exit(status)
SystemExit: 2
2020-03-22 15:06:54,387 ERROR __main__ 2uml
Traceback (most recent call last):
  File "/Users/chenjiadong/Documents/funnyCode/PythonRepo/pyuml/main.py", line 82, in do_2uml
    dot_string = self._parse_to_dot(splitargs.Input)
  File "/Users/chenjiadong/Documents/funnyCode/PythonRepo/pyuml/main.py", line 137, in _parse_to_dot
    tree = ast3.parse(code_string)
  File "/Users/chenjiadong/Documents/funnyCode/PythonRepo/pyuml/venv/lib/python3.7/site-packages/typed_ast/ast3.py", line 62, in parse
    return _ast3._parse(source, filename, mode, feature_version)
TypeError: parse() arg 1 must be a string or bytes object
2020-03-22 15:07:21,820 ERROR __main__ 2uml
Traceback (most recent call last):
  File "/Users/chenjiadong/Documents/funnyCode/PythonRepo/pyuml/main.py", line 82, in do_2uml
    dot_string = self._parse_to_dot(splitargs.Input)
  File "/Users/chenjiadong/Documents/funnyCode/PythonRepo/pyuml/main.py", line 136, in _parse_to_dot
    tree = ast3.parse(code_string)
  File "/Users/chenjiadong/Documents/funnyCode/PythonRepo/pyuml/venv/lib/python3.7/site-packages/typed_ast/ast3.py", line 62, in parse
    return _ast3._parse(source, filename, mode, feature_version)
TypeError: parse() arg 1 must be a string or bytes object
2020-03-22 15:09:35,015 DEBUG graphviz.files write 243 bytes to 'result/uml'
2020-03-22 15:09:35,016 DEBUG graphviz.backend run ['dot', '-Tpng', '-O', 'uml']
2020-03-22 15:12:55,628 DEBUG graphviz.files write 493 bytes to 'result/uml'
2020-03-22 15:12:55,630 DEBUG graphviz.backend run ['dot', '-Tpng', '-O', 'uml']
2020-03-22 15:13:58,778 DEBUG graphviz.files write 493 bytes to 'result/uml'
2020-03-22 15:13:58,780 DEBUG graphviz.backend run ['dot', '-Tpng', '-O', 'uml']
2020-03-22 15:15:12,933 DEBUG graphviz.files write 493 bytes to 'result/uml'
2020-03-22 15:15:12,935 DEBUG graphviz.backend run ['dot', '-Tpng', '-O', 'uml']
2020-03-22 15:17:08,666 DEBUG graphviz.files write 677 bytes to 'result/uml'
2020-03-22 15:17:08,666 DEBUG graphviz.backend run ['dot', '-Tpng', '-O', 'uml']
2020-03-22 17:01:17,852 ERROR __main__ 2uml
Traceback (most recent call last):
  File "/Users/chenjiadong/Documents/funnyCode/PythonRepo/pyuml/main.py", line 82, in do_2uml
    dot_string = self._parse_to_dot(splitargs.Input)
  File "/Users/chenjiadong/Documents/funnyCode/PythonRepo/pyuml/main.py", line 135, in _parse_to_dot
    tree = ast3.parse(code_string)
  File "/Users/chenjiadong/Documents/funnyCode/PythonRepo/pyuml/venv/lib/python3.7/site-packages/typed_ast/ast3.py", line 62, in parse
    return _ast3._parse(source, filename, mode, feature_version)
TypeError: parse() arg 1 must be a string or bytes object
2020-03-22 18:48:12,516 ERROR __main__ 2uml
Traceback (most recent call last):
  File "/Users/chenjiadong/Documents/funnyCode/PythonRepo/pyuml/main.py", line 86, in do_2uml
    code_string_list = loader.load_from_file_or_directory(args)
  File "/Users/chenjiadong/Documents/funnyCode/PythonRepo/pyuml/core/loader.py", line 8, in load_from_file_or_directory
    raise IOError
OSError
2020-03-22 18:49:14,520 ERROR __main__ 2uml
Traceback (most recent call last):
  File "/Users/chenjiadong/Documents/funnyCode/PythonRepo/pyuml/main.py", line 82, in do_2uml
    splitargs = parser.parse_args(shlex.split(args))
  File "/usr/local/Cellar/python/3.7.7/Frameworks/Python.framework/Versions/3.7/lib/python3.7/argparse.py", line 1755, in parse_args
    args, argv = self.parse_known_args(args, namespace)
  File "/usr/local/Cellar/python/3.7.7/Frameworks/Python.framework/Versions/3.7/lib/python3.7/argparse.py", line 1787, in parse_known_args
    namespace, args = self._parse_known_args(args, namespace)
  File "/usr/local/Cellar/python/3.7.7/Frameworks/Python.framework/Versions/3.7/lib/python3.7/argparse.py", line 2022, in _parse_known_args
    ', '.join(required_actions))
  File "/usr/local/Cellar/python/3.7.7/Frameworks/Python.framework/Versions/3.7/lib/python3.7/argparse.py", line 2508, in error
    self.exit(2, _('%(prog)s: error: %(message)s\n') % args)
  File "/usr/local/Cellar/python/3.7.7/Frameworks/Python.framework/Versions/3.7/lib/python3.7/argparse.py", line 2495, in exit
    _sys.exit(status)
SystemExit: 2
2020-03-22 18:49:21,063 ERROR __main__ 2uml
Traceback (most recent call last):
  File "/Users/chenjiadong/Documents/funnyCode/PythonRepo/pyuml/main.py", line 86, in do_2uml
    code_string_list = loader.load_from_file_or_directory(args)
  File "/Users/chenjiadong/Documents/funnyCode/PythonRepo/pyuml/core/loader.py", line 9, in load_from_file_or_directory
    raise IOError
OSError
2020-03-22 18:50:00,185 ERROR __main__ 2uml
Traceback (most recent call last):
  File "/Users/chenjiadong/Documents/funnyCode/PythonRepo/pyuml/main.py", line 88, in do_2uml
    dot_string = self._parse_to_dot(code_string)
  File "/Users/chenjiadong/Documents/funnyCode/PythonRepo/pyuml/main.py", line 141, in _parse_to_dot
    tree = ast3.parse(code_string)
NameError: name 'code_string' is not defined
2020-03-22 18:50:40,157 ERROR __main__ 2uml
Traceback (most recent call last):
  File "/Users/chenjiadong/Documents/funnyCode/PythonRepo/pyuml/main.py", line 88, in do_2uml
    dot_string = self._parse_to_dot(code_string)
  File "/Users/chenjiadong/Documents/funnyCode/PythonRepo/pyuml/main.py", line 140, in _parse_to_dot
    tree = ast3.parse(code_string)
  File "/Users/chenjiadong/Documents/funnyCode/PythonRepo/pyuml/venv/lib/python3.7/site-packages/typed_ast/ast3.py", line 62, in parse
    return _ast3._parse(source, filename, mode, feature_version)
TypeError: parse() arg 1 must be a string or bytes object
2020-03-22 18:51:21,589 ERROR __main__ 2uml
Traceback (most recent call last):
  File "/Users/chenjiadong/Documents/funnyCode/PythonRepo/pyuml/main.py", line 82, in do_2uml
    splitargs = parser.parse_args(shlex.split(args))
  File "/usr/local/Cellar/python/3.7.7/Frameworks/Python.framework/Versions/3.7/lib/python3.7/argparse.py", line 1755, in parse_args
    args, argv = self.parse_known_args(args, namespace)
  File "/usr/local/Cellar/python/3.7.7/Frameworks/Python.framework/Versions/3.7/lib/python3.7/argparse.py", line 1787, in parse_known_args
    namespace, args = self._parse_known_args(args, namespace)
  File "/usr/local/Cellar/python/3.7.7/Frameworks/Python.framework/Versions/3.7/lib/python3.7/argparse.py", line 2022, in _parse_known_args
    ', '.join(required_actions))
  File "/usr/local/Cellar/python/3.7.7/Frameworks/Python.framework/Versions/3.7/lib/python3.7/argparse.py", line 2508, in error
    self.exit(2, _('%(prog)s: error: %(message)s\n') % args)
  File "/usr/local/Cellar/python/3.7.7/Frameworks/Python.framework/Versions/3.7/lib/python3.7/argparse.py", line 2495, in exit
    _sys.exit(status)
SystemExit: 2
2020-03-22 18:51:26,153 ERROR __main__ 2uml
Traceback (most recent call last):
  File "/Users/chenjiadong/Documents/funnyCode/PythonRepo/pyuml/main.py", line 88, in do_2uml
    dot_string = self._parse_to_dot(code_string)
  File "/Users/chenjiadong/Documents/funnyCode/PythonRepo/pyuml/main.py", line 141, in _parse_to_dot
    tree = ast3.parse(code_string)
  File "/Users/chenjiadong/Documents/funnyCode/PythonRepo/pyuml/venv/lib/python3.7/site-packages/typed_ast/ast3.py", line 62, in parse
    return _ast3._parse(source, filename, mode, feature_version)
TypeError: parse() arg 1 must be a string or bytes object
2020-03-22 18:54:40,677 DEBUG graphviz.files write 677 bytes to 'result/uml'
2020-03-22 18:54:40,678 DEBUG graphviz.backend run ['dot', '-Tpng', '-O', 'uml']
2020-03-22 18:54:40,819 DEBUG graphviz.files write 68 bytes to 'result/uml'
2020-03-22 18:54:40,819 DEBUG graphviz.backend run ['dot', '-Tpng', '-O', 'uml']
2020-03-22 18:54:40,831 ERROR __main__ 2uml
Traceback (most recent call last):
  File "/Users/chenjiadong/Documents/funnyCode/PythonRepo/pyuml/main.py", line 89, in do_2uml
    self._render_with_graphviz(dot_string)
  File "/Users/chenjiadong/Documents/funnyCode/PythonRepo/pyuml/main.py", line 151, in _render_with_graphviz
    src.render(format='png', filename="result/uml")
  File "/Users/chenjiadong/Documents/funnyCode/PythonRepo/pyuml/venv/lib/python3.7/site-packages/graphviz/files.py", line 209, in render
    quiet=quiet)
  File "/Users/chenjiadong/Documents/funnyCode/PythonRepo/pyuml/venv/lib/python3.7/site-packages/graphviz/backend.py", line 206, in render
    run(cmd, capture_output=True, cwd=cwd, check=True, quiet=quiet)
  File "/Users/chenjiadong/Documents/funnyCode/PythonRepo/pyuml/venv/lib/python3.7/site-packages/graphviz/backend.py", line 172, in run
    output=out, stderr=err)
graphviz.backend.CalledProcessError: Command '['dot', '-Tpng', '-O', 'uml']' returned non-zero exit status 1. [stderr: b'Error: uml: syntax error in line 2 scanning a quoted string (missing endquote? longer than 16384?)\nString starting:"];\n}\n\n']
2020-03-22 18:55:59,875 DEBUG graphviz.files write 68 bytes to 'result/uml'
2020-03-22 18:55:59,876 DEBUG graphviz.backend run ['dot', '-Tpng', '-O', 'uml']
2020-03-22 18:55:59,895 ERROR __main__ 2uml
Traceback (most recent call last):
  File "/Users/chenjiadong/Documents/funnyCode/PythonRepo/pyuml/main.py", line 89, in do_2uml
    self._render_with_graphviz(dot_string)
  File "/Users/chenjiadong/Documents/funnyCode/PythonRepo/pyuml/main.py", line 151, in _render_with_graphviz
    src.render(format='png', filename="result/uml")
  File "/Users/chenjiadong/Documents/funnyCode/PythonRepo/pyuml/venv/lib/python3.7/site-packages/graphviz/files.py", line 209, in render
    quiet=quiet)
  File "/Users/chenjiadong/Documents/funnyCode/PythonRepo/pyuml/venv/lib/python3.7/site-packages/graphviz/backend.py", line 206, in render
    run(cmd, capture_output=True, cwd=cwd, check=True, quiet=quiet)
  File "/Users/chenjiadong/Documents/funnyCode/PythonRepo/pyuml/venv/lib/python3.7/site-packages/graphviz/backend.py", line 172, in run
    output=out, stderr=err)
graphviz.backend.CalledProcessError: Command '['dot', '-Tpng', '-O', 'uml']' returned non-zero exit status 1. [stderr: b'Error: uml: syntax error in line 2 scanning a quoted string (missing endquote? longer than 16384?)\nString starting:"];\n}\n\n']
2020-03-22 19:07:36,204 DEBUG graphviz.files write 677 bytes to 'result/uml'
2020-03-22 19:07:36,206 DEBUG graphviz.backend run ['dot', '-Tpng', '-O', 'uml']
2020-03-22 19:07:36,308 DEBUG graphviz.files write 68 bytes to 'result/uml'
2020-03-22 19:07:36,308 DEBUG graphviz.backend run ['dot', '-Tpng', '-O', 'uml']
2020-03-22 19:07:36,321 ERROR __main__ 2uml
Traceback (most recent call last):
  File "/Users/chenjiadong/Documents/funnyCode/PythonRepo/pyuml/main.py", line 89, in do_2uml
    self._render_with_graphviz(dot_string)
  File "/Users/chenjiadong/Documents/funnyCode/PythonRepo/pyuml/main.py", line 151, in _render_with_graphviz
    src.render(format='png', filename="result/uml")
  File "/Users/chenjiadong/Documents/funnyCode/PythonRepo/pyuml/venv/lib/python3.7/site-packages/graphviz/files.py", line 209, in render
    quiet=quiet)
  File "/Users/chenjiadong/Documents/funnyCode/PythonRepo/pyuml/venv/lib/python3.7/site-packages/graphviz/backend.py", line 206, in render
    run(cmd, capture_output=True, cwd=cwd, check=True, quiet=quiet)
  File "/Users/chenjiadong/Documents/funnyCode/PythonRepo/pyuml/venv/lib/python3.7/site-packages/graphviz/backend.py", line 172, in run
    output=out, stderr=err)
graphviz.backend.CalledProcessError: Command '['dot', '-Tpng', '-O', 'uml']' returned non-zero exit status 1. [stderr: b'Error: uml: syntax error in line 2 scanning a quoted string (missing endquote? longer than 16384?)\nString starting:"];\n}\n\n']
2020-03-22 19:15:55,722 DEBUG graphviz.files write 677 bytes to 'result/uml'
2020-03-22 19:15:55,725 DEBUG graphviz.backend run ['dot', '-Tpng', '-O', 'uml']
2020-03-22 19:15:55,821 DEBUG graphviz.files write 68 bytes to 'result/uml'
2020-03-22 19:15:55,822 DEBUG graphviz.backend run ['dot', '-Tpng', '-O', 'uml']
2020-03-22 19:15:55,833 ERROR __main__ 2uml
Traceback (most recent call last):
  File "/Users/chenjiadong/Documents/funnyCode/PythonRepo/pyuml/main.py", line 89, in do_2uml
    self._render_with_graphviz(dot_string)
  File "/Users/chenjiadong/Documents/funnyCode/PythonRepo/pyuml/main.py", line 151, in _render_with_graphviz
    src.render(format='png', filename="result/uml")
  File "/Users/chenjiadong/Documents/funnyCode/PythonRepo/pyuml/venv/lib/python3.7/site-packages/graphviz/files.py", line 209, in render
    quiet=quiet)
  File "/Users/chenjiadong/Documents/funnyCode/PythonRepo/pyuml/venv/lib/python3.7/site-packages/graphviz/backend.py", line 206, in render
    run(cmd, capture_output=True, cwd=cwd, check=True, quiet=quiet)
  File "/Users/chenjiadong/Documents/funnyCode/PythonRepo/pyuml/venv/lib/python3.7/site-packages/graphviz/backend.py", line 172, in run
    output=out, stderr=err)
graphviz.backend.CalledProcessError: Command '['dot', '-Tpng', '-O', 'uml']' returned non-zero exit status 1. [stderr: b'Error: uml: syntax error in line 2 scanning a quoted string (missing endquote? longer than 16384?)\nString starting:"];\n}\n\n']
2020-03-22 19:19:56,943 DEBUG graphviz.files write 677 bytes to 'result/uml0'
2020-03-22 19:19:56,945 DEBUG graphviz.backend run ['dot', '-Tpng', '-O', 'uml0']
2020-03-22 19:19:57,020 DEBUG graphviz.files write 68 bytes to 'result/uml1'
2020-03-22 19:19:57,020 DEBUG graphviz.backend run ['dot', '-Tpng', '-O', 'uml1']
2020-03-22 19:19:57,031 ERROR __main__ 2uml
Traceback (most recent call last):
  File "/Users/chenjiadong/Documents/funnyCode/PythonRepo/pyuml/main.py", line 90, in do_2uml
    self._render_with_graphviz(index, dot_string)
  File "/Users/chenjiadong/Documents/funnyCode/PythonRepo/pyuml/main.py", line 150, in _render_with_graphviz
    src.render(format='png', filename="result/uml{}".format(index))
  File "/Users/chenjiadong/Documents/funnyCode/PythonRepo/pyuml/venv/lib/python3.7/site-packages/graphviz/files.py", line 209, in render
    quiet=quiet)
  File "/Users/chenjiadong/Documents/funnyCode/PythonRepo/pyuml/venv/lib/python3.7/site-packages/graphviz/backend.py", line 206, in render
    run(cmd, capture_output=True, cwd=cwd, check=True, quiet=quiet)
  File "/Users/chenjiadong/Documents/funnyCode/PythonRepo/pyuml/venv/lib/python3.7/site-packages/graphviz/backend.py", line 172, in run
    output=out, stderr=err)
graphviz.backend.CalledProcessError: Command '['dot', '-Tpng', '-O', 'uml1']' returned non-zero exit status 1. [stderr: b'Error: uml1: syntax error in line 2 scanning a quoted string (missing endquote? longer than 16384?)\nString starting:"];\n}\n\n']
2020-03-22 20:04:10,735 DEBUG graphviz.files write 677 bytes to 'result/uml0'
2020-03-22 20:04:10,738 DEBUG graphviz.backend run ['dot', '-Tpng', '-O', 'uml0']
2020-03-22 20:04:10,856 DEBUG graphviz.files write 69 bytes to 'result/uml1'
2020-03-22 20:04:10,858 DEBUG graphviz.backend run ['dot', '-Tpng', '-O', 'uml1']
2020-03-22 20:04:48,751 DEBUG graphviz.files write 677 bytes to 'result/uml0'
2020-03-22 20:04:48,753 DEBUG graphviz.backend run ['dot', '-Tpng', '-O', 'uml0']
2020-03-22 20:04:48,810 DEBUG graphviz.files write 69 bytes to 'result/uml1'
2020-03-22 20:04:48,810 DEBUG graphviz.backend run ['dot', '-Tpng', '-O', 'uml1']
2020-03-22 20:53:49,390 ERROR __main__ 2uml
Traceback (most recent call last):
  File "/Users/chenjiadong/Documents/funnyCode/PythonRepo/pyuml/main.py", line 91, in do_2uml
    self._render_with_graphviz(index, dot_string)
TypeError: _render_with_graphviz() missing 1 required positional argument: 'dot'
2020-03-22 20:55:16,792 DEBUG graphviz.files write 69 bytes to '/uml0'
2020-03-22 20:55:16,793 ERROR __main__ 2uml
Traceback (most recent call last):
  File "/Users/chenjiadong/Documents/funnyCode/PythonRepo/pyuml/main.py", line 91, in do_2uml
    self._render_with_graphviz(output_path, index, dot_string)
  File "/Users/chenjiadong/Documents/funnyCode/PythonRepo/pyuml/main.py", line 151, in _render_with_graphviz
    src.render(format='png', filename=os.path.join(output_path, "/uml{}".format(index)))
  File "/Users/chenjiadong/Documents/funnyCode/PythonRepo/pyuml/venv/lib/python3.7/site-packages/graphviz/files.py", line 202, in render
    filepath = self.save(filename, directory)
  File "/Users/chenjiadong/Documents/funnyCode/PythonRepo/pyuml/venv/lib/python3.7/site-packages/graphviz/files.py", line 166, in save
    with io.open(filepath, 'w', encoding=self.encoding) as fd:
PermissionError: [Errno 13] Permission denied: '/uml0'
2020-03-22 20:58:30,651 DEBUG graphviz.files write 69 bytes to '/Users/chenjiadong/Documents/funnyCode/PythonRepo/pyuml/test/test_dot_code/uml0'
2020-03-22 20:58:30,654 DEBUG graphviz.backend run ['dot', '-Tpng', '-O', 'uml0']
2020-03-22 20:58:30,726 DEBUG graphviz.files write 179 bytes to '/Users/chenjiadong/Documents/funnyCode/PythonRepo/pyuml/test/test_dot_code/uml1'
2020-03-22 20:58:30,726 DEBUG graphviz.backend run ['dot', '-Tpng', '-O', 'uml1']
2020-03-22 20:58:30,757 DEBUG graphviz.files write 81 bytes to '/Users/chenjiadong/Documents/funnyCode/PythonRepo/pyuml/test/test_dot_code/uml2'
2020-03-22 20:58:30,758 DEBUG graphviz.backend run ['dot', '-Tpng', '-O', 'uml2']
2020-03-22 20:58:30,789 DEBUG graphviz.files write 450 bytes to '/Users/chenjiadong/Documents/funnyCode/PythonRepo/pyuml/test/test_dot_code/uml3'
2020-03-22 20:58:30,790 DEBUG graphviz.backend run ['dot', '-Tpng', '-O', 'uml3']
2020-03-22 20:58:30,821 DEBUG graphviz.files write 677 bytes to '/Users/chenjiadong/Documents/funnyCode/PythonRepo/pyuml/test/test_dot_code/uml4'
2020-03-22 20:58:30,821 DEBUG graphviz.backend run ['dot', '-Tpng', '-O', 'uml4']
2020-03-22 20:58:30,861 DEBUG graphviz.files write 167 bytes to '/Users/chenjiadong/Documents/funnyCode/PythonRepo/pyuml/test/test_dot_code/uml5'
2020-03-22 20:58:30,861 DEBUG graphviz.backend run ['dot', '-Tpng', '-O', 'uml5']
2020-03-22 20:58:30,889 DEBUG graphviz.files write 69 bytes to '/Users/chenjiadong/Documents/funnyCode/PythonRepo/pyuml/test/test_dot_code/uml6'
2020-03-22 20:58:30,889 DEBUG graphviz.backend run ['dot', '-Tpng', '-O', 'uml6']
2020-03-22 21:00:17,358 ERROR __main__ 2uml
Traceback (most recent call last):
  File "/Users/chenjiadong/Documents/funnyCode/PythonRepo/pyuml/main.py", line 87, in do_2uml
    code_string_list = loader.load_from_file_or_directory(input_path)
  File "/Users/chenjiadong/Documents/funnyCode/PythonRepo/pyuml/core/loader.py", line 9, in load_from_file_or_directory
    raise IOError
OSError
2020-03-22 21:09:28,035 DEBUG graphviz.files write 69 bytes to '/Users/chenjiadong/Documents/funnyCode/PythonRepo/pyuml/result/uml0'
2020-03-22 21:09:28,039 DEBUG graphviz.backend run ['dot', '-Tpng', '-O', 'uml0']
2020-03-22 21:09:28,126 DEBUG graphviz.files write 179 bytes to '/Users/chenjiadong/Documents/funnyCode/PythonRepo/pyuml/result/uml1'
2020-03-22 21:09:28,127 DEBUG graphviz.backend run ['dot', '-Tpng', '-O', 'uml1']
2020-03-22 21:09:28,156 DEBUG graphviz.files write 81 bytes to '/Users/chenjiadong/Documents/funnyCode/PythonRepo/pyuml/result/uml2'
2020-03-22 21:09:28,156 DEBUG graphviz.backend run ['dot', '-Tpng', '-O', 'uml2']
2020-03-22 21:09:28,183 DEBUG graphviz.files write 450 bytes to '/Users/chenjiadong/Documents/funnyCode/PythonRepo/pyuml/result/uml3'
2020-03-22 21:09:28,183 DEBUG graphviz.backend run ['dot', '-Tpng', '-O', 'uml3']
2020-03-22 21:09:28,213 DEBUG graphviz.files write 677 bytes to '/Users/chenjiadong/Documents/funnyCode/PythonRepo/pyuml/result/uml4'
2020-03-22 21:09:28,214 DEBUG graphviz.backend run ['dot', '-Tpng', '-O', 'uml4']
2020-03-22 21:09:28,250 DEBUG graphviz.files write 167 bytes to '/Users/chenjiadong/Documents/funnyCode/PythonRepo/pyuml/result/uml5'
2020-03-22 21:09:28,250 DEBUG graphviz.backend run ['dot', '-Tpng', '-O', 'uml5']
2020-03-22 21:09:28,281 DEBUG graphviz.files write 69 bytes to '/Users/chenjiadong/Documents/funnyCode/PythonRepo/pyuml/result/uml6'
2020-03-22 21:09:28,282 DEBUG graphviz.backend run ['dot', '-Tpng', '-O', 'uml6']
2020-03-22 21:10:41,552 DEBUG graphviz.files write 677 bytes to '/Users/chenjiadong/Documents/funnyCode/PythonRepo/pyuml/result/uml0'
2020-03-22 21:10:41,555 DEBUG graphviz.backend run ['dot', '-Tpng', '-O', 'uml0']
2020-03-22 21:32:22,340 ERROR __main__ 2uml
Traceback (most recent call last):
  File "/Users/chenjiadong/Documents/funnyCode/PythonRepo/pyuml/main.py", line 90, in do_2uml
    dot_string = self._parse_to_dot(code_string)
  File "/Users/chenjiadong/Documents/funnyCode/PythonRepo/pyuml/main.py", line 142, in _parse_to_dot
    class_parser = self._parse_to_class_recoard(code_string)
  File "/Users/chenjiadong/Documents/funnyCode/PythonRepo/pyuml/main.py", line 148, in _parse_to_class_recoard
    tree = ast3.parse(code_string)
  File "/Users/chenjiadong/Documents/funnyCode/PythonRepo/pyuml/venv/lib/python3.7/site-packages/typed_ast/ast3.py", line 62, in parse
    return _ast3._parse(source, filename, mode, feature_version)
  File "<unknown>", line 1
    class ErrorClass
                   ^
SyntaxError: invalid syntax
2020-03-22 21:38:35,162 ERROR __main__ 2uml
Traceback (most recent call last):
  File "/Users/chenjiadong/Documents/funnyCode/PythonRepo/pyuml/main.py", line 91, in do_2uml
    self._render_with_graphviz(output_path, index, dot_string)
  File "/Users/chenjiadong/Documents/funnyCode/PythonRepo/pyuml/main.py", line 155, in _render_with_graphviz
    src.render(format='png', filename='uml{}'.format(index), directory=output_path)
  File "/Users/chenjiadong/Documents/funnyCode/PythonRepo/pyuml/venv/lib/python3.7/site-packages/graphviz/files.py", line 202, in render
    filepath = self.save(filename, directory)
  File "/Users/chenjiadong/Documents/funnyCode/PythonRepo/pyuml/venv/lib/python3.7/site-packages/graphviz/files.py", line 161, in save
    tools.mkdirs(filepath)
  File "/Users/chenjiadong/Documents/funnyCode/PythonRepo/pyuml/venv/lib/python3.7/site-packages/graphviz/tools.py", line 31, in mkdirs
    _compat.makedirs(dirname, mode=mode, exist_ok=True)
  File "/Users/chenjiadong/Documents/funnyCode/PythonRepo/pyuml/venv/lib/python3.7/site-packages/graphviz/_compat.py", line 57, in makedirs
    return os.makedirs(name, mode, exist_ok=exist_ok)
  File "/usr/local/Cellar/python/3.7.7/Frameworks/Python.framework/Versions/3.7/lib/python3.7/os.py", line 223, in makedirs
    mkdir(name, mode)
FileExistsError: [Errno 17] File exists: '/Users/chenjiadong/Documents/funnyCode/PythonRepo/pyuml/test/test_py_code/OOPBasicClass.py'
2020-03-22 21:39:25,956 DEBUG graphviz.files write 677 bytes to '/Users/chenjiadong/Documents/funnyCode/PythonRepo/pyuml/test/test_py_code/OOPBasicClass.p/uml0'
2020-03-22 21:39:25,957 DEBUG graphviz.backend run ['dot', '-Tpng', '-O', 'uml0']
2020-03-22 21:53:33,637 DEBUG graphviz.files write 722 bytes to '/Users/chenjiadong/Documents/funnyCode/PythonRepo/pyuml/result/uml0'
2020-03-22 21:53:33,643 DEBUG graphviz.backend run ['dot', '-Tpng', '-O', 'uml0']
2020-03-22 21:54:34,673 DEBUG graphviz.files write 743 bytes to '/Users/chenjiadong/Documents/funnyCode/PythonRepo/pyuml/result/uml0'
2020-03-22 21:54:34,674 DEBUG graphviz.backend run ['dot', '-Tpng', '-O', 'uml0']
2020-03-22 21:55:28,889 DEBUG graphviz.files write 743 bytes to '/Users/chenjiadong/Documents/funnyCode/PythonRepo/pyuml/result/uml0'
2020-03-22 21:55:28,890 DEBUG graphviz.backend run ['dot', '-Tpng', '-O', 'uml0']
2020-03-22 21:55:32,903 ERROR __main__ 2uml
Traceback (most recent call last):
  File "/Users/chenjiadong/Documents/funnyCode/PythonRepo/pyuml/main.py", line 82, in do_2uml
    splitargs = parser.parse_args(shlex.split(args))
  File "/usr/local/Cellar/python/3.7.7/Frameworks/Python.framework/Versions/3.7/lib/python3.7/argparse.py", line 1755, in parse_args
    args, argv = self.parse_known_args(args, namespace)
  File "/usr/local/Cellar/python/3.7.7/Frameworks/Python.framework/Versions/3.7/lib/python3.7/argparse.py", line 1787, in parse_known_args
    namespace, args = self._parse_known_args(args, namespace)
  File "/usr/local/Cellar/python/3.7.7/Frameworks/Python.framework/Versions/3.7/lib/python3.7/argparse.py", line 2022, in _parse_known_args
    ', '.join(required_actions))
  File "/usr/local/Cellar/python/3.7.7/Frameworks/Python.framework/Versions/3.7/lib/python3.7/argparse.py", line 2508, in error
    self.exit(2, _('%(prog)s: error: %(message)s\n') % args)
  File "/usr/local/Cellar/python/3.7.7/Frameworks/Python.framework/Versions/3.7/lib/python3.7/argparse.py", line 2495, in exit
    _sys.exit(status)
SystemExit: 2
2020-03-22 21:55:35,148 ERROR __main__ 2uml
Traceback (most recent call last):
  File "/Users/chenjiadong/Documents/funnyCode/PythonRepo/pyuml/main.py", line 82, in do_2uml
    splitargs = parser.parse_args(shlex.split(args))
  File "/usr/local/Cellar/python/3.7.7/Frameworks/Python.framework/Versions/3.7/lib/python3.7/argparse.py", line 1755, in parse_args
    args, argv = self.parse_known_args(args, namespace)
  File "/usr/local/Cellar/python/3.7.7/Frameworks/Python.framework/Versions/3.7/lib/python3.7/argparse.py", line 1787, in parse_known_args
    namespace, args = self._parse_known_args(args, namespace)
  File "/usr/local/Cellar/python/3.7.7/Frameworks/Python.framework/Versions/3.7/lib/python3.7/argparse.py", line 2022, in _parse_known_args
    ', '.join(required_actions))
  File "/usr/local/Cellar/python/3.7.7/Frameworks/Python.framework/Versions/3.7/lib/python3.7/argparse.py", line 2508, in error
    self.exit(2, _('%(prog)s: error: %(message)s\n') % args)
  File "/usr/local/Cellar/python/3.7.7/Frameworks/Python.framework/Versions/3.7/lib/python3.7/argparse.py", line 2495, in exit
    _sys.exit(status)
SystemExit: 2
2020-03-22 21:55:43,770 ERROR __main__ 2uml
Traceback (most recent call last):
  File "/Users/chenjiadong/Documents/funnyCode/PythonRepo/pyuml/main.py", line 82, in do_2uml
    splitargs = parser.parse_args(shlex.split(args))
  File "/usr/local/Cellar/python/3.7.7/Frameworks/Python.framework/Versions/3.7/lib/python3.7/argparse.py", line 1755, in parse_args
    args, argv = self.parse_known_args(args, namespace)
  File "/usr/local/Cellar/python/3.7.7/Frameworks/Python.framework/Versions/3.7/lib/python3.7/argparse.py", line 1787, in parse_known_args
    namespace, args = self._parse_known_args(args, namespace)
  File "/usr/local/Cellar/python/3.7.7/Frameworks/Python.framework/Versions/3.7/lib/python3.7/argparse.py", line 2022, in _parse_known_args
    ', '.join(required_actions))
  File "/usr/local/Cellar/python/3.7.7/Frameworks/Python.framework/Versions/3.7/lib/python3.7/argparse.py", line 2508, in error
    self.exit(2, _('%(prog)s: error: %(message)s\n') % args)
  File "/usr/local/Cellar/python/3.7.7/Frameworks/Python.framework/Versions/3.7/lib/python3.7/argparse.py", line 2495, in exit
    _sys.exit(status)
SystemExit: 2
2020-03-23 09:29:39,791 ERROR __main__ 2uml
Traceback (most recent call last):
  File "/Users/chenjiadong/Documents/funnyCode/PythonRepo/pyuml/main.py", line 88, in do_2uml
    code_string_list = loader.load_from_file_or_directory(input_path)
  File "/Users/chenjiadong/Documents/funnyCode/PythonRepo/pyuml/core/loader.py", line 9, in load_from_file_or_directory
    raise IOError
OSError
2020-03-23 09:30:52,115 ERROR __main__ 2uml
Traceback (most recent call last):
  File "/Users/chenjiadong/Documents/funnyCode/PythonRepo/pyuml/main.py", line 88, in do_2uml
    code_string_list = loader.load_from_file_or_directory(input_path)
  File "/Users/chenjiadong/Documents/funnyCode/PythonRepo/pyuml/main.py", line 88, in do_2uml
    code_string_list = loader.load_from_file_or_directory(input_path)
  File "_pydevd_bundle/pydevd_cython_darwin_37_64.pyx", line 1470, in _pydevd_bundle.pydevd_cython_darwin_37_64.ThreadTracer.__call__
  File "_pydevd_bundle/pydevd_cython_darwin_37_64.pyx", line 855, in _pydevd_bundle.pydevd_cython_darwin_37_64.PyDBFrame.trace_dispatch
  File "_pydevd_bundle/pydevd_cython_darwin_37_64.pyx", line 846, in _pydevd_bundle.pydevd_cython_darwin_37_64.PyDBFrame.trace_dispatch
  File "_pydevd_bundle/pydevd_cython_darwin_37_64.pyx", line 288, in _pydevd_bundle.pydevd_cython_darwin_37_64.PyDBFrame.do_wait_suspend
  File "/Applications/PyCharm CE.app/Contents/plugins/python-ce/helpers/pydev/pydevd.py", line 1099, in do_wait_suspend
    self._do_wait_suspend(thread, frame, event, arg, suspend_type, from_this_thread)
  File "/Applications/PyCharm CE.app/Contents/plugins/python-ce/helpers/pydev/pydevd.py", line 1114, in _do_wait_suspend
    time.sleep(0.01)
KeyboardInterrupt
2020-03-23 09:31:00,042 ERROR __main__ 2uml
Traceback (most recent call last):
  File "/Users/chenjiadong/Documents/funnyCode/PythonRepo/pyuml/main.py", line 83, in do_2uml
    splitargs = parser.parse_args(shlex.split(args))
  File "/usr/local/Cellar/python/3.7.7/Frameworks/Python.framework/Versions/3.7/lib/python3.7/argparse.py", line 1758, in parse_args
    self.error(msg % ' '.join(argv))
  File "/usr/local/Cellar/python/3.7.7/Frameworks/Python.framework/Versions/3.7/lib/python3.7/argparse.py", line 2508, in error
    self.exit(2, _('%(prog)s: error: %(message)s\n') % args)
  File "/usr/local/Cellar/python/3.7.7/Frameworks/Python.framework/Versions/3.7/lib/python3.7/argparse.py", line 2495, in exit
    _sys.exit(status)
SystemExit: 2
2020-03-23 09:31:19,617 ERROR __main__ 2uml
Traceback (most recent call last):
  File "/Users/chenjiadong/Documents/funnyCode/PythonRepo/pyuml/main.py", line 83, in do_2uml
    splitargs = parser.parse_args(shlex.split(args))
  File "/usr/local/Cellar/python/3.7.7/Frameworks/Python.framework/Versions/3.7/lib/python3.7/argparse.py", line 1758, in parse_args
    self.error(msg % ' '.join(argv))
  File "/usr/local/Cellar/python/3.7.7/Frameworks/Python.framework/Versions/3.7/lib/python3.7/argparse.py", line 2508, in error
    self.exit(2, _('%(prog)s: error: %(message)s\n') % args)
  File "/usr/local/Cellar/python/3.7.7/Frameworks/Python.framework/Versions/3.7/lib/python3.7/argparse.py", line 2495, in exit
    _sys.exit(status)
SystemExit: 2
2020-03-23 09:42:53,680 DEBUG graphviz.files write 69 bytes to '/Users/chenjiadong/Documents/uml0'
2020-03-23 09:42:53,682 DEBUG graphviz.backend run ['dot', '-Tpng', '-O', 'uml0']
2020-03-23 09:42:53,762 DEBUG graphviz.files write 179 bytes to '/Users/chenjiadong/Documents/uml1'
2020-03-23 09:42:53,764 DEBUG graphviz.backend run ['dot', '-Tpng', '-O', 'uml1']
2020-03-23 09:42:53,793 DEBUG graphviz.files write 81 bytes to '/Users/chenjiadong/Documents/uml2'
2020-03-23 09:42:53,794 DEBUG graphviz.backend run ['dot', '-Tpng', '-O', 'uml2']
2020-03-23 09:42:53,820 DEBUG graphviz.files write 450 bytes to '/Users/chenjiadong/Documents/uml3'
2020-03-23 09:42:53,824 DEBUG graphviz.backend run ['dot', '-Tpng', '-O', 'uml3']
2020-03-23 09:42:53,854 ERROR __main__ 2uml
Traceback (most recent call last):
  File "/Users/chenjiadong/Documents/funnyCode/PythonRepo/pyuml/main.py", line 90, in do_2uml
    dot_string = self._parse_to_dot(code_string)
  File "/Users/chenjiadong/Documents/funnyCode/PythonRepo/pyuml/main.py", line 148, in _parse_to_dot
    class_parser = self._parse_to_class_recoard(code_string)
  File "/Users/chenjiadong/Documents/funnyCode/PythonRepo/pyuml/main.py", line 161, in _parse_to_class_recoard
    tree = ast3.parse(code_string)
  File "/Users/chenjiadong/Documents/funnyCode/PythonRepo/pyuml/venv/lib/python3.7/site-packages/typed_ast/ast3.py", line 62, in parse
    return _ast3._parse(source, filename, mode, feature_version)
  File "<unknown>", line 1
    class ErrorClass
                   ^
SyntaxError: invalid syntax
2020-03-23 09:43:38,139 DEBUG graphviz.files write 743 bytes to '/Users/chenjiadong/Documents/uml0'
2020-03-23 09:43:38,140 DEBUG graphviz.backend run ['dot', '-Tpng', '-O', 'uml0']
2020-03-23 09:44:18,379 ERROR __main__ 2uml
Traceback (most recent call last):
  File "/Users/chenjiadong/Documents/funnyCode/PythonRepo/pyuml/main.py", line 90, in do_2uml
    dot_string = self._parse_to_dot(code_string)
  File "/Users/chenjiadong/Documents/funnyCode/PythonRepo/pyuml/main.py", line 149, in _parse_to_dot
    self._persistent_to_file(class_parser.classes_list)
  File "/Users/chenjiadong/Documents/funnyCode/PythonRepo/pyuml/main.py", line 157, in _persistent_to_file
    serializer.serialize(obj)
TypeError: serialize() missing 1 required positional argument: 'obj'
2020-03-23 09:45:27,754 ERROR __main__ 2uml
Traceback (most recent call last):
  File "/Users/chenjiadong/Documents/funnyCode/PythonRepo/pyuml/main.py", line 90, in do_2uml
    dot_string = self._parse_to_dot(code_string)
  File "/Users/chenjiadong/Documents/funnyCode/PythonRepo/pyuml/main.py", line 149, in _parse_to_dot
    self._persistent_to_file(class_parser.classes_list)
  File "/Users/chenjiadong/Documents/funnyCode/PythonRepo/pyuml/main.py", line 158, in _persistent_to_file
    raise SystemError
SystemError
2020-03-23 09:50:14,403 ERROR __main__ load
Traceback (most recent call last):
  File "/usr/local/Cellar/python/3.7.7/Frameworks/Python.framework/Versions/3.7/lib/python3.7/shelve.py", line 111, in __getitem__
    value = self.cache[key]
KeyError: 'Car'

During handling of the above exception, another exception occurred:

Traceback (most recent call last):
  File "/Users/chenjiadong/Documents/funnyCode/PythonRepo/pyuml/main.py", line 108, in do_Load
    result = serializer.deserilize(splitargs.Input)
  File "/Users/chenjiadong/Documents/funnyCode/PythonRepo/pyuml/core/serializer.py", line 18, in deserilize
    data = db[path]
  File "/usr/local/Cellar/python/3.7.7/Frameworks/Python.framework/Versions/3.7/lib/python3.7/shelve.py", line 113, in __getitem__
    f = BytesIO(self.dict[key.encode(self.keyencoding)])
KeyError: b'Car'
2020-03-23 09:51:35,864 DEBUG graphviz.files write 743 bytes to '/Users/chenjiadong/Documents/uml0'
2020-03-23 09:51:35,866 DEBUG graphviz.backend run ['dot', '-Tpng', '-O', 'uml0']
2020-03-23 09:51:52,610 ERROR __main__ load
Traceback (most recent call last):
  File "/Users/chenjiadong/Documents/funnyCode/PythonRepo/pyuml/main.py", line 106, in do_Load
    splitargs = parser.parse_args(shlex.split(args))
  File "/usr/local/Cellar/python/3.7.7/Frameworks/Python.framework/Versions/3.7/lib/python3.7/argparse.py", line 1755, in parse_args
    args, argv = self.parse_known_args(args, namespace)
  File "/usr/local/Cellar/python/3.7.7/Frameworks/Python.framework/Versions/3.7/lib/python3.7/argparse.py", line 1787, in parse_known_args
    namespace, args = self._parse_known_args(args, namespace)
  File "/usr/local/Cellar/python/3.7.7/Frameworks/Python.framework/Versions/3.7/lib/python3.7/argparse.py", line 1993, in _parse_known_args
    start_index = consume_optional(start_index)
  File "/usr/local/Cellar/python/3.7.7/Frameworks/Python.framework/Versions/3.7/lib/python3.7/argparse.py", line 1933, in consume_optional
    take_action(action, args, option_string)
  File "/usr/local/Cellar/python/3.7.7/Frameworks/Python.framework/Versions/3.7/lib/python3.7/argparse.py", line 1861, in take_action
    action(self, namespace, argument_values, option_string)
  File "/usr/local/Cellar/python/3.7.7/Frameworks/Python.framework/Versions/3.7/lib/python3.7/argparse.py", line 1044, in __call__
    parser.exit()
  File "/usr/local/Cellar/python/3.7.7/Frameworks/Python.framework/Versions/3.7/lib/python3.7/argparse.py", line 2495, in exit
    _sys.exit(status)
SystemExit: 0
2020-03-23 09:52:55,726 ERROR __main__ load
Traceback (most recent call last):
  File "/usr/local/Cellar/python/3.7.7/Frameworks/Python.framework/Versions/3.7/lib/python3.7/shelve.py", line 111, in __getitem__
    value = self.cache[key]
KeyError: 'Car'

During handling of the above exception, another exception occurred:

Traceback (most recent call last):
  File "/Users/chenjiadong/Documents/funnyCode/PythonRepo/pyuml/main.py", line 108, in do_Load
    result = serializer.deserilize(splitargs.Input)
  File "/Users/chenjiadong/Documents/funnyCode/PythonRepo/pyuml/core/serializer.py", line 19, in deserilize
    data = db[name]
  File "/usr/local/Cellar/python/3.7.7/Frameworks/Python.framework/Versions/3.7/lib/python3.7/shelve.py", line 113, in __getitem__
    f = BytesIO(self.dict[key.encode(self.keyencoding)])
KeyError: b'Car'
2020-03-23 09:53:19,226 DEBUG graphviz.files write 743 bytes to '/Users/chenjiadong/Documents/uml0'
2020-03-23 09:53:19,226 DEBUG graphviz.backend run ['dot', '-Tpng', '-O', 'uml0']
2020-03-23 10:09:57,409 ERROR __main__ 2uml
Traceback (most recent call last):
  File "/Users/chenjiadong/Documents/funnyCode/PythonRepo/pyuml/main.py", line 90, in do_2uml
    dot_string = self._parse_to_dot(code_string)
  File "/Users/chenjiadong/Documents/funnyCode/PythonRepo/pyuml/main.py", line 126, in _parse_to_dot
    self._persistent_to_file(class_parser.classes_list)
  File "/Users/chenjiadong/Documents/funnyCode/PythonRepo/pyuml/main.py", line 134, in _persistent_to_file
    serializer.serialize(obj)
  File "/Users/chenjiadong/Documents/funnyCode/PythonRepo/pyuml/core/serializer.py", line 13, in serialize
    with shelve.open(self._path) as db:
  File "/usr/local/Cellar/python/3.7.7/Frameworks/Python.framework/Versions/3.7/lib/python3.7/shelve.py", line 243, in open
    return DbfilenameShelf(filename, flag, protocol, writeback)
  File "/usr/local/Cellar/python/3.7.7/Frameworks/Python.framework/Versions/3.7/lib/python3.7/shelve.py", line 227, in __init__
    Shelf.__init__(self, dbm.open(filename, flag), protocol, writeback)
  File "/usr/local/Cellar/python/3.7.7/Frameworks/Python.framework/Versions/3.7/lib/python3.7/dbm/__init__.py", line 94, in open
    return mod.open(file, flag, mode)
_gdbm.error: [Errno 2] No such file or directory
2020-03-23 10:11:54,807 DEBUG graphviz.files write 743 bytes to '/Users/chenjiadong/Documents/uml0'
2020-03-23 10:11:54,810 DEBUG graphviz.backend run ['dot', '-Tpng', '-O', 'uml0']
2020-03-23 11:57:48,947 ERROR __main__ load
Traceback (most recent call last):
  File "/usr/local/Cellar/python/3.7.7/Frameworks/Python.framework/Versions/3.7/lib/python3.7/shelve.py", line 111, in __getitem__
    value = self.cache[key]
KeyError: 'dsds'

During handling of the above exception, another exception occurred:

Traceback (most recent call last):
  File "/Users/chenjiadong/Documents/funnyCode/PythonRepo/pyuml/main.py", line 108, in do_Load
    result = serializer.deserilize(splitargs.Input)
  File "/Users/chenjiadong/Documents/funnyCode/PythonRepo/pyuml/core/serializer.py", line 20, in deserilize
    data = db[name]
  File "/usr/local/Cellar/python/3.7.7/Frameworks/Python.framework/Versions/3.7/lib/python3.7/shelve.py", line 113, in __getitem__
    f = BytesIO(self.dict[key.encode(self.keyencoding)])
KeyError: b'dsds'
2020-03-23 11:57:51,839 ERROR __main__ load
Traceback (most recent call last):
  File "/Users/chenjiadong/Documents/funnyCode/PythonRepo/pyuml/main.py", line 106, in do_Load
    splitargs = parser.parse_args(shlex.split(args))
  File "/usr/local/Cellar/python/3.7.7/Frameworks/Python.framework/Versions/3.7/lib/python3.7/argparse.py", line 1758, in parse_args
    self.error(msg % ' '.join(argv))
  File "/usr/local/Cellar/python/3.7.7/Frameworks/Python.framework/Versions/3.7/lib/python3.7/argparse.py", line 2508, in error
    self.exit(2, _('%(prog)s: error: %(message)s\n') % args)
  File "/usr/local/Cellar/python/3.7.7/Frameworks/Python.framework/Versions/3.7/lib/python3.7/argparse.py", line 2495, in exit
    _sys.exit(status)
SystemExit: 2
2020-03-23 11:58:23,192 DEBUG graphviz.files write 69 bytes to '/Users/chenjiadong/Documents/funnyCode/PythonRepo/d/uml0'
2020-03-23 11:58:23,193 DEBUG graphviz.backend run ['dot', '-Tpng', '-O', 'uml0']
2020-03-23 11:58:23,304 DEBUG graphviz.files write 179 bytes to '/Users/chenjiadong/Documents/funnyCode/PythonRepo/d/uml1'
2020-03-23 11:58:23,304 DEBUG graphviz.backend run ['dot', '-Tpng', '-O', 'uml1']
2020-03-23 11:58:23,338 DEBUG graphviz.files write 81 bytes to '/Users/chenjiadong/Documents/funnyCode/PythonRepo/d/uml2'
2020-03-23 11:58:23,339 DEBUG graphviz.backend run ['dot', '-Tpng', '-O', 'uml2']
2020-03-23 11:58:23,369 DEBUG graphviz.files write 450 bytes to '/Users/chenjiadong/Documents/funnyCode/PythonRepo/d/uml3'
2020-03-23 11:58:23,370 DEBUG graphviz.backend run ['dot', '-Tpng', '-O', 'uml3']
2020-03-23 11:58:23,414 ERROR __main__ 2uml
Traceback (most recent call last):
  File "/Users/chenjiadong/Documents/funnyCode/PythonRepo/pyuml/main.py", line 90, in do_2uml
    dot_string = self._parse_to_dot(code_string)
  File "/Users/chenjiadong/Documents/funnyCode/PythonRepo/pyuml/main.py", line 125, in _parse_to_dot
    class_parser = self._parse_to_class_recoard(code_string)
  File "/Users/chenjiadong/Documents/funnyCode/PythonRepo/pyuml/main.py", line 137, in _parse_to_class_recoard
    tree = ast3.parse(code_string)
  File "/Users/chenjiadong/Documents/funnyCode/PythonRepo/pyuml/venv/lib/python3.7/site-packages/typed_ast/ast3.py", line 62, in parse
    return _ast3._parse(source, filename, mode, feature_version)
  File "<unknown>", line 1
    class ErrorClass
                   ^
SyntaxError: invalid syntax
2020-03-23 12:00:00,455 DEBUG graphviz.files write 743 bytes to '/Users/chenjiadong/Documents/funnyCode/PythonRepo/d_1/uml0'
2020-03-23 12:00:00,456 DEBUG graphviz.backend run ['dot', '-Tpng', '-O', 'uml0']
2020-03-23 12:00:58,666 DEBUG graphviz.files write 815 bytes to '/Users/chenjiadong/Documents/funnyCode/PythonRepo/pyuml/result/uml0'
2020-03-23 12:00:58,667 DEBUG graphviz.backend run ['dot', '-Tpng', '-O', 'uml0']
2020-03-23 12:01:12,138 ERROR __main__ load
Traceback (most recent call last):
  File "/usr/local/Cellar/python/3.7.7/Frameworks/Python.framework/Versions/3.7/lib/python3.7/shelve.py", line 111, in __getitem__
    value = self.cache[key]
KeyError: 'Movement'

During handling of the above exception, another exception occurred:

Traceback (most recent call last):
  File "/Users/chenjiadong/Documents/funnyCode/PythonRepo/pyuml/main.py", line 108, in do_Load
    result = serializer.deserilize(splitargs.Input)
  File "/Users/chenjiadong/Documents/funnyCode/PythonRepo/pyuml/core/serializer.py", line 20, in deserilize
    data = db[name]
  File "/usr/local/Cellar/python/3.7.7/Frameworks/Python.framework/Versions/3.7/lib/python3.7/shelve.py", line 113, in __getitem__
    f = BytesIO(self.dict[key.encode(self.keyencoding)])
KeyError: b'Movement'
2020-03-23 12:06:02,214 ERROR __main__ 2uml
Traceback (most recent call last):
  File "/Users/chenjiadong/Documents/funnyCode/PythonRepo/pyuml/main.py", line 82, in do_2uml
    splitargs = parser.parse_args(shlex.split(args))
  File "/usr/local/Cellar/python/3.7.7/Frameworks/Python.framework/Versions/3.7/lib/python3.7/argparse.py", line 1755, in parse_args
    args, argv = self.parse_known_args(args, namespace)
  File "/usr/local/Cellar/python/3.7.7/Frameworks/Python.framework/Versions/3.7/lib/python3.7/argparse.py", line 1787, in parse_known_args
    namespace, args = self._parse_known_args(args, namespace)
  File "/usr/local/Cellar/python/3.7.7/Frameworks/Python.framework/Versions/3.7/lib/python3.7/argparse.py", line 1993, in _parse_known_args
    start_index = consume_optional(start_index)
  File "/usr/local/Cellar/python/3.7.7/Frameworks/Python.framework/Versions/3.7/lib/python3.7/argparse.py", line 1933, in consume_optional
    take_action(action, args, option_string)
  File "/usr/local/Cellar/python/3.7.7/Frameworks/Python.framework/Versions/3.7/lib/python3.7/argparse.py", line 1861, in take_action
    action(self, namespace, argument_values, option_string)
  File "/usr/local/Cellar/python/3.7.7/Frameworks/Python.framework/Versions/3.7/lib/python3.7/argparse.py", line 1044, in __call__
    parser.exit()
  File "/usr/local/Cellar/python/3.7.7/Frameworks/Python.framework/Versions/3.7/lib/python3.7/argparse.py", line 2495, in exit
    _sys.exit(status)
SystemExit: 0
2020-03-23 12:09:27,148 ERROR __main__ load
Traceback (most recent call last):
  File "/Users/chenjiadong/Documents/funnyCode/PythonRepo/pyuml/main.py", line 106, in do_Load
    splitargs = parser.parse_args(shlex.split(args))
  File "/usr/local/Cellar/python/3.7.7/Frameworks/Python.framework/Versions/3.7/lib/python3.7/argparse.py", line 1755, in parse_args
    args, argv = self.parse_known_args(args, namespace)
  File "/usr/local/Cellar/python/3.7.7/Frameworks/Python.framework/Versions/3.7/lib/python3.7/argparse.py", line 1787, in parse_known_args
    namespace, args = self._parse_known_args(args, namespace)
  File "/usr/local/Cellar/python/3.7.7/Frameworks/Python.framework/Versions/3.7/lib/python3.7/argparse.py", line 1993, in _parse_known_args
    start_index = consume_optional(start_index)
  File "/usr/local/Cellar/python/3.7.7/Frameworks/Python.framework/Versions/3.7/lib/python3.7/argparse.py", line 1933, in consume_optional
    take_action(action, args, option_string)
  File "/usr/local/Cellar/python/3.7.7/Frameworks/Python.framework/Versions/3.7/lib/python3.7/argparse.py", line 1861, in take_action
    action(self, namespace, argument_values, option_string)
  File "/usr/local/Cellar/python/3.7.7/Frameworks/Python.framework/Versions/3.7/lib/python3.7/argparse.py", line 1044, in __call__
    parser.exit()
  File "/usr/local/Cellar/python/3.7.7/Frameworks/Python.framework/Versions/3.7/lib/python3.7/argparse.py", line 2495, in exit
    _sys.exit(status)
SystemExit: 0
2020-03-23 12:10:00,617 ERROR __main__ load
Traceback (most recent call last):
  File "/Users/chenjiadong/Documents/funnyCode/PythonRepo/pyuml/main.py", line 106, in do_Load
    splitargs = parser.parse_args(shlex.split(args))
  File "/usr/local/Cellar/python/3.7.7/Frameworks/Python.framework/Versions/3.7/lib/python3.7/argparse.py", line 1755, in parse_args
    args, argv = self.parse_known_args(args, namespace)
  File "/usr/local/Cellar/python/3.7.7/Frameworks/Python.framework/Versions/3.7/lib/python3.7/argparse.py", line 1787, in parse_known_args
    namespace, args = self._parse_known_args(args, namespace)
  File "/usr/local/Cellar/python/3.7.7/Frameworks/Python.framework/Versions/3.7/lib/python3.7/argparse.py", line 1993, in _parse_known_args
    start_index = consume_optional(start_index)
  File "/usr/local/Cellar/python/3.7.7/Frameworks/Python.framework/Versions/3.7/lib/python3.7/argparse.py", line 1933, in consume_optional
    take_action(action, args, option_string)
  File "/usr/local/Cellar/python/3.7.7/Frameworks/Python.framework/Versions/3.7/lib/python3.7/argparse.py", line 1861, in take_action
    action(self, namespace, argument_values, option_string)
  File "/usr/local/Cellar/python/3.7.7/Frameworks/Python.framework/Versions/3.7/lib/python3.7/argparse.py", line 1044, in __call__
    parser.exit()
  File "/usr/local/Cellar/python/3.7.7/Frameworks/Python.framework/Versions/3.7/lib/python3.7/argparse.py", line 2495, in exit
    _sys.exit(status)
SystemExit: 0
2020-03-23 12:10:35,073 ERROR __main__ load
Traceback (most recent call last):
  File "/Users/chenjiadong/Documents/funnyCode/PythonRepo/pyuml/main.py", line 106, in do_Load
    splitargs = parser.parse_args(shlex.split(args))
  File "/usr/local/Cellar/python/3.7.7/Frameworks/Python.framework/Versions/3.7/lib/python3.7/argparse.py", line 1755, in parse_args
    args, argv = self.parse_known_args(args, namespace)
  File "/usr/local/Cellar/python/3.7.7/Frameworks/Python.framework/Versions/3.7/lib/python3.7/argparse.py", line 1787, in parse_known_args
    namespace, args = self._parse_known_args(args, namespace)
  File "/usr/local/Cellar/python/3.7.7/Frameworks/Python.framework/Versions/3.7/lib/python3.7/argparse.py", line 1993, in _parse_known_args
    start_index = consume_optional(start_index)
  File "/usr/local/Cellar/python/3.7.7/Frameworks/Python.framework/Versions/3.7/lib/python3.7/argparse.py", line 1933, in consume_optional
    take_action(action, args, option_string)
  File "/usr/local/Cellar/python/3.7.7/Frameworks/Python.framework/Versions/3.7/lib/python3.7/argparse.py", line 1861, in take_action
    action(self, namespace, argument_values, option_string)
  File "/usr/local/Cellar/python/3.7.7/Frameworks/Python.framework/Versions/3.7/lib/python3.7/argparse.py", line 1044, in __call__
    parser.exit()
  File "/usr/local/Cellar/python/3.7.7/Frameworks/Python.framework/Versions/3.7/lib/python3.7/argparse.py", line 2495, in exit
    _sys.exit(status)
SystemExit: 0
2020-03-23 12:14:30,094 ERROR __main__ 2uml
Traceback (most recent call last):
  File "/Users/chenjiadong/Documents/funnyCode/PythonRepo/pyuml/main.py", line 87, in do_2uml
    code_string_list = loader.load_from_file_or_directory(input_path)
  File "/Users/chenjiadong/Documents/funnyCode/PythonRepo/pyuml/core/loader.py", line 9, in load_from_file_or_directory
    raise IOError
OSError
2020-03-23 12:14:53,804 ERROR __main__ 2uml
Traceback (most recent call last):
  File "/Users/chenjiadong/Documents/funnyCode/PythonRepo/pyuml/main.py", line 87, in do_2uml
    code_string_list = loader.load_from_file_or_directory(input_path)
  File "/Users/chenjiadong/Documents/funnyCode/PythonRepo/pyuml/core/loader.py", line 9, in load_from_file_or_directory
    raise IOError
OSError
2020-03-23 12:15:26,887 ERROR __main__ 2uml
Traceback (most recent call last):
  File "/Users/chenjiadong/Documents/funnyCode/PythonRepo/pyuml/main.py", line 87, in do_2uml
    code_string_list = loader.load_from_file_or_directory(input_path)
  File "/Users/chenjiadong/Documents/funnyCode/PythonRepo/pyuml/core/loader.py", line 9, in load_from_file_or_directory
    raise IOError
OSError
2020-03-23 12:16:12,351 ERROR __main__ 2uml
Traceback (most recent call last):
  File "/Users/chenjiadong/Documents/funnyCode/PythonRepo/pyuml/main.py", line 87, in do_2uml
    code_string_list = loader.load_from_file_or_directory(input_path)
  File "/Users/chenjiadong/Documents/funnyCode/PythonRepo/pyuml/core/loader.py", line 9, in load_from_file_or_directory
    raise IOError
OSError
2020-03-23 12:16:27,959 ERROR __main__ load
Traceback (most recent call last):
  File "/usr/local/Cellar/python/3.7.7/Frameworks/Python.framework/Versions/3.7/lib/python3.7/shelve.py", line 111, in __getitem__
    value = self.cache[key]
KeyError: 'car'

During handling of the above exception, another exception occurred:

Traceback (most recent call last):
  File "/Users/chenjiadong/Documents/funnyCode/PythonRepo/pyuml/main.py", line 108, in do_Load
    result = serializer.deserilize(splitargs.Input)
  File "/Users/chenjiadong/Documents/funnyCode/PythonRepo/pyuml/core/serializer.py", line 20, in deserilize
    data = db[name]
  File "/usr/local/Cellar/python/3.7.7/Frameworks/Python.framework/Versions/3.7/lib/python3.7/shelve.py", line 113, in __getitem__
    f = BytesIO(self.dict[key.encode(self.keyencoding)])
KeyError: b'car'
2020-03-23 12:16:58,429 ERROR __main__ load
Traceback (most recent call last):
  File "/usr/local/Cellar/python/3.7.7/Frameworks/Python.framework/Versions/3.7/lib/python3.7/shelve.py", line 111, in __getitem__
    value = self.cache[key]
KeyError: 'd'

During handling of the above exception, another exception occurred:

Traceback (most recent call last):
  File "/Users/chenjiadong/Documents/funnyCode/PythonRepo/pyuml/main.py", line 108, in do_Load
    result = serializer.deserilize(splitargs.Input)
  File "/Users/chenjiadong/Documents/funnyCode/PythonRepo/pyuml/core/serializer.py", line 20, in deserilize
    data = db[name]
  File "/usr/local/Cellar/python/3.7.7/Frameworks/Python.framework/Versions/3.7/lib/python3.7/shelve.py", line 113, in __getitem__
    f = BytesIO(self.dict[key.encode(self.keyencoding)])
KeyError: b'd'
2020-03-23 12:17:00,611 ERROR __main__ load
Traceback (most recent call last):
  File "/usr/local/Cellar/python/3.7.7/Frameworks/Python.framework/Versions/3.7/lib/python3.7/shelve.py", line 111, in __getitem__
    value = self.cache[key]
KeyError: 'Car'

During handling of the above exception, another exception occurred:

Traceback (most recent call last):
  File "/Users/chenjiadong/Documents/funnyCode/PythonRepo/pyuml/main.py", line 108, in do_Load
    result = serializer.deserilize(splitargs.Input)
  File "/Users/chenjiadong/Documents/funnyCode/PythonRepo/pyuml/core/serializer.py", line 20, in deserilize
    data = db[name]
  File "/usr/local/Cellar/python/3.7.7/Frameworks/Python.framework/Versions/3.7/lib/python3.7/shelve.py", line 113, in __getitem__
    f = BytesIO(self.dict[key.encode(self.keyencoding)])
KeyError: b'Car'
2020-03-23 12:17:07,002 ERROR __main__ 2uml
Traceback (most recent call last):
  File "/Users/chenjiadong/Documents/funnyCode/PythonRepo/pyuml/main.py", line 87, in do_2uml
    code_string_list = loader.load_from_file_or_directory(input_path)
  File "/Users/chenjiadong/Documents/funnyCode/PythonRepo/pyuml/core/loader.py", line 9, in load_from_file_or_directory
    raise IOError
OSError
2020-03-23 12:17:15,788 DEBUG graphviz.files write 69 bytes to '/Users/chenjiadong/Documents/funnyCode/PythonRepo/uml0'
2020-03-23 12:17:15,789 DEBUG graphviz.backend run ['dot', '-Tpng', '-O', 'uml0']
2020-03-23 14:05:26,029 ERROR __main__ load
Traceback (most recent call last):
  File "/Users/chenjiadong/Documents/funnyCode/PythonRepo/pyuml/main.py", line 106, in do_load
    splitargs = parser.parse_args(shlex.split(args))
  File "/usr/local/Cellar/python/3.7.7/Frameworks/Python.framework/Versions/3.7/lib/python3.7/argparse.py", line 1755, in parse_args
    args, argv = self.parse_known_args(args, namespace)
  File "/usr/local/Cellar/python/3.7.7/Frameworks/Python.framework/Versions/3.7/lib/python3.7/argparse.py", line 1787, in parse_known_args
    namespace, args = self._parse_known_args(args, namespace)
  File "/usr/local/Cellar/python/3.7.7/Frameworks/Python.framework/Versions/3.7/lib/python3.7/argparse.py", line 2022, in _parse_known_args
    ', '.join(required_actions))
  File "/usr/local/Cellar/python/3.7.7/Frameworks/Python.framework/Versions/3.7/lib/python3.7/argparse.py", line 2508, in error
    self.exit(2, _('%(prog)s: error: %(message)s\n') % args)
  File "/usr/local/Cellar/python/3.7.7/Frameworks/Python.framework/Versions/3.7/lib/python3.7/argparse.py", line 2495, in exit
    _sys.exit(status)
SystemExit: 2
2020-03-23 14:05:31,843 ERROR __main__ load
Traceback (most recent call last):
  File "/usr/local/Cellar/python/3.7.7/Frameworks/Python.framework/Versions/3.7/lib/python3.7/shelve.py", line 111, in __getitem__
    value = self.cache[key]
KeyError: 'Car'

During handling of the above exception, another exception occurred:

Traceback (most recent call last):
  File "/Users/chenjiadong/Documents/funnyCode/PythonRepo/pyuml/main.py", line 108, in do_load
    result = serializer.deserilize(splitargs.Input)
  File "/Users/chenjiadong/Documents/funnyCode/PythonRepo/pyuml/core/serializer.py", line 20, in deserilize
    data = db[name]
  File "/usr/local/Cellar/python/3.7.7/Frameworks/Python.framework/Versions/3.7/lib/python3.7/shelve.py", line 113, in __getitem__
    f = BytesIO(self.dict[key.encode(self.keyencoding)])
KeyError: b'Car'
2020-03-23 14:06:20,952 DEBUG graphviz.files write 815 bytes to '/Users/chenjiadong/Documents/uml0'
2020-03-23 14:06:20,954 DEBUG graphviz.backend run ['dot', '-Tpng', '-O', 'uml0']
2020-03-23 14:07:04,051 ERROR __main__ load
Traceback (most recent call last):
  File "/Users/chenjiadong/Documents/funnyCode/PythonRepo/pyuml/main.py", line 106, in do_load
    splitargs = parser.parse_args(shlex.split(args))
  File "/usr/local/Cellar/python/3.7.7/Frameworks/Python.framework/Versions/3.7/lib/python3.7/argparse.py", line 1755, in parse_args
    args, argv = self.parse_known_args(args, namespace)
  File "/usr/local/Cellar/python/3.7.7/Frameworks/Python.framework/Versions/3.7/lib/python3.7/argparse.py", line 1787, in parse_known_args
    namespace, args = self._parse_known_args(args, namespace)
  File "/usr/local/Cellar/python/3.7.7/Frameworks/Python.framework/Versions/3.7/lib/python3.7/argparse.py", line 1993, in _parse_known_args
    start_index = consume_optional(start_index)
  File "/usr/local/Cellar/python/3.7.7/Frameworks/Python.framework/Versions/3.7/lib/python3.7/argparse.py", line 1933, in consume_optional
    take_action(action, args, option_string)
  File "/usr/local/Cellar/python/3.7.7/Frameworks/Python.framework/Versions/3.7/lib/python3.7/argparse.py", line 1861, in take_action
    action(self, namespace, argument_values, option_string)
  File "/usr/local/Cellar/python/3.7.7/Frameworks/Python.framework/Versions/3.7/lib/python3.7/argparse.py", line 1044, in __call__
    parser.exit()
  File "/usr/local/Cellar/python/3.7.7/Frameworks/Python.framework/Versions/3.7/lib/python3.7/argparse.py", line 2495, in exit
    _sys.exit(status)
SystemExit: 0
2020-03-23 14:13:31,642 ERROR __main__ load
Traceback (most recent call last):
  File "/Users/chenjiadong/Documents/funnyCode/PythonRepo/pyuml/main.py", line 106, in do_load
    splitargs = parser.parse_args(shlex.split(args))
  File "/usr/local/Cellar/python/3.7.7/Frameworks/Python.framework/Versions/3.7/lib/python3.7/argparse.py", line 1755, in parse_args
    args, argv = self.parse_known_args(args, namespace)
  File "/usr/local/Cellar/python/3.7.7/Frameworks/Python.framework/Versions/3.7/lib/python3.7/argparse.py", line 1787, in parse_known_args
    namespace, args = self._parse_known_args(args, namespace)
  File "/usr/local/Cellar/python/3.7.7/Frameworks/Python.framework/Versions/3.7/lib/python3.7/argparse.py", line 2022, in _parse_known_args
    ', '.join(required_actions))
  File "/usr/local/Cellar/python/3.7.7/Frameworks/Python.framework/Versions/3.7/lib/python3.7/argparse.py", line 2508, in error
    self.exit(2, _('%(prog)s: error: %(message)s\n') % args)
  File "/usr/local/Cellar/python/3.7.7/Frameworks/Python.framework/Versions/3.7/lib/python3.7/argparse.py", line 2495, in exit
    _sys.exit(status)
SystemExit: 2
2020-03-23 14:14:20,398 ERROR __main__ load
Traceback (most recent call last):
  File "/Users/chenjiadong/Documents/funnyCode/PythonRepo/pyuml/main.py", line 106, in do_load
    splitargs = parser.parse_args(shlex.split(args))
  File "/usr/local/Cellar/python/3.7.7/Frameworks/Python.framework/Versions/3.7/lib/python3.7/argparse.py", line 1755, in parse_args
    args, argv = self.parse_known_args(args, namespace)
  File "/usr/local/Cellar/python/3.7.7/Frameworks/Python.framework/Versions/3.7/lib/python3.7/argparse.py", line 1787, in parse_known_args
    namespace, args = self._parse_known_args(args, namespace)
  File "/usr/local/Cellar/python/3.7.7/Frameworks/Python.framework/Versions/3.7/lib/python3.7/argparse.py", line 1993, in _parse_known_args
    start_index = consume_optional(start_index)
  File "/usr/local/Cellar/python/3.7.7/Frameworks/Python.framework/Versions/3.7/lib/python3.7/argparse.py", line 1933, in consume_optional
    take_action(action, args, option_string)
  File "/usr/local/Cellar/python/3.7.7/Frameworks/Python.framework/Versions/3.7/lib/python3.7/argparse.py", line 1861, in take_action
    action(self, namespace, argument_values, option_string)
  File "/usr/local/Cellar/python/3.7.7/Frameworks/Python.framework/Versions/3.7/lib/python3.7/argparse.py", line 1044, in __call__
    parser.exit()
  File "/usr/local/Cellar/python/3.7.7/Frameworks/Python.framework/Versions/3.7/lib/python3.7/argparse.py", line 2495, in exit
    _sys.exit(status)
SystemExit: 0
2020-03-23 15:26:39,108 ERROR __main__ 2uml
Traceback (most recent call last):
  File "/Users/chenjiadong/Documents/funnyCode/PythonRepo/pyuml/main.py", line 82, in do_2uml
    splitargs = parser.parse_args(shlex.split(args))
  File "/usr/local/Cellar/python/3.7.7/Frameworks/Python.framework/Versions/3.7/lib/python3.7/argparse.py", line 1755, in parse_args
    args, argv = self.parse_known_args(args, namespace)
  File "/usr/local/Cellar/python/3.7.7/Frameworks/Python.framework/Versions/3.7/lib/python3.7/argparse.py", line 1787, in parse_known_args
    namespace, args = self._parse_known_args(args, namespace)
  File "/usr/local/Cellar/python/3.7.7/Frameworks/Python.framework/Versions/3.7/lib/python3.7/argparse.py", line 2022, in _parse_known_args
    ', '.join(required_actions))
  File "/usr/local/Cellar/python/3.7.7/Frameworks/Python.framework/Versions/3.7/lib/python3.7/argparse.py", line 2508, in error
    self.exit(2, _('%(prog)s: error: %(message)s\n') % args)
  File "/usr/local/Cellar/python/3.7.7/Frameworks/Python.framework/Versions/3.7/lib/python3.7/argparse.py", line 2495, in exit
    _sys.exit(status)
SystemExit: 2
2020-03-23 15:26:52,553 ERROR __main__ load
Traceback (most recent call last):
  File "/usr/local/Cellar/python/3.7.7/Frameworks/Python.framework/Versions/3.7/lib/python3.7/shelve.py", line 111, in __getitem__
    value = self.cache[key]
KeyError: 'd'

During handling of the above exception, another exception occurred:

Traceback (most recent call last):
  File "/Users/chenjiadong/Documents/funnyCode/PythonRepo/pyuml/main.py", line 108, in do_load
    result = serializer.deserilize(splitargs.Input)
  File "/Users/chenjiadong/Documents/funnyCode/PythonRepo/pyuml/core/serializer.py", line 20, in deserilize
    data = db[name]
  File "/usr/local/Cellar/python/3.7.7/Frameworks/Python.framework/Versions/3.7/lib/python3.7/shelve.py", line 113, in __getitem__
    f = BytesIO(self.dict[key.encode(self.keyencoding)])
KeyError: b'd'
2020-03-23 15:58:47,937 ERROR __main__ 2uml
Traceback (most recent call last):
  File "/Users/chenjiadong/Documents/funnyCode/PythonRepo/pyuml/main.py", line 82, in do_2uml
    splitargs = parser.parse_args(shlex.split(args))
  File "/usr/local/Cellar/python/3.7.7/Frameworks/Python.framework/Versions/3.7/lib/python3.7/argparse.py", line 1755, in parse_args
    args, argv = self.parse_known_args(args, namespace)
  File "/usr/local/Cellar/python/3.7.7/Frameworks/Python.framework/Versions/3.7/lib/python3.7/argparse.py", line 1787, in parse_known_args
    namespace, args = self._parse_known_args(args, namespace)
  File "/usr/local/Cellar/python/3.7.7/Frameworks/Python.framework/Versions/3.7/lib/python3.7/argparse.py", line 1993, in _parse_known_args
    start_index = consume_optional(start_index)
  File "/usr/local/Cellar/python/3.7.7/Frameworks/Python.framework/Versions/3.7/lib/python3.7/argparse.py", line 1933, in consume_optional
    take_action(action, args, option_string)
  File "/usr/local/Cellar/python/3.7.7/Frameworks/Python.framework/Versions/3.7/lib/python3.7/argparse.py", line 1861, in take_action
    action(self, namespace, argument_values, option_string)
  File "/usr/local/Cellar/python/3.7.7/Frameworks/Python.framework/Versions/3.7/lib/python3.7/argparse.py", line 1044, in __call__
    parser.exit()
  File "/usr/local/Cellar/python/3.7.7/Frameworks/Python.framework/Versions/3.7/lib/python3.7/argparse.py", line 2495, in exit
    _sys.exit(status)
SystemExit: 0
2020-03-23 16:22:58,182 ERROR __main__ 2uml
Traceback (most recent call last):
  File "/Users/chenjiadong/Documents/funnyCode/PythonRepo/pyuml/main.py", line 82, in do_2uml
    splitargs = parser.parse_args(shlex.split(args))
  File "/usr/local/Cellar/python/3.7.7/Frameworks/Python.framework/Versions/3.7/lib/python3.7/argparse.py", line 1755, in parse_args
    args, argv = self.parse_known_args(args, namespace)
  File "/usr/local/Cellar/python/3.7.7/Frameworks/Python.framework/Versions/3.7/lib/python3.7/argparse.py", line 1787, in parse_known_args
    namespace, args = self._parse_known_args(args, namespace)
  File "/usr/local/Cellar/python/3.7.7/Frameworks/Python.framework/Versions/3.7/lib/python3.7/argparse.py", line 2022, in _parse_known_args
    ', '.join(required_actions))
  File "/usr/local/Cellar/python/3.7.7/Frameworks/Python.framework/Versions/3.7/lib/python3.7/argparse.py", line 2508, in error
    self.exit(2, _('%(prog)s: error: %(message)s\n') % args)
  File "/usr/local/Cellar/python/3.7.7/Frameworks/Python.framework/Versions/3.7/lib/python3.7/argparse.py", line 2495, in exit
    _sys.exit(status)
SystemExit: 2
2020-03-23 16:23:01,221 ERROR __main__ 2uml
Traceback (most recent call last):
  File "/Users/chenjiadong/Documents/funnyCode/PythonRepo/pyuml/main.py", line 82, in do_2uml
    splitargs = parser.parse_args(shlex.split(args))
  File "/usr/local/Cellar/python/3.7.7/Frameworks/Python.framework/Versions/3.7/lib/python3.7/argparse.py", line 1755, in parse_args
    args, argv = self.parse_known_args(args, namespace)
  File "/usr/local/Cellar/python/3.7.7/Frameworks/Python.framework/Versions/3.7/lib/python3.7/argparse.py", line 1787, in parse_known_args
    namespace, args = self._parse_known_args(args, namespace)
  File "/usr/local/Cellar/python/3.7.7/Frameworks/Python.framework/Versions/3.7/lib/python3.7/argparse.py", line 2022, in _parse_known_args
    ', '.join(required_actions))
  File "/usr/local/Cellar/python/3.7.7/Frameworks/Python.framework/Versions/3.7/lib/python3.7/argparse.py", line 2508, in error
    self.exit(2, _('%(prog)s: error: %(message)s\n') % args)
  File "/usr/local/Cellar/python/3.7.7/Frameworks/Python.framework/Versions/3.7/lib/python3.7/argparse.py", line 2495, in exit
    _sys.exit(status)
SystemExit: 2
2020-03-23 16:23:04,560 ERROR __main__ 2uml
Traceback (most recent call last):
  File "/Users/chenjiadong/Documents/funnyCode/PythonRepo/pyuml/main.py", line 82, in do_2uml
    splitargs = parser.parse_args(shlex.split(args))
  File "/usr/local/Cellar/python/3.7.7/Frameworks/Python.framework/Versions/3.7/lib/python3.7/argparse.py", line 1755, in parse_args
    args, argv = self.parse_known_args(args, namespace)
  File "/usr/local/Cellar/python/3.7.7/Frameworks/Python.framework/Versions/3.7/lib/python3.7/argparse.py", line 1787, in parse_known_args
    namespace, args = self._parse_known_args(args, namespace)
  File "/usr/local/Cellar/python/3.7.7/Frameworks/Python.framework/Versions/3.7/lib/python3.7/argparse.py", line 1993, in _parse_known_args
    start_index = consume_optional(start_index)
  File "/usr/local/Cellar/python/3.7.7/Frameworks/Python.framework/Versions/3.7/lib/python3.7/argparse.py", line 1933, in consume_optional
    take_action(action, args, option_string)
  File "/usr/local/Cellar/python/3.7.7/Frameworks/Python.framework/Versions/3.7/lib/python3.7/argparse.py", line 1861, in take_action
    action(self, namespace, argument_values, option_string)
  File "/usr/local/Cellar/python/3.7.7/Frameworks/Python.framework/Versions/3.7/lib/python3.7/argparse.py", line 1044, in __call__
    parser.exit()
  File "/usr/local/Cellar/python/3.7.7/Frameworks/Python.framework/Versions/3.7/lib/python3.7/argparse.py", line 2495, in exit
    _sys.exit(status)
SystemExit: 0
2020-03-27 20:29:39,048 ERROR __main__ 2uml
Traceback (most recent call last):
  File "/Users/chenjiadong/Documents/funnyCode/PythonRepo/pyuml/main.py", line 84, in do_2uml
    input_path = splitargs.Input
AttributeError: 'Namespace' object has no attribute 'Input'
2020-03-27 20:30:23,685 ERROR __main__ 2uml
Traceback (most recent call last):
  File "/Users/chenjiadong/Documents/funnyCode/PythonRepo/pyuml/main.py", line 84, in do_2uml
    input_path = splitargs.Input
AttributeError: 'Namespace' object has no attribute 'Input'
2020-03-27 20:32:50,903 ERROR __main__ 2uml
Traceback (most recent call last):
  File "/Users/chenjiadong/Documents/funnyCode/PythonRepo/pyuml/main.py", line 82, in do_2uml
    splitargs = parser.parse_args(shlex.split(args))
  File "/usr/local/Cellar/python/3.7.7/Frameworks/Python.framework/Versions/3.7/lib/python3.7/argparse.py", line 1755, in parse_args
    args, argv = self.parse_known_args(args, namespace)
  File "/usr/local/Cellar/python/3.7.7/Frameworks/Python.framework/Versions/3.7/lib/python3.7/argparse.py", line 1787, in parse_known_args
    namespace, args = self._parse_known_args(args, namespace)
  File "/usr/local/Cellar/python/3.7.7/Frameworks/Python.framework/Versions/3.7/lib/python3.7/argparse.py", line 2022, in _parse_known_args
    ', '.join(required_actions))
  File "/usr/local/Cellar/python/3.7.7/Frameworks/Python.framework/Versions/3.7/lib/python3.7/argparse.py", line 2508, in error
    self.exit(2, _('%(prog)s: error: %(message)s\n') % args)
  File "/usr/local/Cellar/python/3.7.7/Frameworks/Python.framework/Versions/3.7/lib/python3.7/argparse.py", line 2495, in exit
    _sys.exit(status)
SystemExit: 2
2020-03-27 20:33:07,497 ERROR __main__ 2uml
Traceback (most recent call last):
  File "/Users/chenjiadong/Documents/funnyCode/PythonRepo/pyuml/main.py", line 90, in do_2uml
    dot_string = self._parse_to_dot(code_string)
  File "/Users/chenjiadong/Documents/funnyCode/PythonRepo/pyuml/main.py", line 125, in _parse_to_dot
    class_parser = self._parse_to_class_recoard(code_string)
  File "/Users/chenjiadong/Documents/funnyCode/PythonRepo/pyuml/main.py", line 139, in _parse_to_class_recoard
    class_parser.visit(tree)
  File "/Users/chenjiadong/Documents/funnyCode/PythonRepo/pyuml/venv/lib/python3.7/site-packages/typed_ast/ast3.py", line 279, in visit
    return visitor(node)
  File "/Users/chenjiadong/Documents/funnyCode/PythonRepo/pyuml/core/parser.py", line 63, in visit_Module
    assert isinstance(node, Module)
AssertionError
2020-03-27 20:36:04,594 ERROR __main__ 2uml
Traceback (most recent call last):
  File "/Users/chenjiadong/Documents/funnyCode/PythonRepo/pyuml/main.py", line 90, in do_2uml
    dot_string = self._parse_to_dot(code_string)
  File "/Users/chenjiadong/Documents/funnyCode/PythonRepo/pyuml/main.py", line 125, in _parse_to_dot
    class_parser = self._parse_to_class_recoard(code_string)
  File "/Users/chenjiadong/Documents/funnyCode/PythonRepo/pyuml/main.py", line 139, in _parse_to_class_recoard
    class_parser.visit(tree)
  File "/Users/chenjiadong/Documents/funnyCode/PythonRepo/pyuml/venv/lib/python3.7/site-packages/typed_ast/ast3.py", line 279, in visit
    return visitor(node)
  File "/Users/chenjiadong/Documents/funnyCode/PythonRepo/pyuml/core/parser.py", line 64, in visit_Module
    assert isinstance(node, ModuleDef)
NameError: name 'ModuleDef' is not defined
2020-03-27 20:37:20,876 DEBUG graphviz.files write 815 bytes to '/Users/chenjiadong/Documents/funnyCode/PythonRepo/uml0'
2020-03-27 20:37:20,878 DEBUG graphviz.backend run ['dot', '-Tpng', '-O', 'uml0']
2020-03-27 20:42:56,244 DEBUG graphviz.files write 815 bytes to '/Users/chenjiadong/Documents/funnyCode/uml0'
2020-03-27 20:42:56,245 DEBUG graphviz.backend run ['dot', '-Tpng', '-O', 'uml0']
2020-03-27 20:46:36,971 ERROR __main__ 2uml
Traceback (most recent call last):
  File "/Users/chenjiadong/Documents/funnyCode/PythonRepo/pyuml/main.py", line 90, in do_2uml
    dot_string = self._parse_to_dot(code_string)
  File "/Users/chenjiadong/Documents/funnyCode/PythonRepo/pyuml/main.py", line 127, in _parse_to_dot
    dot_string = DotWriter().write(class_parser.classes_list)
  File "/Users/chenjiadong/Documents/funnyCode/PythonRepo/pyuml/core/writer.py", line 14, in write
    dot_string = self.write_node(dot_string, classes)
  File "/Users/chenjiadong/Documents/funnyCode/PythonRepo/pyuml/core/writer.py", line 35, in write_node
    dot_string = self._write_class(dot_string, index, classes[index].name)
TypeError: _write_class() takes 3 positional arguments but 4 were given
2020-03-27 20:47:07,913 DEBUG graphviz.files write 815 bytes to '/Users/chenjiadong/Documents/funnyCode/uml0'
2020-03-27 20:47:07,914 DEBUG graphviz.backend run ['dot', '-Tpng', '-O', 'uml0']
2020-03-27 20:51:01,597 DEBUG graphviz.files write 815 bytes to '/Users/chenjiadong/Documents/funnyCode/uml0'
2020-03-27 20:51:01,600 DEBUG graphviz.backend run ['dot', '-Tpng', '-O', 'uml0']
2020-03-27 20:53:58,644 DEBUG graphviz.files write 815 bytes to '/Users/chenjiadong/Documents/funnyCode/uml0'
2020-03-27 20:53:58,647 DEBUG graphviz.backend run ['dot', '-Tpng', '-O', 'uml0']
2020-03-29 13:34:07,595 ERROR utilities.logger 2uml
Traceback (most recent call last):
  File "/Users/chenjiadong/Documents/funnyCode/PythonRepo/pyuml/main.py", line 80, in do_2uml
    splitargs = parser.parse_args(shlex.split(args))
  File "/usr/local/Cellar/python/3.7.7/Frameworks/Python.framework/Versions/3.7/lib/python3.7/argparse.py", line 1755, in parse_args
    args, argv = self.parse_known_args(args, namespace)
  File "/usr/local/Cellar/python/3.7.7/Frameworks/Python.framework/Versions/3.7/lib/python3.7/argparse.py", line 1787, in parse_known_args
    namespace, args = self._parse_known_args(args, namespace)
  File "/usr/local/Cellar/python/3.7.7/Frameworks/Python.framework/Versions/3.7/lib/python3.7/argparse.py", line 2022, in _parse_known_args
    ', '.join(required_actions))
  File "/usr/local/Cellar/python/3.7.7/Frameworks/Python.framework/Versions/3.7/lib/python3.7/argparse.py", line 2508, in error
    self.exit(2, _('%(prog)s: error: %(message)s\n') % args)
  File "/usr/local/Cellar/python/3.7.7/Frameworks/Python.framework/Versions/3.7/lib/python3.7/argparse.py", line 2495, in exit
    _sys.exit(status)
SystemExit: 2
2020-03-29 13:37:01,784 DEBUG graphviz.files write 776 bytes to '/Users/chenjiadong/Documents/funnyCode/PythonRepo/uml0'
2020-03-29 13:37:01,785 DEBUG graphviz.backend run ['dot', '-Tpng', '-O', 'uml0']
2020-03-29 13:39:14,314 ERROR utilities.logger 2uml
Traceback (most recent call last):
  File "/Users/chenjiadong/Documents/funnyCode/PythonRepo/pyuml/main.py", line 88, in do_2uml
    dot_string = self._parse_to_dot(code_string)
  File "/Users/chenjiadong/Documents/funnyCode/PythonRepo/pyuml/main.py", line 118, in _parse_to_dot
    class_parser = self._parse_to_class_recoard(code_string)
  File "/Users/chenjiadong/Documents/funnyCode/PythonRepo/pyuml/main.py", line 132, in _parse_to_class_recoard
    class_parser.visit(tree)
  File "/Users/chenjiadong/Documents/funnyCode/PythonRepo/pyuml/venv/lib/python3.7/site-packages/typed_ast/ast3.py", line 279, in visit
    return visitor(node)
  File "/Users/chenjiadong/Documents/funnyCode/PythonRepo/pyuml/core/parser.py", line 69, in visit_Module
    self.visit(n)
  File "/Users/chenjiadong/Documents/funnyCode/PythonRepo/pyuml/venv/lib/python3.7/site-packages/typed_ast/ast3.py", line 279, in visit
    return visitor(node)
  File "/Users/chenjiadong/Documents/funnyCode/PythonRepo/pyuml/core/parser.py", line 108, in visit_ClassDef
    if isinstance(target.value, ast3.Name):
  File "/Users/chenjiadong/Documents/funnyCode/PythonRepo/pyuml/core/parser.py", line 108, in visit_ClassDef
    if isinstance(target.value, ast3.Name):
  File "_pydevd_bundle/pydevd_cython_darwin_37_64.pyx", line 1060, in _pydevd_bundle.pydevd_cython_darwin_37_64.SafeCallWrapper.__call__
  File "_pydevd_bundle/pydevd_cython_darwin_37_64.pyx", line 566, in _pydevd_bundle.pydevd_cython_darwin_37_64.PyDBFrame.trace_dispatch
  File "_pydevd_bundle/pydevd_cython_darwin_37_64.pyx", line 855, in _pydevd_bundle.pydevd_cython_darwin_37_64.PyDBFrame.trace_dispatch
  File "_pydevd_bundle/pydevd_cython_darwin_37_64.pyx", line 846, in _pydevd_bundle.pydevd_cython_darwin_37_64.PyDBFrame.trace_dispatch
  File "_pydevd_bundle/pydevd_cython_darwin_37_64.pyx", line 288, in _pydevd_bundle.pydevd_cython_darwin_37_64.PyDBFrame.do_wait_suspend
  File "/Applications/PyCharm CE.app/Contents/plugins/python-ce/helpers/pydev/pydevd.py", line 1099, in do_wait_suspend
    self._do_wait_suspend(thread, frame, event, arg, suspend_type, from_this_thread)
  File "/Applications/PyCharm CE.app/Contents/plugins/python-ce/helpers/pydev/pydevd.py", line 1114, in _do_wait_suspend
    time.sleep(0.01)
KeyboardInterrupt
2020-03-29 13:42:53,789 ERROR utilities.logger 2uml
Traceback (most recent call last):
  File "/Users/chenjiadong/Documents/funnyCode/PythonRepo/pyuml/main.py", line 88, in do_2uml
    dot_string = self._parse_to_dot(code_string)
  File "/Users/chenjiadong/Documents/funnyCode/PythonRepo/pyuml/main.py", line 118, in _parse_to_dot
    class_parser = self._parse_to_class_recoard(code_string)
  File "/Users/chenjiadong/Documents/funnyCode/PythonRepo/pyuml/main.py", line 132, in _parse_to_class_recoard
    class_parser.visit(tree)
  File "/Users/chenjiadong/Documents/funnyCode/PythonRepo/pyuml/venv/lib/python3.7/site-packages/typed_ast/ast3.py", line 279, in visit
    return visitor(node)
  File "/Users/chenjiadong/Documents/funnyCode/PythonRepo/pyuml/core/parser.py", line 69, in visit_Module
    self.visit(n)
  File "/Users/chenjiadong/Documents/funnyCode/PythonRepo/pyuml/venv/lib/python3.7/site-packages/typed_ast/ast3.py", line 279, in visit
    return visitor(node)
  File "/Users/chenjiadong/Documents/funnyCode/PythonRepo/pyuml/core/parser.py", line 93, in visit_ClassDef
    if child.name.startswith('__'):
  File "/Users/chenjiadong/Documents/funnyCode/PythonRepo/pyuml/core/parser.py", line 93, in visit_ClassDef
    if child.name.startswith('__'):
  File "_pydevd_bundle/pydevd_cython_darwin_37_64.pyx", line 1060, in _pydevd_bundle.pydevd_cython_darwin_37_64.SafeCallWrapper.__call__
  File "_pydevd_bundle/pydevd_cython_darwin_37_64.pyx", line 566, in _pydevd_bundle.pydevd_cython_darwin_37_64.PyDBFrame.trace_dispatch
  File "_pydevd_bundle/pydevd_cython_darwin_37_64.pyx", line 855, in _pydevd_bundle.pydevd_cython_darwin_37_64.PyDBFrame.trace_dispatch
  File "_pydevd_bundle/pydevd_cython_darwin_37_64.pyx", line 846, in _pydevd_bundle.pydevd_cython_darwin_37_64.PyDBFrame.trace_dispatch
  File "_pydevd_bundle/pydevd_cython_darwin_37_64.pyx", line 288, in _pydevd_bundle.pydevd_cython_darwin_37_64.PyDBFrame.do_wait_suspend
  File "/Applications/PyCharm CE.app/Contents/plugins/python-ce/helpers/pydev/pydevd.py", line 1099, in do_wait_suspend
    self._do_wait_suspend(thread, frame, event, arg, suspend_type, from_this_thread)
  File "/Applications/PyCharm CE.app/Contents/plugins/python-ce/helpers/pydev/pydevd.py", line 1114, in _do_wait_suspend
    time.sleep(0.01)
KeyboardInterrupt
2020-03-29 13:45:23,184 ERROR utilities.logger 2uml
Traceback (most recent call last):
  File "/Users/chenjiadong/Documents/funnyCode/PythonRepo/pyuml/main.py", line 88, in do_2uml
    dot_string = self._parse_to_dot(code_string)
  File "/Users/chenjiadong/Documents/funnyCode/PythonRepo/pyuml/main.py", line 118, in _parse_to_dot
    class_parser = self._parse_to_class_recoard(code_string)
  File "/Users/chenjiadong/Documents/funnyCode/PythonRepo/pyuml/main.py", line 132, in _parse_to_class_recoard
    class_parser.visit(tree)
  File "/Users/chenjiadong/Documents/funnyCode/PythonRepo/pyuml/venv/lib/python3.7/site-packages/typed_ast/ast3.py", line 279, in visit
    return visitor(node)
  File "/Users/chenjiadong/Documents/funnyCode/PythonRepo/pyuml/core/parser.py", line 69, in visit_Module
    self.visit(n)
  File "/Users/chenjiadong/Documents/funnyCode/PythonRepo/pyuml/venv/lib/python3.7/site-packages/typed_ast/ast3.py", line 279, in visit
    return visitor(node)
  File "/Users/chenjiadong/Documents/funnyCode/PythonRepo/pyuml/core/parser.py", line 106, in visit_ClassDef
    for target in code.targets:
  File "/Users/chenjiadong/Documents/funnyCode/PythonRepo/pyuml/core/parser.py", line 106, in visit_ClassDef
    for target in code.targets:
  File "_pydevd_bundle/pydevd_cython_darwin_37_64.pyx", line 1060, in _pydevd_bundle.pydevd_cython_darwin_37_64.SafeCallWrapper.__call__
  File "_pydevd_bundle/pydevd_cython_darwin_37_64.pyx", line 566, in _pydevd_bundle.pydevd_cython_darwin_37_64.PyDBFrame.trace_dispatch
  File "_pydevd_bundle/pydevd_cython_darwin_37_64.pyx", line 855, in _pydevd_bundle.pydevd_cython_darwin_37_64.PyDBFrame.trace_dispatch
  File "_pydevd_bundle/pydevd_cython_darwin_37_64.pyx", line 846, in _pydevd_bundle.pydevd_cython_darwin_37_64.PyDBFrame.trace_dispatch
  File "_pydevd_bundle/pydevd_cython_darwin_37_64.pyx", line 288, in _pydevd_bundle.pydevd_cython_darwin_37_64.PyDBFrame.do_wait_suspend
  File "/Applications/PyCharm CE.app/Contents/plugins/python-ce/helpers/pydev/pydevd.py", line 1099, in do_wait_suspend
    self._do_wait_suspend(thread, frame, event, arg, suspend_type, from_this_thread)
  File "/Applications/PyCharm CE.app/Contents/plugins/python-ce/helpers/pydev/pydevd.py", line 1114, in _do_wait_suspend
    time.sleep(0.01)
KeyboardInterrupt
2020-03-29 13:56:07,248 DEBUG graphviz.files write 585 bytes to '/Users/chenjiadong/Documents/funnyCode/PythonRepo/uml0'
2020-03-29 13:56:07,250 DEBUG graphviz.backend run ['dot', '-Tpng', '-O', 'uml0']
2020-03-29 14:04:33,856 ERROR utilities.logger 2uml
Traceback (most recent call last):
  File "/Users/chenjiadong/Documents/funnyCode/PythonRepo/pyuml/main.py", line 88, in do_2uml
    dot_string = self._parse_to_dot(code_string)
  File "/Users/chenjiadong/Documents/funnyCode/PythonRepo/pyuml/main.py", line 118, in _parse_to_dot
    class_parser = self._parse_to_class_recoard(code_string)
  File "/Users/chenjiadong/Documents/funnyCode/PythonRepo/pyuml/main.py", line 132, in _parse_to_class_recoard
    class_parser.visit(tree)
  File "/Users/chenjiadong/Documents/funnyCode/PythonRepo/pyuml/venv/lib/python3.7/site-packages/typed_ast/ast3.py", line 279, in visit
    return visitor(node)
  File "/Users/chenjiadong/Documents/funnyCode/PythonRepo/pyuml/core/parser.py", line 69, in visit_Module
    self.visit(n)
  File "/Users/chenjiadong/Documents/funnyCode/PythonRepo/pyuml/venv/lib/python3.7/site-packages/typed_ast/ast3.py", line 279, in visit
    return visitor(node)
  File "/Users/chenjiadong/Documents/funnyCode/PythonRepo/pyuml/core/parser.py", line 104, in visit_ClassDef
    print()
  File "/Users/chenjiadong/Documents/funnyCode/PythonRepo/pyuml/core/parser.py", line 104, in visit_ClassDef
    print()
  File "_pydevd_bundle/pydevd_cython_darwin_37_64.pyx", line 1470, in _pydevd_bundle.pydevd_cython_darwin_37_64.ThreadTracer.__call__
  File "_pydevd_bundle/pydevd_cython_darwin_37_64.pyx", line 855, in _pydevd_bundle.pydevd_cython_darwin_37_64.PyDBFrame.trace_dispatch
  File "_pydevd_bundle/pydevd_cython_darwin_37_64.pyx", line 846, in _pydevd_bundle.pydevd_cython_darwin_37_64.PyDBFrame.trace_dispatch
  File "_pydevd_bundle/pydevd_cython_darwin_37_64.pyx", line 288, in _pydevd_bundle.pydevd_cython_darwin_37_64.PyDBFrame.do_wait_suspend
  File "/Applications/PyCharm CE.app/Contents/plugins/python-ce/helpers/pydev/pydevd.py", line 1099, in do_wait_suspend
    self._do_wait_suspend(thread, frame, event, arg, suspend_type, from_this_thread)
  File "/Applications/PyCharm CE.app/Contents/plugins/python-ce/helpers/pydev/pydevd.py", line 1114, in _do_wait_suspend
    time.sleep(0.01)
KeyboardInterrupt
2020-03-29 14:04:52,292 ERROR utilities.logger 2uml
Traceback (most recent call last):
  File "/Users/chenjiadong/Documents/funnyCode/PythonRepo/pyuml/main.py", line 88, in do_2uml
    dot_string = self._parse_to_dot(code_string)
  File "/Users/chenjiadong/Documents/funnyCode/PythonRepo/pyuml/main.py", line 118, in _parse_to_dot
    class_parser = self._parse_to_class_recoard(code_string)
  File "/Users/chenjiadong/Documents/funnyCode/PythonRepo/pyuml/main.py", line 132, in _parse_to_class_recoard
    class_parser.visit(tree)
  File "/Users/chenjiadong/Documents/funnyCode/PythonRepo/pyuml/venv/lib/python3.7/site-packages/typed_ast/ast3.py", line 279, in visit
    return visitor(node)
  File "/Users/chenjiadong/Documents/funnyCode/PythonRepo/pyuml/core/parser.py", line 69, in visit_Module
    self.visit(n)
  File "/Users/chenjiadong/Documents/funnyCode/PythonRepo/pyuml/venv/lib/python3.7/site-packages/typed_ast/ast3.py", line 279, in visit
    return visitor(node)
  File "/Users/chenjiadong/Documents/funnyCode/PythonRepo/pyuml/core/parser.py", line 104, in visit_ClassDef
    self._parse_type_annotations(code, class_recorder)
  File "/Users/chenjiadong/Documents/funnyCode/PythonRepo/pyuml/core/parser.py", line 136, in _parse_type_annotations
    for target in code.targets:
AttributeError: 'AnnAssign' object has no attribute 'targets'
2020-03-29 14:09:25,183 DEBUG graphviz.files write 669 bytes to '/Users/chenjiadong/Documents/funnyCode/PythonRepo/uml0'
2020-03-29 14:09:25,185 DEBUG graphviz.backend run ['dot', '-Tpng', '-O', 'uml0']
2020-03-29 14:11:13,035 DEBUG graphviz.files write 753 bytes to '/Users/chenjiadong/Documents/funnyCode/PythonRepo/uml0'
2020-03-29 14:11:13,035 DEBUG graphviz.backend run ['dot', '-Tpng', '-O', 'uml0']
2020-03-29 14:21:23,662 ERROR utilities.logger 2uml
Traceback (most recent call last):
  File "/Users/chenjiadong/Documents/funnyCode/PythonRepo/pyuml/main.py", line 88, in do_2uml
    dot_string = self._parse_to_dot(code_string)
  File "/Users/chenjiadong/Documents/funnyCode/PythonRepo/pyuml/main.py", line 118, in _parse_to_dot
    class_parser = self._parse_to_class_recoard(code_string)
  File "/Users/chenjiadong/Documents/funnyCode/PythonRepo/pyuml/main.py", line 132, in _parse_to_class_recoard
    class_parser.visit(tree)
  File "/Users/chenjiadong/Documents/funnyCode/PythonRepo/pyuml/venv/lib/python3.7/site-packages/typed_ast/ast3.py", line 279, in visit
    return visitor(node)
  File "/Users/chenjiadong/Documents/funnyCode/PythonRepo/pyuml/core/parser.py", line 69, in visit_Module
    self.visit(n)
  File "/Users/chenjiadong/Documents/funnyCode/PythonRepo/pyuml/venv/lib/python3.7/site-packages/typed_ast/ast3.py", line 279, in visit
    return visitor(node)
  File "/Users/chenjiadong/Documents/funnyCode/PythonRepo/pyuml/core/parser.py", line 104, in visit_ClassDef
    self._parse_type_annotations(code, class_recorder)
  File "/Users/chenjiadong/Documents/funnyCode/PythonRepo/pyuml/core/parser.py", line 136, in _parse_type_annotations
    for target in code.targets:
  File "/Users/chenjiadong/Documents/funnyCode/PythonRepo/pyuml/core/parser.py", line 136, in _parse_type_annotations
    for target in code.targets:
  File "_pydevd_bundle/pydevd_cython_darwin_37_64.pyx", line 1470, in _pydevd_bundle.pydevd_cython_darwin_37_64.ThreadTracer.__call__
  File "_pydevd_bundle/pydevd_cython_darwin_37_64.pyx", line 855, in _pydevd_bundle.pydevd_cython_darwin_37_64.PyDBFrame.trace_dispatch
  File "_pydevd_bundle/pydevd_cython_darwin_37_64.pyx", line 846, in _pydevd_bundle.pydevd_cython_darwin_37_64.PyDBFrame.trace_dispatch
  File "_pydevd_bundle/pydevd_cython_darwin_37_64.pyx", line 288, in _pydevd_bundle.pydevd_cython_darwin_37_64.PyDBFrame.do_wait_suspend
  File "/Applications/PyCharm CE.app/Contents/plugins/python-ce/helpers/pydev/pydevd.py", line 1099, in do_wait_suspend
    self._do_wait_suspend(thread, frame, event, arg, suspend_type, from_this_thread)
  File "/Applications/PyCharm CE.app/Contents/plugins/python-ce/helpers/pydev/pydevd.py", line 1114, in _do_wait_suspend
    time.sleep(0.01)
KeyboardInterrupt
2020-03-29 14:22:05,156 DEBUG graphviz.files write 727 bytes to '/Users/chenjiadong/Documents/funnyCode/PythonRepo/uml0'
2020-03-29 14:22:05,157 DEBUG graphviz.backend run ['dot', '-Tpng', '-O', 'uml0']
2020-03-29 14:23:51,224 DEBUG graphviz.files write 69 bytes to '/Users/chenjiadong/Documents/funnyCode/PythonRepo/pyuml/test/test_dot_code/uml0'
2020-03-29 14:23:51,228 DEBUG graphviz.backend run ['dot', '-Tpng', '-O', 'uml0']
2020-03-29 14:23:51,307 DEBUG graphviz.files write 753 bytes to '/Users/chenjiadong/Documents/funnyCode/PythonRepo/pyuml/test/test_dot_code/uml1'
2020-03-29 14:23:51,308 DEBUG graphviz.backend run ['dot', '-Tpng', '-O', 'uml1']
2020-03-29 14:23:51,343 DEBUG graphviz.files write 179 bytes to '/Users/chenjiadong/Documents/funnyCode/PythonRepo/pyuml/test/test_dot_code/uml2'
2020-03-29 14:23:51,344 DEBUG graphviz.backend run ['dot', '-Tpng', '-O', 'uml2']
2020-03-29 14:23:51,373 DEBUG graphviz.files write 81 bytes to '/Users/chenjiadong/Documents/funnyCode/PythonRepo/pyuml/test/test_dot_code/uml3'
2020-03-29 14:23:51,374 DEBUG graphviz.backend run ['dot', '-Tpng', '-O', 'uml3']
2020-03-29 14:23:51,418 DEBUG graphviz.files write 727 bytes to '/Users/chenjiadong/Documents/funnyCode/PythonRepo/pyuml/test/test_dot_code/uml4'
2020-03-29 14:23:51,419 DEBUG graphviz.backend run ['dot', '-Tpng', '-O', 'uml4']
2020-03-29 14:23:51,459 DEBUG graphviz.files write 450 bytes to '/Users/chenjiadong/Documents/funnyCode/PythonRepo/pyuml/test/test_dot_code/uml5'
2020-03-29 14:23:51,461 DEBUG graphviz.backend run ['dot', '-Tpng', '-O', 'uml5']
2020-03-29 14:23:51,491 ERROR utilities.logger 2uml
Traceback (most recent call last):
  File "/Users/chenjiadong/Documents/funnyCode/PythonRepo/pyuml/main.py", line 88, in do_2uml
    dot_string = self._parse_to_dot(code_string)
  File "/Users/chenjiadong/Documents/funnyCode/PythonRepo/pyuml/main.py", line 118, in _parse_to_dot
    class_parser = self._parse_to_class_recoard(code_string)
  File "/Users/chenjiadong/Documents/funnyCode/PythonRepo/pyuml/main.py", line 130, in _parse_to_class_recoard
    tree = ast3.parse(code_string)
  File "/Users/chenjiadong/Documents/funnyCode/PythonRepo/pyuml/venv/lib/python3.7/site-packages/typed_ast/ast3.py", line 62, in parse
    return _ast3._parse(source, filename, mode, feature_version)
  File "<unknown>", line 1
    class ErrorClass
                   ^
SyntaxError: invalid syntax
2020-03-29 14:27:36,552 DEBUG graphviz.files write 727 bytes to '/Users/chenjiadong/Documents/funnyCode/PythonRepo/uml0'
2020-03-29 14:27:36,555 DEBUG graphviz.backend run ['dot', '-Tpng', '-O', 'uml0']
2020-03-29 15:44:45,353 ERROR utilities.logger 2uml
Traceback (most recent call last):
  File "/Users/chenjiadong/Documents/funnyCode/PythonRepo/pyuml/main.py", line 88, in do_2uml
    dot_string = self._parse_to_dot(code_string)
  File "/Users/chenjiadong/Documents/funnyCode/PythonRepo/pyuml/main.py", line 118, in _parse_to_dot
    class_parser = self._parse_to_class_recoard(code_string)
  File "/Users/chenjiadong/Documents/funnyCode/PythonRepo/pyuml/main.py", line 132, in _parse_to_class_recoard
    class_parser.visit(tree)
  File "/Users/chenjiadong/Documents/funnyCode/PythonRepo/pyuml/venv/lib/python3.7/site-packages/typed_ast/ast3.py", line 279, in visit
    return visitor(node)
  File "/Users/chenjiadong/Documents/funnyCode/PythonRepo/pyuml/core/parser.py", line 69, in visit_Module
    self.visit(n)
  File "/Users/chenjiadong/Documents/funnyCode/PythonRepo/pyuml/venv/lib/python3.7/site-packages/typed_ast/ast3.py", line 279, in visit
    return visitor(node)
  File "/Users/chenjiadong/Documents/funnyCode/PythonRepo/pyuml/core/parser.py", line 91, in visit_ClassDef
    type_comment = " : " + child.type_comment
  File "/Users/chenjiadong/Documents/funnyCode/PythonRepo/pyuml/core/parser.py", line 91, in visit_ClassDef
    type_comment = " : " + child.type_comment
  File "_pydevd_bundle/pydevd_cython_darwin_37_64.pyx", line 1060, in _pydevd_bundle.pydevd_cython_darwin_37_64.SafeCallWrapper.__call__
  File "_pydevd_bundle/pydevd_cython_darwin_37_64.pyx", line 566, in _pydevd_bundle.pydevd_cython_darwin_37_64.PyDBFrame.trace_dispatch
  File "_pydevd_bundle/pydevd_cython_darwin_37_64.pyx", line 855, in _pydevd_bundle.pydevd_cython_darwin_37_64.PyDBFrame.trace_dispatch
  File "_pydevd_bundle/pydevd_cython_darwin_37_64.pyx", line 846, in _pydevd_bundle.pydevd_cython_darwin_37_64.PyDBFrame.trace_dispatch
  File "_pydevd_bundle/pydevd_cython_darwin_37_64.pyx", line 288, in _pydevd_bundle.pydevd_cython_darwin_37_64.PyDBFrame.do_wait_suspend
  File "/Applications/PyCharm CE.app/Contents/plugins/python-ce/helpers/pydev/pydevd.py", line 1099, in do_wait_suspend
    self._do_wait_suspend(thread, frame, event, arg, suspend_type, from_this_thread)
  File "/Applications/PyCharm CE.app/Contents/plugins/python-ce/helpers/pydev/pydevd.py", line 1114, in _do_wait_suspend
    time.sleep(0.01)
KeyboardInterrupt
2020-03-29 16:00:11,778 ERROR utilities.logger 2uml
Traceback (most recent call last):
  File "/Users/chenjiadong/Documents/funnyCode/PythonRepo/pyuml/main.py", line 88, in do_2uml
    dot_string = self._parse_to_dot(code_string)
  File "/Users/chenjiadong/Documents/funnyCode/PythonRepo/pyuml/main.py", line 118, in _parse_to_dot
    class_parser = self._parse_to_class_recoard(code_string)
  File "/Users/chenjiadong/Documents/funnyCode/PythonRepo/pyuml/main.py", line 132, in _parse_to_class_recoard
    class_parser.visit(tree)
  File "/Users/chenjiadong/Documents/funnyCode/PythonRepo/pyuml/venv/lib/python3.7/site-packages/typed_ast/ast3.py", line 279, in visit
    return visitor(node)
  File "/Users/chenjiadong/Documents/funnyCode/PythonRepo/pyuml/core/parser.py", line 69, in visit_Module
    self.visit(n)
  File "/Users/chenjiadong/Documents/funnyCode/PythonRepo/pyuml/venv/lib/python3.7/site-packages/typed_ast/ast3.py", line 279, in visit
    return visitor(node)
  File "/Users/chenjiadong/Documents/funnyCode/PythonRepo/pyuml/core/parser.py", line 111, in visit_ClassDef
  File "/Users/chenjiadong/Documents/funnyCode/PythonRepo/pyuml/core/parser.py", line 111, in visit_ClassDef
  File "_pydevd_bundle/pydevd_cython_darwin_37_64.pyx", line 1060, in _pydevd_bundle.pydevd_cython_darwin_37_64.SafeCallWrapper.__call__
  File "_pydevd_bundle/pydevd_cython_darwin_37_64.pyx", line 566, in _pydevd_bundle.pydevd_cython_darwin_37_64.PyDBFrame.trace_dispatch
  File "_pydevd_bundle/pydevd_cython_darwin_37_64.pyx", line 976, in _pydevd_bundle.pydevd_cython_darwin_37_64.PyDBFrame.trace_dispatch
  File "_pydevd_bundle/pydevd_cython_darwin_37_64.pyx", line 938, in _pydevd_bundle.pydevd_cython_darwin_37_64.PyDBFrame.trace_dispatch
  File "_pydevd_bundle/pydevd_cython_darwin_37_64.pyx", line 288, in _pydevd_bundle.pydevd_cython_darwin_37_64.PyDBFrame.do_wait_suspend
  File "/Applications/PyCharm CE.app/Contents/plugins/python-ce/helpers/pydev/pydevd.py", line 1099, in do_wait_suspend
    self._do_wait_suspend(thread, frame, event, arg, suspend_type, from_this_thread)
  File "/Applications/PyCharm CE.app/Contents/plugins/python-ce/helpers/pydev/pydevd.py", line 1114, in _do_wait_suspend
    time.sleep(0.01)
KeyboardInterrupt
2020-03-29 16:01:00,608 ERROR utilities.logger 2uml
Traceback (most recent call last):
  File "/Users/chenjiadong/Documents/funnyCode/PythonRepo/pyuml/main.py", line 88, in do_2uml
    dot_string = self._parse_to_dot(code_string)
  File "/Users/chenjiadong/Documents/funnyCode/PythonRepo/pyuml/main.py", line 118, in _parse_to_dot
    class_parser = self._parse_to_class_recoard(code_string)
  File "/Users/chenjiadong/Documents/funnyCode/PythonRepo/pyuml/main.py", line 132, in _parse_to_class_recoard
    class_parser.visit(tree)
  File "/Users/chenjiadong/Documents/funnyCode/PythonRepo/pyuml/venv/lib/python3.7/site-packages/typed_ast/ast3.py", line 279, in visit
    return visitor(node)
  File "/Users/chenjiadong/Documents/funnyCode/PythonRepo/pyuml/core/parser.py", line 69, in visit_Module
    self.visit(n)
  File "/Users/chenjiadong/Documents/funnyCode/PythonRepo/pyuml/venv/lib/python3.7/site-packages/typed_ast/ast3.py", line 279, in visit
    return visitor(node)
  File "/Users/chenjiadong/Documents/funnyCode/PythonRepo/pyuml/core/parser.py", line 107, in visit_ClassDef
    if child.name.startswith('__'):
  File "/Users/chenjiadong/Documents/funnyCode/PythonRepo/pyuml/core/parser.py", line 107, in visit_ClassDef
    if child.name.startswith('__'):
  File "_pydevd_bundle/pydevd_cython_darwin_37_64.pyx", line 1060, in _pydevd_bundle.pydevd_cython_darwin_37_64.SafeCallWrapper.__call__
  File "_pydevd_bundle/pydevd_cython_darwin_37_64.pyx", line 566, in _pydevd_bundle.pydevd_cython_darwin_37_64.PyDBFrame.trace_dispatch
  File "_pydevd_bundle/pydevd_cython_darwin_37_64.pyx", line 855, in _pydevd_bundle.pydevd_cython_darwin_37_64.PyDBFrame.trace_dispatch
  File "_pydevd_bundle/pydevd_cython_darwin_37_64.pyx", line 846, in _pydevd_bundle.pydevd_cython_darwin_37_64.PyDBFrame.trace_dispatch
  File "_pydevd_bundle/pydevd_cython_darwin_37_64.pyx", line 288, in _pydevd_bundle.pydevd_cython_darwin_37_64.PyDBFrame.do_wait_suspend
  File "/Applications/PyCharm CE.app/Contents/plugins/python-ce/helpers/pydev/pydevd.py", line 1099, in do_wait_suspend
    self._do_wait_suspend(thread, frame, event, arg, suspend_type, from_this_thread)
  File "/Applications/PyCharm CE.app/Contents/plugins/python-ce/helpers/pydev/pydevd.py", line 1114, in _do_wait_suspend
    time.sleep(0.01)
KeyboardInterrupt
2020-03-29 16:04:19,433 ERROR utilities.logger 2uml
Traceback (most recent call last):
  File "/Users/chenjiadong/Documents/funnyCode/PythonRepo/pyuml/main.py", line 88, in do_2uml
    dot_string = self._parse_to_dot(code_string)
  File "/Users/chenjiadong/Documents/funnyCode/PythonRepo/pyuml/main.py", line 118, in _parse_to_dot
    class_parser = self._parse_to_class_recoard(code_string)
  File "/Users/chenjiadong/Documents/funnyCode/PythonRepo/pyuml/main.py", line 132, in _parse_to_class_recoard
    class_parser.visit(tree)
  File "/Users/chenjiadong/Documents/funnyCode/PythonRepo/pyuml/venv/lib/python3.7/site-packages/typed_ast/ast3.py", line 279, in visit
    return visitor(node)
  File "/Users/chenjiadong/Documents/funnyCode/PythonRepo/pyuml/core/parser.py", line 69, in visit_Module
    self.visit(n)
  File "/Users/chenjiadong/Documents/funnyCode/PythonRepo/pyuml/venv/lib/python3.7/site-packages/typed_ast/ast3.py", line 279, in visit
    return visitor(node)
  File "/Users/chenjiadong/Documents/funnyCode/PythonRepo/pyuml/core/parser.py", line 107, in visit_ClassDef
    if child.name.startswith('__'):
  File "/Users/chenjiadong/Documents/funnyCode/PythonRepo/pyuml/core/parser.py", line 107, in visit_ClassDef
    if child.name.startswith('__'):
  File "_pydevd_bundle/pydevd_cython_darwin_37_64.pyx", line 1060, in _pydevd_bundle.pydevd_cython_darwin_37_64.SafeCallWrapper.__call__
  File "_pydevd_bundle/pydevd_cython_darwin_37_64.pyx", line 566, in _pydevd_bundle.pydevd_cython_darwin_37_64.PyDBFrame.trace_dispatch
  File "_pydevd_bundle/pydevd_cython_darwin_37_64.pyx", line 855, in _pydevd_bundle.pydevd_cython_darwin_37_64.PyDBFrame.trace_dispatch
  File "_pydevd_bundle/pydevd_cython_darwin_37_64.pyx", line 846, in _pydevd_bundle.pydevd_cython_darwin_37_64.PyDBFrame.trace_dispatch
  File "_pydevd_bundle/pydevd_cython_darwin_37_64.pyx", line 288, in _pydevd_bundle.pydevd_cython_darwin_37_64.PyDBFrame.do_wait_suspend
  File "/Applications/PyCharm CE.app/Contents/plugins/python-ce/helpers/pydev/pydevd.py", line 1099, in do_wait_suspend
    self._do_wait_suspend(thread, frame, event, arg, suspend_type, from_this_thread)
  File "/Applications/PyCharm CE.app/Contents/plugins/python-ce/helpers/pydev/pydevd.py", line 1114, in _do_wait_suspend
    time.sleep(0.01)
KeyboardInterrupt
2020-03-29 16:04:41,386 DEBUG graphviz.files write 727 bytes to '/Users/chenjiadong/Documents/funnyCode/PythonRepo/uml0'
2020-03-29 16:04:41,387 DEBUG graphviz.backend run ['dot', '-Tpng', '-O', 'uml0']
2020-03-29 16:06:31,385 DEBUG graphviz.files write 727 bytes to '/Users/chenjiadong/Documents/funnyCode/PythonRepo/uml0'
2020-03-29 16:06:31,385 DEBUG graphviz.backend run ['dot', '-Tpng', '-O', 'uml0']
2020-03-29 16:12:08,847 ERROR utilities.logger 2uml
Traceback (most recent call last):
  File "/Users/chenjiadong/Documents/funnyCode/PythonRepo/pyuml/main.py", line 88, in do_2uml
    dot_string = self._parse_to_dot(code_string)
  File "/Users/chenjiadong/Documents/funnyCode/PythonRepo/pyuml/main.py", line 118, in _parse_to_dot
    class_parser = self._parse_to_class_recoard(code_string)
  File "/Users/chenjiadong/Documents/funnyCode/PythonRepo/pyuml/main.py", line 132, in _parse_to_class_recoard
    class_parser.visit(tree)
  File "/Users/chenjiadong/Documents/funnyCode/PythonRepo/pyuml/venv/lib/python3.7/site-packages/typed_ast/ast3.py", line 279, in visit
    return visitor(node)
  File "/Users/chenjiadong/Documents/funnyCode/PythonRepo/pyuml/core/parser.py", line 70, in visit_Module
    self.visit(n)
  File "/Users/chenjiadong/Documents/funnyCode/PythonRepo/pyuml/venv/lib/python3.7/site-packages/typed_ast/ast3.py", line 279, in visit
    return visitor(node)
  File "/Users/chenjiadong/Documents/funnyCode/PythonRepo/pyuml/core/parser.py", line 98, in visit_ClassDef
    for arg in child.args.args:
  File "/Users/chenjiadong/Documents/funnyCode/PythonRepo/pyuml/core/parser.py", line 98, in visit_ClassDef
    for arg in child.args.args:
  File "_pydevd_bundle/pydevd_cython_darwin_37_64.pyx", line 1470, in _pydevd_bundle.pydevd_cython_darwin_37_64.ThreadTracer.__call__
  File "_pydevd_bundle/pydevd_cython_darwin_37_64.pyx", line 855, in _pydevd_bundle.pydevd_cython_darwin_37_64.PyDBFrame.trace_dispatch
  File "_pydevd_bundle/pydevd_cython_darwin_37_64.pyx", line 846, in _pydevd_bundle.pydevd_cython_darwin_37_64.PyDBFrame.trace_dispatch
  File "_pydevd_bundle/pydevd_cython_darwin_37_64.pyx", line 288, in _pydevd_bundle.pydevd_cython_darwin_37_64.PyDBFrame.do_wait_suspend
  File "/Applications/PyCharm CE.app/Contents/plugins/python-ce/helpers/pydev/pydevd.py", line 1099, in do_wait_suspend
    self._do_wait_suspend(thread, frame, event, arg, suspend_type, from_this_thread)
  File "/Applications/PyCharm CE.app/Contents/plugins/python-ce/helpers/pydev/pydevd.py", line 1114, in _do_wait_suspend
    time.sleep(0.01)
KeyboardInterrupt
2020-03-29 16:13:01,627 DEBUG graphviz.files write 735 bytes to '/Users/chenjiadong/Documents/funnyCode/PythonRepo/uml0'
2020-03-29 16:13:01,628 DEBUG graphviz.backend run ['dot', '-Tpng', '-O', 'uml0']
2020-03-29 16:13:53,132 DEBUG graphviz.files write 817 bytes to '/Users/chenjiadong/Documents/funnyCode/PythonRepo/uml0'
2020-03-29 16:13:53,132 DEBUG graphviz.backend run ['dot', '-Tpng', '-O', 'uml0']
2020-03-29 16:15:45,273 DEBUG graphviz.files write 825 bytes to '/Users/chenjiadong/Documents/funnyCode/PythonRepo/uml0'
2020-03-29 16:15:45,273 DEBUG graphviz.backend run ['dot', '-Tpng', '-O', 'uml0']
2020-03-29 16:16:21,318 DEBUG graphviz.files write 825 bytes to '/Users/chenjiadong/Documents/funnyCode/PythonRepo/uml0'
2020-03-29 16:16:21,318 DEBUG graphviz.backend run ['dot', '-Tpng', '-O', 'uml0']
2020-03-29 16:17:24,666 ERROR utilities.logger 2uml
Traceback (most recent call last):
  File "/Users/chenjiadong/Documents/funnyCode/PythonRepo/pyuml/main.py", line 88, in do_2uml
    dot_string = self._parse_to_dot(code_string)
  File "/Users/chenjiadong/Documents/funnyCode/PythonRepo/pyuml/main.py", line 118, in _parse_to_dot
    class_parser = self._parse_to_class_recoard(code_string)
  File "/Users/chenjiadong/Documents/funnyCode/PythonRepo/pyuml/main.py", line 132, in _parse_to_class_recoard
    class_parser.visit(tree)
  File "/Users/chenjiadong/Documents/funnyCode/PythonRepo/pyuml/venv/lib/python3.7/site-packages/typed_ast/ast3.py", line 279, in visit
    return visitor(node)
  File "/Users/chenjiadong/Documents/funnyCode/PythonRepo/pyuml/core/parser.py", line 70, in visit_Module
    self.visit(n)
  File "/Users/chenjiadong/Documents/funnyCode/PythonRepo/pyuml/venv/lib/python3.7/site-packages/typed_ast/ast3.py", line 279, in visit
    return visitor(node)
  File "/Users/chenjiadong/Documents/funnyCode/PythonRepo/pyuml/core/parser.py", line 123, in visit_ClassDef
    for code in child.body:
  File "/Users/chenjiadong/Documents/funnyCode/PythonRepo/pyuml/core/parser.py", line 123, in visit_ClassDef
    for code in child.body:
  File "_pydevd_bundle/pydevd_cython_darwin_37_64.pyx", line 1470, in _pydevd_bundle.pydevd_cython_darwin_37_64.ThreadTracer.__call__
  File "_pydevd_bundle/pydevd_cython_darwin_37_64.pyx", line 855, in _pydevd_bundle.pydevd_cython_darwin_37_64.PyDBFrame.trace_dispatch
  File "_pydevd_bundle/pydevd_cython_darwin_37_64.pyx", line 846, in _pydevd_bundle.pydevd_cython_darwin_37_64.PyDBFrame.trace_dispatch
  File "_pydevd_bundle/pydevd_cython_darwin_37_64.pyx", line 288, in _pydevd_bundle.pydevd_cython_darwin_37_64.PyDBFrame.do_wait_suspend
  File "/Applications/PyCharm CE.app/Contents/plugins/python-ce/helpers/pydev/pydevd.py", line 1099, in do_wait_suspend
    self._do_wait_suspend(thread, frame, event, arg, suspend_type, from_this_thread)
  File "/Applications/PyCharm CE.app/Contents/plugins/python-ce/helpers/pydev/pydevd.py", line 1114, in _do_wait_suspend
    time.sleep(0.01)
KeyboardInterrupt
2020-03-29 16:18:21,517 DEBUG graphviz.files write 855 bytes to '/Users/chenjiadong/Documents/funnyCode/PythonRepo/uml0'
2020-03-29 16:18:21,518 DEBUG graphviz.backend run ['dot', '-Tpng', '-O', 'uml0']
2020-03-29 16:38:27,306 ERROR utilities.logger 2uml
Traceback (most recent call last):
  File "/Users/chenjiadong/Documents/funnyCode/PythonRepo/pyuml/main.py", line 88, in do_2uml
    dot_string = self._parse_to_dot(code_string)
  File "/Users/chenjiadong/Documents/funnyCode/PythonRepo/pyuml/main.py", line 118, in _parse_to_dot
    class_parser = self._parse_to_class_recoard(code_string)
  File "/Users/chenjiadong/Documents/funnyCode/PythonRepo/pyuml/main.py", line 132, in _parse_to_class_recoard
    class_parser.visit(tree)
  File "/Users/chenjiadong/Documents/funnyCode/PythonRepo/pyuml/venv/lib/python3.7/site-packages/typed_ast/ast3.py", line 279, in visit
    return visitor(node)
  File "/Users/chenjiadong/Documents/funnyCode/PythonRepo/pyuml/core/parser.py", line 70, in visit_Module
    self.visit(n)
  File "/Users/chenjiadong/Documents/funnyCode/PythonRepo/pyuml/venv/lib/python3.7/site-packages/typed_ast/ast3.py", line 279, in visit
    return visitor(node)
  File "/Users/chenjiadong/Documents/funnyCode/PythonRepo/pyuml/core/parser.py", line 96, in visit_ClassDef
    if isinstance(child.args, ast3.arguments):
  File "/Users/chenjiadong/Documents/funnyCode/PythonRepo/pyuml/core/parser.py", line 96, in visit_ClassDef
    if isinstance(child.args, ast3.arguments):
  File "_pydevd_bundle/pydevd_cython_darwin_37_64.pyx", line 1470, in _pydevd_bundle.pydevd_cython_darwin_37_64.ThreadTracer.__call__
  File "_pydevd_bundle/pydevd_cython_darwin_37_64.pyx", line 855, in _pydevd_bundle.pydevd_cython_darwin_37_64.PyDBFrame.trace_dispatch
  File "_pydevd_bundle/pydevd_cython_darwin_37_64.pyx", line 846, in _pydevd_bundle.pydevd_cython_darwin_37_64.PyDBFrame.trace_dispatch
  File "_pydevd_bundle/pydevd_cython_darwin_37_64.pyx", line 288, in _pydevd_bundle.pydevd_cython_darwin_37_64.PyDBFrame.do_wait_suspend
  File "/Applications/PyCharm CE.app/Contents/plugins/python-ce/helpers/pydev/pydevd.py", line 1099, in do_wait_suspend
    self._do_wait_suspend(thread, frame, event, arg, suspend_type, from_this_thread)
  File "/Applications/PyCharm CE.app/Contents/plugins/python-ce/helpers/pydev/pydevd.py", line 1114, in _do_wait_suspend
    time.sleep(0.01)
KeyboardInterrupt
2020-03-29 16:42:23,517 ERROR utilities.logger 2uml
Traceback (most recent call last):
  File "/Users/chenjiadong/Documents/funnyCode/PythonRepo/pyuml/main.py", line 88, in do_2uml
    dot_string = self._parse_to_dot(code_string)
  File "/Users/chenjiadong/Documents/funnyCode/PythonRepo/pyuml/main.py", line 118, in _parse_to_dot
    class_parser = self._parse_to_class_recoard(code_string)
  File "/Users/chenjiadong/Documents/funnyCode/PythonRepo/pyuml/main.py", line 132, in _parse_to_class_recoard
    class_parser.visit(tree)
  File "/Users/chenjiadong/Documents/funnyCode/PythonRepo/pyuml/venv/lib/python3.7/site-packages/typed_ast/ast3.py", line 279, in visit
    return visitor(node)
  File "/Users/chenjiadong/Documents/funnyCode/PythonRepo/pyuml/core/parser.py", line 70, in visit_Module
    self.visit(n)
  File "/Users/chenjiadong/Documents/funnyCode/PythonRepo/pyuml/venv/lib/python3.7/site-packages/typed_ast/ast3.py", line 279, in visit
    return visitor(node)
  File "/Users/chenjiadong/Documents/funnyCode/PythonRepo/pyuml/core/parser.py", line 96, in visit_ClassDef
    if isinstance(child.args, ast3.arguments):
  File "/Users/chenjiadong/Documents/funnyCode/PythonRepo/pyuml/core/parser.py", line 96, in visit_ClassDef
    if isinstance(child.args, ast3.arguments):
  File "_pydevd_bundle/pydevd_cython_darwin_37_64.pyx", line 1470, in _pydevd_bundle.pydevd_cython_darwin_37_64.ThreadTracer.__call__
  File "_pydevd_bundle/pydevd_cython_darwin_37_64.pyx", line 855, in _pydevd_bundle.pydevd_cython_darwin_37_64.PyDBFrame.trace_dispatch
  File "_pydevd_bundle/pydevd_cython_darwin_37_64.pyx", line 846, in _pydevd_bundle.pydevd_cython_darwin_37_64.PyDBFrame.trace_dispatch
  File "_pydevd_bundle/pydevd_cython_darwin_37_64.pyx", line 288, in _pydevd_bundle.pydevd_cython_darwin_37_64.PyDBFrame.do_wait_suspend
  File "/Applications/PyCharm CE.app/Contents/plugins/python-ce/helpers/pydev/pydevd.py", line 1099, in do_wait_suspend
    self._do_wait_suspend(thread, frame, event, arg, suspend_type, from_this_thread)
  File "/Applications/PyCharm CE.app/Contents/plugins/python-ce/helpers/pydev/pydevd.py", line 1114, in _do_wait_suspend
    time.sleep(0.01)
KeyboardInterrupt
2020-03-29 16:45:22,966 ERROR utilities.logger 2uml
Traceback (most recent call last):
  File "/Users/chenjiadong/Documents/funnyCode/PythonRepo/pyuml/main.py", line 88, in do_2uml
    dot_string = self._parse_to_dot(code_string)
  File "/Users/chenjiadong/Documents/funnyCode/PythonRepo/pyuml/main.py", line 118, in _parse_to_dot
    class_parser = self._parse_to_class_recoard(code_string)
  File "/Users/chenjiadong/Documents/funnyCode/PythonRepo/pyuml/main.py", line 132, in _parse_to_class_recoard
    class_parser.visit(tree)
  File "/Users/chenjiadong/Documents/funnyCode/PythonRepo/pyuml/venv/lib/python3.7/site-packages/typed_ast/ast3.py", line 279, in visit
    return visitor(node)
  File "/Users/chenjiadong/Documents/funnyCode/PythonRepo/pyuml/core/parser.py", line 70, in visit_Module
    self.visit(n)
  File "/Users/chenjiadong/Documents/funnyCode/PythonRepo/pyuml/venv/lib/python3.7/site-packages/typed_ast/ast3.py", line 279, in visit
    return visitor(node)
  File "/Users/chenjiadong/Documents/funnyCode/PythonRepo/pyuml/core/parser.py", line 96, in visit_ClassDef
    if isinstance(child.args, ast3.arguments):
  File "/Users/chenjiadong/Documents/funnyCode/PythonRepo/pyuml/core/parser.py", line 96, in visit_ClassDef
    if isinstance(child.args, ast3.arguments):
  File "_pydevd_bundle/pydevd_cython_darwin_37_64.pyx", line 1470, in _pydevd_bundle.pydevd_cython_darwin_37_64.ThreadTracer.__call__
  File "_pydevd_bundle/pydevd_cython_darwin_37_64.pyx", line 855, in _pydevd_bundle.pydevd_cython_darwin_37_64.PyDBFrame.trace_dispatch
  File "_pydevd_bundle/pydevd_cython_darwin_37_64.pyx", line 846, in _pydevd_bundle.pydevd_cython_darwin_37_64.PyDBFrame.trace_dispatch
  File "_pydevd_bundle/pydevd_cython_darwin_37_64.pyx", line 288, in _pydevd_bundle.pydevd_cython_darwin_37_64.PyDBFrame.do_wait_suspend
  File "/Applications/PyCharm CE.app/Contents/plugins/python-ce/helpers/pydev/pydevd.py", line 1099, in do_wait_suspend
    self._do_wait_suspend(thread, frame, event, arg, suspend_type, from_this_thread)
  File "/Applications/PyCharm CE.app/Contents/plugins/python-ce/helpers/pydev/pydevd.py", line 1114, in _do_wait_suspend
    time.sleep(0.01)
KeyboardInterrupt
2020-03-29 16:46:28,719 ERROR utilities.logger 2uml
Traceback (most recent call last):
  File "/Users/chenjiadong/Documents/funnyCode/PythonRepo/pyuml/main.py", line 88, in do_2uml
    dot_string = self._parse_to_dot(code_string)
  File "/Users/chenjiadong/Documents/funnyCode/PythonRepo/pyuml/main.py", line 118, in _parse_to_dot
    class_parser = self._parse_to_class_recoard(code_string)
  File "/Users/chenjiadong/Documents/funnyCode/PythonRepo/pyuml/main.py", line 132, in _parse_to_class_recoard
    class_parser.visit(tree)
  File "/Users/chenjiadong/Documents/funnyCode/PythonRepo/pyuml/venv/lib/python3.7/site-packages/typed_ast/ast3.py", line 279, in visit
    return visitor(node)
  File "/Users/chenjiadong/Documents/funnyCode/PythonRepo/pyuml/core/parser.py", line 70, in visit_Module
    self.visit(n)
  File "/Users/chenjiadong/Documents/funnyCode/PythonRepo/pyuml/venv/lib/python3.7/site-packages/typed_ast/ast3.py", line 279, in visit
    return visitor(node)
  File "/Users/chenjiadong/Documents/funnyCode/PythonRepo/pyuml/core/parser.py", line 96, in visit_ClassDef
    if isinstance(child.args, ast3.arguments):
  File "/Users/chenjiadong/Documents/funnyCode/PythonRepo/pyuml/core/parser.py", line 96, in visit_ClassDef
    if isinstance(child.args, ast3.arguments):
  File "_pydevd_bundle/pydevd_cython_darwin_37_64.pyx", line 1470, in _pydevd_bundle.pydevd_cython_darwin_37_64.ThreadTracer.__call__
  File "_pydevd_bundle/pydevd_cython_darwin_37_64.pyx", line 855, in _pydevd_bundle.pydevd_cython_darwin_37_64.PyDBFrame.trace_dispatch
  File "_pydevd_bundle/pydevd_cython_darwin_37_64.pyx", line 846, in _pydevd_bundle.pydevd_cython_darwin_37_64.PyDBFrame.trace_dispatch
  File "_pydevd_bundle/pydevd_cython_darwin_37_64.pyx", line 288, in _pydevd_bundle.pydevd_cython_darwin_37_64.PyDBFrame.do_wait_suspend
  File "/Applications/PyCharm CE.app/Contents/plugins/python-ce/helpers/pydev/pydevd.py", line 1099, in do_wait_suspend
    self._do_wait_suspend(thread, frame, event, arg, suspend_type, from_this_thread)
  File "/Applications/PyCharm CE.app/Contents/plugins/python-ce/helpers/pydev/pydevd.py", line 1114, in _do_wait_suspend
    time.sleep(0.01)
KeyboardInterrupt
2020-03-29 16:56:23,424 DEBUG graphviz.files write 832 bytes to '/Users/chenjiadong/Documents/funnyCode/PythonRepo/uml0'
2020-03-29 16:56:23,426 DEBUG graphviz.backend run ['dot', '-Tpng', '-O', 'uml0']
2020-03-29 16:58:09,613 ERROR utilities.logger 2uml
Traceback (most recent call last):
  File "/Users/chenjiadong/Documents/funnyCode/PythonRepo/pyuml/main.py", line 88, in do_2uml
    dot_string = self._parse_to_dot(code_string)
  File "/Users/chenjiadong/Documents/funnyCode/PythonRepo/pyuml/main.py", line 118, in _parse_to_dot
    class_parser = self._parse_to_class_recoard(code_string)
  File "/Users/chenjiadong/Documents/funnyCode/PythonRepo/pyuml/main.py", line 132, in _parse_to_class_recoard
    class_parser.visit(tree)
  File "/Users/chenjiadong/Documents/funnyCode/PythonRepo/pyuml/venv/lib/python3.7/site-packages/typed_ast/ast3.py", line 279, in visit
    return visitor(node)
  File "/Users/chenjiadong/Documents/funnyCode/PythonRepo/pyuml/core/parser.py", line 70, in visit_Module
    self.visit(n)
  File "/Users/chenjiadong/Documents/funnyCode/PythonRepo/pyuml/venv/lib/python3.7/site-packages/typed_ast/ast3.py", line 279, in visit
    return visitor(node)
  File "/Users/chenjiadong/Documents/funnyCode/PythonRepo/pyuml/core/parser.py", line 102, in visit_ClassDef
    argument_info += ': ' + arg.type_comment
  File "/Users/chenjiadong/Documents/funnyCode/PythonRepo/pyuml/core/parser.py", line 102, in visit_ClassDef
    argument_info += ': ' + arg.type_comment
  File "_pydevd_bundle/pydevd_cython_darwin_37_64.pyx", line 1470, in _pydevd_bundle.pydevd_cython_darwin_37_64.ThreadTracer.__call__
  File "_pydevd_bundle/pydevd_cython_darwin_37_64.pyx", line 855, in _pydevd_bundle.pydevd_cython_darwin_37_64.PyDBFrame.trace_dispatch
  File "_pydevd_bundle/pydevd_cython_darwin_37_64.pyx", line 846, in _pydevd_bundle.pydevd_cython_darwin_37_64.PyDBFrame.trace_dispatch
  File "_pydevd_bundle/pydevd_cython_darwin_37_64.pyx", line 288, in _pydevd_bundle.pydevd_cython_darwin_37_64.PyDBFrame.do_wait_suspend
  File "/Applications/PyCharm CE.app/Contents/plugins/python-ce/helpers/pydev/pydevd.py", line 1099, in do_wait_suspend
    self._do_wait_suspend(thread, frame, event, arg, suspend_type, from_this_thread)
  File "/Applications/PyCharm CE.app/Contents/plugins/python-ce/helpers/pydev/pydevd.py", line 1114, in _do_wait_suspend
    time.sleep(0.01)
KeyboardInterrupt
2020-03-29 16:58:15,262 DEBUG graphviz.files write 832 bytes to '/Users/chenjiadong/Documents/funnyCode/PythonRepo/uml0'
2020-03-29 16:58:15,262 DEBUG graphviz.backend run ['dot', '-Tpng', '-O', 'uml0']
2020-03-29 16:59:10,019 DEBUG graphviz.files write 832 bytes to '/Users/chenjiadong/Documents/funnyCode/PythonRepo/uml0'
2020-03-29 16:59:10,020 DEBUG graphviz.backend run ['dot', '-Tpng', '-O', 'uml0']
2020-03-29 17:01:37,829 DEBUG graphviz.files write 69 bytes to '/Users/chenjiadong/Documents/funnyCode/PythonRepo/pyuml/test/test_dot_code/uml0'
2020-03-29 17:01:37,831 DEBUG graphviz.backend run ['dot', '-Tpng', '-O', 'uml0']
2020-03-29 17:01:37,886 DEBUG graphviz.files write 827 bytes to '/Users/chenjiadong/Documents/funnyCode/PythonRepo/pyuml/test/test_dot_code/uml1'
2020-03-29 17:01:37,886 DEBUG graphviz.backend run ['dot', '-Tpng', '-O', 'uml1']
2020-03-29 17:01:37,922 DEBUG graphviz.files write 185 bytes to '/Users/chenjiadong/Documents/funnyCode/PythonRepo/pyuml/test/test_dot_code/uml2'
2020-03-29 17:01:37,922 DEBUG graphviz.backend run ['dot', '-Tpng', '-O', 'uml2']
2020-03-29 17:01:37,951 DEBUG graphviz.files write 83 bytes to '/Users/chenjiadong/Documents/funnyCode/PythonRepo/pyuml/test/test_dot_code/uml3'
2020-03-29 17:01:37,952 DEBUG graphviz.backend run ['dot', '-Tpng', '-O', 'uml3']
2020-03-29 17:01:37,983 DEBUG graphviz.files write 827 bytes to '/Users/chenjiadong/Documents/funnyCode/PythonRepo/pyuml/test/test_dot_code/uml4'
2020-03-29 17:01:37,983 DEBUG graphviz.backend run ['dot', '-Tpng', '-O', 'uml4']
2020-03-29 17:01:38,019 DEBUG graphviz.files write 458 bytes to '/Users/chenjiadong/Documents/funnyCode/PythonRepo/pyuml/test/test_dot_code/uml5'
2020-03-29 17:01:38,019 DEBUG graphviz.backend run ['dot', '-Tpng', '-O', 'uml5']
2020-03-29 17:01:38,054 ERROR utilities.logger 2uml
Traceback (most recent call last):
  File "/Users/chenjiadong/Documents/funnyCode/PythonRepo/pyuml/main.py", line 88, in do_2uml
    dot_string = self._parse_to_dot(code_string)
  File "/Users/chenjiadong/Documents/funnyCode/PythonRepo/pyuml/main.py", line 118, in _parse_to_dot
    class_parser = self._parse_to_class_recoard(code_string)
  File "/Users/chenjiadong/Documents/funnyCode/PythonRepo/pyuml/main.py", line 130, in _parse_to_class_recoard
    tree = ast3.parse(code_string)
  File "/Users/chenjiadong/Documents/funnyCode/PythonRepo/pyuml/venv/lib/python3.7/site-packages/typed_ast/ast3.py", line 62, in parse
    return _ast3._parse(source, filename, mode, feature_version)
  File "<unknown>", line 1
    class ErrorClass
                   ^
SyntaxError: invalid syntax
2020-03-29 17:08:53,172 DEBUG graphviz.files write 69 bytes to '/Users/chenjiadong/Documents/funnyCode/PythonRepo/pyuml/test/test_dot_code/uml0'
2020-03-29 17:08:53,174 DEBUG graphviz.backend run ['dot', '-Tpng', '-O', 'uml0']
2020-03-29 17:08:53,266 DEBUG graphviz.files write 827 bytes to '/Users/chenjiadong/Documents/funnyCode/PythonRepo/pyuml/test/test_dot_code/uml1'
2020-03-29 17:08:53,266 DEBUG graphviz.backend run ['dot', '-Tpng', '-O', 'uml1']
2020-03-29 17:08:53,302 DEBUG graphviz.files write 185 bytes to '/Users/chenjiadong/Documents/funnyCode/PythonRepo/pyuml/test/test_dot_code/uml2'
2020-03-29 17:08:53,303 DEBUG graphviz.backend run ['dot', '-Tpng', '-O', 'uml2']
2020-03-29 17:08:53,333 DEBUG graphviz.files write 83 bytes to '/Users/chenjiadong/Documents/funnyCode/PythonRepo/pyuml/test/test_dot_code/uml3'
2020-03-29 17:08:53,334 DEBUG graphviz.backend run ['dot', '-Tpng', '-O', 'uml3']
2020-03-29 17:08:53,377 DEBUG graphviz.files write 827 bytes to '/Users/chenjiadong/Documents/funnyCode/PythonRepo/pyuml/test/test_dot_code/uml4'
2020-03-29 17:08:53,378 DEBUG graphviz.backend run ['dot', '-Tpng', '-O', 'uml4']
2020-03-29 17:08:53,416 DEBUG graphviz.files write 458 bytes to '/Users/chenjiadong/Documents/funnyCode/PythonRepo/pyuml/test/test_dot_code/uml5'
2020-03-29 17:08:53,416 DEBUG graphviz.backend run ['dot', '-Tpng', '-O', 'uml5']
2020-03-29 17:08:53,445 DEBUG graphviz.files write 19 bytes to '/Users/chenjiadong/Documents/funnyCode/PythonRepo/pyuml/test/test_dot_code/uml6'
2020-03-29 17:08:53,448 DEBUG graphviz.backend run ['dot', '-Tpng', '-O', 'uml6']
2020-03-29 17:08:53,470 DEBUG graphviz.files write 169 bytes to '/Users/chenjiadong/Documents/funnyCode/PythonRepo/pyuml/test/test_dot_code/uml7'
2020-03-29 17:08:53,471 DEBUG graphviz.backend run ['dot', '-Tpng', '-O', 'uml7']
2020-03-29 17:08:53,499 DEBUG graphviz.files write 69 bytes to '/Users/chenjiadong/Documents/funnyCode/PythonRepo/pyuml/test/test_dot_code/uml8'
2020-03-29 17:08:53,499 DEBUG graphviz.backend run ['dot', '-Tpng', '-O', 'uml8']
2020-03-29 17:13:06,905 DEBUG graphviz.files write 827 bytes to '/Users/chenjiadong/Documents/funnyCode/PythonRepo/pyuml/result/uml0'
2020-03-29 17:13:06,909 DEBUG graphviz.backend run ['dot', '-Tpng', '-O', 'uml0']
2020-03-31 22:11:47,367 ERROR utilities.logger 2uml
Traceback (most recent call last):
  File "/Users/chenjiadong/Documents/funnyCode/PythonRep_git_test/pyuml/main.py", line 80, in do_2uml
    splitargs = parser.parse_args(shlex.split(args))
  File "/usr/local/Cellar/python/3.7.7/Frameworks/Python.framework/Versions/3.7/lib/python3.7/argparse.py", line 1755, in parse_args
    args, argv = self.parse_known_args(args, namespace)
  File "/usr/local/Cellar/python/3.7.7/Frameworks/Python.framework/Versions/3.7/lib/python3.7/argparse.py", line 1787, in parse_known_args
    namespace, args = self._parse_known_args(args, namespace)
  File "/usr/local/Cellar/python/3.7.7/Frameworks/Python.framework/Versions/3.7/lib/python3.7/argparse.py", line 2022, in _parse_known_args
    ', '.join(required_actions))
  File "/usr/local/Cellar/python/3.7.7/Frameworks/Python.framework/Versions/3.7/lib/python3.7/argparse.py", line 2508, in error
    self.exit(2, _('%(prog)s: error: %(message)s\n') % args)
  File "/usr/local/Cellar/python/3.7.7/Frameworks/Python.framework/Versions/3.7/lib/python3.7/argparse.py", line 2495, in exit
    _sys.exit(status)
SystemExit: 2
2020-03-31 22:12:13,266 ERROR utilities.logger 2uml
Traceback (most recent call last):
  File "/Users/chenjiadong/Documents/funnyCode/PythonRep_git_test/pyuml/main.py", line 88, in do_2uml
    dot_string = self._parse_to_dot(code_string)
  File "/Users/chenjiadong/Documents/funnyCode/PythonRep_git_test/pyuml/main.py", line 119, in _parse_to_dot
    self._persistent_to_file(class_parser.classes_list)
  File "/Users/chenjiadong/Documents/funnyCode/PythonRep_git_test/pyuml/main.py", line 125, in _persistent_to_file
    serializer = Serializer('ast.db')
TypeError: __init__() missing 1 required positional argument: 'file_name'
2020-03-31 22:12:57,237 DEBUG graphviz.files write 69 bytes to '/Users/chenjiadong/Documents/funnyCode/PythonRep_git/uml0'
2020-03-31 22:12:57,238 DEBUG graphviz.backend run ['dot', '-Tpng', '-O', 'uml0']
2020-03-31 22:12:57,318 DEBUG graphviz.files write 827 bytes to '/Users/chenjiadong/Documents/funnyCode/PythonRep_git/uml1'
2020-03-31 22:12:57,318 DEBUG graphviz.backend run ['dot', '-Tpng', '-O', 'uml1']
2020-03-31 22:12:57,355 DEBUG graphviz.files write 185 bytes to '/Users/chenjiadong/Documents/funnyCode/PythonRep_git/uml2'
2020-03-31 22:12:57,355 DEBUG graphviz.backend run ['dot', '-Tpng', '-O', 'uml2']
2020-03-31 22:12:57,386 DEBUG graphviz.files write 83 bytes to '/Users/chenjiadong/Documents/funnyCode/PythonRep_git/uml3'
2020-03-31 22:12:57,387 DEBUG graphviz.backend run ['dot', '-Tpng', '-O', 'uml3']
2020-03-31 22:12:57,419 DEBUG graphviz.files write 827 bytes to '/Users/chenjiadong/Documents/funnyCode/PythonRep_git/uml4'
2020-03-31 22:12:57,420 DEBUG graphviz.backend run ['dot', '-Tpng', '-O', 'uml4']
2020-03-31 22:12:57,463 DEBUG graphviz.files write 458 bytes to '/Users/chenjiadong/Documents/funnyCode/PythonRep_git/uml5'
2020-03-31 22:12:57,463 DEBUG graphviz.backend run ['dot', '-Tpng', '-O', 'uml5']
2020-03-31 22:12:57,492 ERROR utilities.logger 2uml
Traceback (most recent call last):
  File "/Users/chenjiadong/Documents/funnyCode/PythonRep_git_test/pyuml/main.py", line 88, in do_2uml
    dot_string = self._parse_to_dot(code_string)
  File "/Users/chenjiadong/Documents/funnyCode/PythonRep_git_test/pyuml/main.py", line 118, in _parse_to_dot
    class_parser = self._parse_to_class_recoard(code_string)
  File "/Users/chenjiadong/Documents/funnyCode/PythonRep_git_test/pyuml/main.py", line 130, in _parse_to_class_recoard
    tree = ast3.parse(code_string)
  File "/Users/chenjiadong/Documents/funnyCode/PythonRepo/pyuml/venv/lib/python3.7/site-packages/typed_ast/ast3.py", line 62, in parse
    return _ast3._parse(source, filename, mode, feature_version)
  File "<unknown>", line 1
    class ErrorClass
                   ^
SyntaxError: invalid syntax
2020-03-31 22:29:35,279 ERROR utilities.logger 2uml
Traceback (most recent call last):
  File "/Users/chenjiadong/Documents/funnyCode/PythonRep_git_test/pyuml/main.py", line 80, in do_2uml
    splitargs = parser.parse_args(shlex.split(args))
  File "/usr/local/Cellar/python/3.7.7/Frameworks/Python.framework/Versions/3.7/lib/python3.7/argparse.py", line 1755, in parse_args
    args, argv = self.parse_known_args(args, namespace)
  File "/usr/local/Cellar/python/3.7.7/Frameworks/Python.framework/Versions/3.7/lib/python3.7/argparse.py", line 1787, in parse_known_args
    namespace, args = self._parse_known_args(args, namespace)
  File "/usr/local/Cellar/python/3.7.7/Frameworks/Python.framework/Versions/3.7/lib/python3.7/argparse.py", line 2022, in _parse_known_args
    ', '.join(required_actions))
  File "/usr/local/Cellar/python/3.7.7/Frameworks/Python.framework/Versions/3.7/lib/python3.7/argparse.py", line 2508, in error
    self.exit(2, _('%(prog)s: error: %(message)s\n') % args)
  File "/usr/local/Cellar/python/3.7.7/Frameworks/Python.framework/Versions/3.7/lib/python3.7/argparse.py", line 2495, in exit
    _sys.exit(status)
SystemExit: 2
2020-03-31 22:29:54,944 DEBUG graphviz.files write 827 bytes to '/Users/chenjiadong/Documents/funnyCode/PythonRep_git_test/uml0'
2020-03-31 22:29:54,945 DEBUG graphviz.backend run ['dot', '-Tpng', '-O', 'uml0']
2020-04-01 04:15:31,301 ERROR utilities.logger 2uml
Traceback (most recent call last):
  File "C:/Users/miaomi/Downloads/pyuml-0.0.1/main.py", line 80, in do_2uml
    splitargs = parser.parse_args(shlex.split(args))
  File "D:\Users\miaomi\anaconda3\envs\pyuml-0.0.1\lib\argparse.py", line 1755, in parse_args
    args, argv = self.parse_known_args(args, namespace)
  File "D:\Users\miaomi\anaconda3\envs\pyuml-0.0.1\lib\argparse.py", line 1787, in parse_known_args
    namespace, args = self._parse_known_args(args, namespace)
  File "D:\Users\miaomi\anaconda3\envs\pyuml-0.0.1\lib\argparse.py", line 2022, in _parse_known_args
    ', '.join(required_actions))
  File "C:\Users\miaomi\Downloads\pyuml-0.0.1\utilities\argument_parser.py", line 6, in error
    raise SystemExit
SystemExit
2020-04-01 04:16:59,280 ERROR utilities.logger 2uml
Traceback (most recent call last):
  File "C:/Users/miaomi/Downloads/pyuml-0.0.1/main.py", line 80, in do_2uml
    splitargs = parser.parse_args(shlex.split(args))
  File "D:\Users\miaomi\anaconda3\envs\pyuml-0.0.1\lib\argparse.py", line 1755, in parse_args
    args, argv = self.parse_known_args(args, namespace)
  File "D:\Users\miaomi\anaconda3\envs\pyuml-0.0.1\lib\argparse.py", line 1787, in parse_known_args
    namespace, args = self._parse_known_args(args, namespace)
  File "D:\Users\miaomi\anaconda3\envs\pyuml-0.0.1\lib\argparse.py", line 2022, in _parse_known_args
    ', '.join(required_actions))
  File "C:\Users\miaomi\Downloads\pyuml-0.0.1\utilities\argument_parser.py", line 8, in error
    raise SystemExit
SystemExit
2020-04-01 04:17:12,991 ERROR utilities.logger load
Traceback (most recent call last):
  File "C:/Users/miaomi/Downloads/pyuml-0.0.1/main.py", line 104, in do_load
    splitargs = parser.parse_args(shlex.split(args))
  File "D:\Users\miaomi\anaconda3\envs\pyuml-0.0.1\lib\argparse.py", line 1755, in parse_args
    args, argv = self.parse_known_args(args, namespace)
  File "D:\Users\miaomi\anaconda3\envs\pyuml-0.0.1\lib\argparse.py", line 1787, in parse_known_args
    namespace, args = self._parse_known_args(args, namespace)
  File "D:\Users\miaomi\anaconda3\envs\pyuml-0.0.1\lib\argparse.py", line 2022, in _parse_known_args
    ', '.join(required_actions))
  File "C:\Users\miaomi\Downloads\pyuml-0.0.1\utilities\argument_parser.py", line 8, in error
    raise SystemExit
SystemExit
2020-04-01 04:20:47,497 DEBUG graphviz.files write 458 bytes to 'C:\\Users\\miaomi\\Downloads\\pyuml-\\uml0'
2020-04-01 04:20:47,498 DEBUG graphviz.backend run ['dot', '-Tpng', '-O', 'uml0']
2020-04-01 04:23:31,271 DEBUG graphviz.files write 458 bytes to 'C:\\Users\\miaomi\\Downloads\\pyuml-\\uml0'
2020-04-01 04:23:31,272 DEBUG graphviz.backend run ['dot', '-Tpng', '-O', 'uml0']
2020-04-01 04:28:46,429 DEBUG graphviz.files write 458 bytes to 'C:\\Users\\miaomi\\Downloads\\pyuml-\\uml0'
2020-04-01 04:28:46,430 DEBUG graphviz.backend run ['dot', '-Tpng', '-O', 'uml0']
2020-04-01 04:31:01,503 DEBUG graphviz.files write 458 bytes to 'C:\\Users\\miaomi\\Downloads\\pyuml-\\uml0'
2020-04-01 04:31:01,504 DEBUG graphviz.backend run ['dot', '-Tpng', '-O', 'uml0']
2020-04-01 04:33:00,137 ERROR utilities.logger 2uml
Traceback (most recent call last):
  File "C:/Users/miaomi/Downloads/pyuml-0.0.1/main.py", line 85, in do_2uml
    code_string_list = loader.load_from_file_or_directory(input_path)
  File "C:\Users\miaomi\Downloads\pyuml-0.0.1\core\loader.py", line 17, in load_from_file_or_directory
    raise IOError
OSError
2020-04-01 04:33:11,894 DEBUG graphviz.files write 458 bytes to 'C:\\Users\\miaomi\\Downloads\\pyuml-\\uml0'
2020-04-01 04:33:11,894 DEBUG graphviz.backend run ['dot', '-Tpng', '-O', 'uml0']
2020-04-01 04:33:12,049 DEBUG graphviz.files write 83 bytes to 'C:\\Users\\miaomi\\Downloads\\pyuml-\\uml1'
2020-04-01 04:33:12,050 DEBUG graphviz.backend run ['dot', '-Tpng', '-O', 'uml1']
2020-04-01 04:33:12,096 DEBUG graphviz.files write 169 bytes to 'C:\\Users\\miaomi\\Downloads\\pyuml-\\uml2'
2020-04-01 04:33:12,097 DEBUG graphviz.backend run ['dot', '-Tpng', '-O', 'uml2']
2020-04-01 04:33:12,150 DEBUG graphviz.files write 185 bytes to 'C:\\Users\\miaomi\\Downloads\\pyuml-\\uml3'
2020-04-01 04:33:12,152 DEBUG graphviz.backend run ['dot', '-Tpng', '-O', 'uml3']
2020-04-01 04:33:12,194 ERROR utilities.logger 2uml
Traceback (most recent call last):
  File "C:/Users/miaomi/Downloads/pyuml-0.0.1/main.py", line 88, in do_2uml
    dot_string = self._parse_to_dot(code_string)
  File "C:/Users/miaomi/Downloads/pyuml-0.0.1/main.py", line 118, in _parse_to_dot
    class_parser = self._parse_to_class_recoard(code_string)
  File "C:/Users/miaomi/Downloads/pyuml-0.0.1/main.py", line 130, in _parse_to_class_recoard
    tree = ast3.parse(code_string)
  File "D:\Users\miaomi\anaconda3\envs\pyuml-0.0.1\lib\site-packages\typed_ast\ast3.py", line 62, in parse
    return _ast3._parse(source, filename, mode, feature_version)
  File "<unknown>", line 1
    class ErrorClass
                   ^
SyntaxError: invalid syntax
2020-04-01 04:34:22,215 ERROR utilities.logger 2uml
Traceback (most recent call last):
  File "C:/Users/miaomi/Downloads/pyuml-0.0.1/main.py", line 80, in do_2uml
    splitargs = parser.parse_args(shlex.split(args))
  File "D:\Users\miaomi\anaconda3\envs\pyuml-0.0.1\lib\argparse.py", line 1758, in parse_args
    self.error(msg % ' '.join(argv))
  File "C:\Users\miaomi\Downloads\pyuml-0.0.1\utilities\argument_parser.py", line 8, in error
    raise SystemExit
SystemExit
2020-04-01 04:34:46,672 DEBUG graphviz.files write 827 bytes to 'C:\\Users\\miaomi\\Downloads\\pyuml-\\uml0'
2020-04-01 04:34:46,672 DEBUG graphviz.backend run ['dot', '-Tpng', '-O', 'uml0']
2020-04-01 04:53:51,569 ERROR utilities.logger 2uml
Traceback (most recent call last):
  File "C:/Users/miaomi/Downloads/pyuml/main.py", line 80, in do_2uml
    splitargs = parser.parse_args(shlex.split(args))
  File "D:\Users\miaomi\anaconda3\envs\pyuml-0.0.1\lib\argparse.py", line 1755, in parse_args
    args, argv = self.parse_known_args(args, namespace)
  File "D:\Users\miaomi\anaconda3\envs\pyuml-0.0.1\lib\argparse.py", line 1787, in parse_known_args
    namespace, args = self._parse_known_args(args, namespace)
  File "D:\Users\miaomi\anaconda3\envs\pyuml-0.0.1\lib\argparse.py", line 2022, in _parse_known_args
    ', '.join(required_actions))
  File "C:\Users\miaomi\Downloads\pyuml\utilities\argument_parser.py", line 8, in error
    raise SystemExit
SystemExit
2020-04-01 04:58:55,895 ERROR utilities.logger load
Traceback (most recent call last):
  File "D:\Users\miaomi\anaconda3\envs\pyuml-0.0.1\lib\shelve.py", line 111, in __getitem__
    value = self.cache[key]
KeyError: 'Car'

During handling of the above exception, another exception occurred:

Traceback (most recent call last):
  File "C:/Users/miaomi/Downloads/pyuml/main.py", line 106, in do_load
    result = serializer.deserilize(splitargs.input)
  File "C:\Users\miaomi\Downloads\pyuml\core\serializer.py", line 56, in deserilize
    data = db[name]
  File "D:\Users\miaomi\anaconda3\envs\pyuml-0.0.1\lib\shelve.py", line 113, in __getitem__
    f = BytesIO(self.dict[key.encode(self.keyencoding)])
  File "D:\Users\miaomi\anaconda3\envs\pyuml-0.0.1\lib\dbm\dumb.py", line 153, in __getitem__
    pos, siz = self._index[key]     # may raise KeyError
KeyError: b'Car'
2020-04-01 04:58:59,724 ERROR utilities.logger load
Traceback (most recent call last):
  File "C:/Users/miaomi/Downloads/pyuml/main.py", line 104, in do_load
    splitargs = parser.parse_args(shlex.split(args))
  File "D:\Users\miaomi\anaconda3\envs\pyuml-0.0.1\lib\argparse.py", line 1755, in parse_args
    args, argv = self.parse_known_args(args, namespace)
  File "D:\Users\miaomi\anaconda3\envs\pyuml-0.0.1\lib\argparse.py", line 1787, in parse_known_args
    namespace, args = self._parse_known_args(args, namespace)
  File "D:\Users\miaomi\anaconda3\envs\pyuml-0.0.1\lib\argparse.py", line 2022, in _parse_known_args
    ', '.join(required_actions))
  File "C:\Users\miaomi\Downloads\pyuml\utilities\argument_parser.py", line 8, in error
    raise SystemExit
SystemExit
