2020-03-22 15:04:01,758 ERROR __main__ 2uml
Traceback (most recent call last):
  File "/Users/chenjiadong/Documents/funnyCode/PythonRepo/pyuml/main.py", line 82, in do_2uml
    dot_string = self._parse_to_dot(splitargs.Input)
  File "/Users/chenjiadong/Documents/funnyCode/PythonRepo/pyuml/main.py", line 136, in _parse_to_dot
    tree = ast3.parse(code_string)
  File "/Users/chenjiadong/Documents/funnyCode/PythonRepo/pyuml/venv/lib/python3.7/site-packages/typed_ast/ast3.py", line 62, in parse
    return _ast3._parse(source, filename, mode, feature_version)
TypeError: parse() arg 1 must be a string or bytes object
2020-03-22 15:05:53,564 ERROR __main__ 2uml_from_binary
Traceback (most recent call last):
  File "/Users/chenjiadong/Documents/funnyCode/PythonRepo/pyuml/main.py", line 117, in do_2uml_from_binary
    splitargs = parser.parse_args(shlex.split(args))
  File "/usr/local/Cellar/python/3.7.7/Frameworks/Python.framework/Versions/3.7/lib/python3.7/argparse.py", line 1755, in parse_args
    args, argv = self.parse_known_args(args, namespace)
  File "/usr/local/Cellar/python/3.7.7/Frameworks/Python.framework/Versions/3.7/lib/python3.7/argparse.py", line 1787, in parse_known_args
    namespace, args = self._parse_known_args(args, namespace)
  File "/usr/local/Cellar/python/3.7.7/Frameworks/Python.framework/Versions/3.7/lib/python3.7/argparse.py", line 2022, in _parse_known_args
    ', '.join(required_actions))
  File "/usr/local/Cellar/python/3.7.7/Frameworks/Python.framework/Versions/3.7/lib/python3.7/argparse.py", line 2508, in error
    self.exit(2, _('%(prog)s: error: %(message)s\n') % args)
  File "/usr/local/Cellar/python/3.7.7/Frameworks/Python.framework/Versions/3.7/lib/python3.7/argparse.py", line 2495, in exit
    _sys.exit(status)
SystemExit: 2
2020-03-22 15:06:54,387 ERROR __main__ 2uml
Traceback (most recent call last):
  File "/Users/chenjiadong/Documents/funnyCode/PythonRepo/pyuml/main.py", line 82, in do_2uml
    dot_string = self._parse_to_dot(splitargs.Input)
  File "/Users/chenjiadong/Documents/funnyCode/PythonRepo/pyuml/main.py", line 137, in _parse_to_dot
    tree = ast3.parse(code_string)
  File "/Users/chenjiadong/Documents/funnyCode/PythonRepo/pyuml/venv/lib/python3.7/site-packages/typed_ast/ast3.py", line 62, in parse
    return _ast3._parse(source, filename, mode, feature_version)
TypeError: parse() arg 1 must be a string or bytes object
2020-03-22 15:07:21,820 ERROR __main__ 2uml
Traceback (most recent call last):
  File "/Users/chenjiadong/Documents/funnyCode/PythonRepo/pyuml/main.py", line 82, in do_2uml
    dot_string = self._parse_to_dot(splitargs.Input)
  File "/Users/chenjiadong/Documents/funnyCode/PythonRepo/pyuml/main.py", line 136, in _parse_to_dot
    tree = ast3.parse(code_string)
  File "/Users/chenjiadong/Documents/funnyCode/PythonRepo/pyuml/venv/lib/python3.7/site-packages/typed_ast/ast3.py", line 62, in parse
    return _ast3._parse(source, filename, mode, feature_version)
TypeError: parse() arg 1 must be a string or bytes object
2020-03-22 15:09:35,015 DEBUG graphviz.files write 243 bytes to 'result/uml'
2020-03-22 15:09:35,016 DEBUG graphviz.backend run ['dot', '-Tpng', '-O', 'uml']
2020-03-22 15:12:55,628 DEBUG graphviz.files write 493 bytes to 'result/uml'
2020-03-22 15:12:55,630 DEBUG graphviz.backend run ['dot', '-Tpng', '-O', 'uml']
2020-03-22 15:13:58,778 DEBUG graphviz.files write 493 bytes to 'result/uml'
2020-03-22 15:13:58,780 DEBUG graphviz.backend run ['dot', '-Tpng', '-O', 'uml']
2020-03-22 15:15:12,933 DEBUG graphviz.files write 493 bytes to 'result/uml'
2020-03-22 15:15:12,935 DEBUG graphviz.backend run ['dot', '-Tpng', '-O', 'uml']
2020-03-22 15:17:08,666 DEBUG graphviz.files write 677 bytes to 'result/uml'
2020-03-22 15:17:08,666 DEBUG graphviz.backend run ['dot', '-Tpng', '-O', 'uml']
2020-03-22 17:01:17,852 ERROR __main__ 2uml
Traceback (most recent call last):
  File "/Users/chenjiadong/Documents/funnyCode/PythonRepo/pyuml/main.py", line 82, in do_2uml
    dot_string = self._parse_to_dot(splitargs.Input)
  File "/Users/chenjiadong/Documents/funnyCode/PythonRepo/pyuml/main.py", line 135, in _parse_to_dot
    tree = ast3.parse(code_string)
  File "/Users/chenjiadong/Documents/funnyCode/PythonRepo/pyuml/venv/lib/python3.7/site-packages/typed_ast/ast3.py", line 62, in parse
    return _ast3._parse(source, filename, mode, feature_version)
TypeError: parse() arg 1 must be a string or bytes object
2020-03-22 18:48:12,516 ERROR __main__ 2uml
Traceback (most recent call last):
  File "/Users/chenjiadong/Documents/funnyCode/PythonRepo/pyuml/main.py", line 86, in do_2uml
    code_string_list = loader.load_from_file_or_directory(args)
  File "/Users/chenjiadong/Documents/funnyCode/PythonRepo/pyuml/core/loader.py", line 8, in load_from_file_or_directory
    raise IOError
OSError
2020-03-22 18:49:14,520 ERROR __main__ 2uml
Traceback (most recent call last):
  File "/Users/chenjiadong/Documents/funnyCode/PythonRepo/pyuml/main.py", line 82, in do_2uml
    splitargs = parser.parse_args(shlex.split(args))
  File "/usr/local/Cellar/python/3.7.7/Frameworks/Python.framework/Versions/3.7/lib/python3.7/argparse.py", line 1755, in parse_args
    args, argv = self.parse_known_args(args, namespace)
  File "/usr/local/Cellar/python/3.7.7/Frameworks/Python.framework/Versions/3.7/lib/python3.7/argparse.py", line 1787, in parse_known_args
    namespace, args = self._parse_known_args(args, namespace)
  File "/usr/local/Cellar/python/3.7.7/Frameworks/Python.framework/Versions/3.7/lib/python3.7/argparse.py", line 2022, in _parse_known_args
    ', '.join(required_actions))
  File "/usr/local/Cellar/python/3.7.7/Frameworks/Python.framework/Versions/3.7/lib/python3.7/argparse.py", line 2508, in error
    self.exit(2, _('%(prog)s: error: %(message)s\n') % args)
  File "/usr/local/Cellar/python/3.7.7/Frameworks/Python.framework/Versions/3.7/lib/python3.7/argparse.py", line 2495, in exit
    _sys.exit(status)
SystemExit: 2
2020-03-22 18:49:21,063 ERROR __main__ 2uml
Traceback (most recent call last):
  File "/Users/chenjiadong/Documents/funnyCode/PythonRepo/pyuml/main.py", line 86, in do_2uml
    code_string_list = loader.load_from_file_or_directory(args)
  File "/Users/chenjiadong/Documents/funnyCode/PythonRepo/pyuml/core/loader.py", line 9, in load_from_file_or_directory
    raise IOError
OSError
2020-03-22 18:50:00,185 ERROR __main__ 2uml
Traceback (most recent call last):
  File "/Users/chenjiadong/Documents/funnyCode/PythonRepo/pyuml/main.py", line 88, in do_2uml
    dot_string = self._parse_to_dot(code_string)
  File "/Users/chenjiadong/Documents/funnyCode/PythonRepo/pyuml/main.py", line 141, in _parse_to_dot
    tree = ast3.parse(code_string)
NameError: name 'code_string' is not defined
2020-03-22 18:50:40,157 ERROR __main__ 2uml
Traceback (most recent call last):
  File "/Users/chenjiadong/Documents/funnyCode/PythonRepo/pyuml/main.py", line 88, in do_2uml
    dot_string = self._parse_to_dot(code_string)
  File "/Users/chenjiadong/Documents/funnyCode/PythonRepo/pyuml/main.py", line 140, in _parse_to_dot
    tree = ast3.parse(code_string)
  File "/Users/chenjiadong/Documents/funnyCode/PythonRepo/pyuml/venv/lib/python3.7/site-packages/typed_ast/ast3.py", line 62, in parse
    return _ast3._parse(source, filename, mode, feature_version)
TypeError: parse() arg 1 must be a string or bytes object
2020-03-22 18:51:21,589 ERROR __main__ 2uml
Traceback (most recent call last):
  File "/Users/chenjiadong/Documents/funnyCode/PythonRepo/pyuml/main.py", line 82, in do_2uml
    splitargs = parser.parse_args(shlex.split(args))
  File "/usr/local/Cellar/python/3.7.7/Frameworks/Python.framework/Versions/3.7/lib/python3.7/argparse.py", line 1755, in parse_args
    args, argv = self.parse_known_args(args, namespace)
  File "/usr/local/Cellar/python/3.7.7/Frameworks/Python.framework/Versions/3.7/lib/python3.7/argparse.py", line 1787, in parse_known_args
    namespace, args = self._parse_known_args(args, namespace)
  File "/usr/local/Cellar/python/3.7.7/Frameworks/Python.framework/Versions/3.7/lib/python3.7/argparse.py", line 2022, in _parse_known_args
    ', '.join(required_actions))
  File "/usr/local/Cellar/python/3.7.7/Frameworks/Python.framework/Versions/3.7/lib/python3.7/argparse.py", line 2508, in error
    self.exit(2, _('%(prog)s: error: %(message)s\n') % args)
  File "/usr/local/Cellar/python/3.7.7/Frameworks/Python.framework/Versions/3.7/lib/python3.7/argparse.py", line 2495, in exit
    _sys.exit(status)
SystemExit: 2
2020-03-22 18:51:26,153 ERROR __main__ 2uml
Traceback (most recent call last):
  File "/Users/chenjiadong/Documents/funnyCode/PythonRepo/pyuml/main.py", line 88, in do_2uml
    dot_string = self._parse_to_dot(code_string)
  File "/Users/chenjiadong/Documents/funnyCode/PythonRepo/pyuml/main.py", line 141, in _parse_to_dot
    tree = ast3.parse(code_string)
  File "/Users/chenjiadong/Documents/funnyCode/PythonRepo/pyuml/venv/lib/python3.7/site-packages/typed_ast/ast3.py", line 62, in parse
    return _ast3._parse(source, filename, mode, feature_version)
TypeError: parse() arg 1 must be a string or bytes object
2020-03-22 18:54:40,677 DEBUG graphviz.files write 677 bytes to 'result/uml'
2020-03-22 18:54:40,678 DEBUG graphviz.backend run ['dot', '-Tpng', '-O', 'uml']
2020-03-22 18:54:40,819 DEBUG graphviz.files write 68 bytes to 'result/uml'
2020-03-22 18:54:40,819 DEBUG graphviz.backend run ['dot', '-Tpng', '-O', 'uml']
2020-03-22 18:54:40,831 ERROR __main__ 2uml
Traceback (most recent call last):
  File "/Users/chenjiadong/Documents/funnyCode/PythonRepo/pyuml/main.py", line 89, in do_2uml
    self._render_with_graphviz(dot_string)
  File "/Users/chenjiadong/Documents/funnyCode/PythonRepo/pyuml/main.py", line 151, in _render_with_graphviz
    src.render(format='png', filename="result/uml")
  File "/Users/chenjiadong/Documents/funnyCode/PythonRepo/pyuml/venv/lib/python3.7/site-packages/graphviz/files.py", line 209, in render
    quiet=quiet)
  File "/Users/chenjiadong/Documents/funnyCode/PythonRepo/pyuml/venv/lib/python3.7/site-packages/graphviz/backend.py", line 206, in render
    run(cmd, capture_output=True, cwd=cwd, check=True, quiet=quiet)
  File "/Users/chenjiadong/Documents/funnyCode/PythonRepo/pyuml/venv/lib/python3.7/site-packages/graphviz/backend.py", line 172, in run
    output=out, stderr=err)
graphviz.backend.CalledProcessError: Command '['dot', '-Tpng', '-O', 'uml']' returned non-zero exit status 1. [stderr: b'Error: uml: syntax error in line 2 scanning a quoted string (missing endquote? longer than 16384?)\nString starting:"];\n}\n\n']
2020-03-22 18:55:59,875 DEBUG graphviz.files write 68 bytes to 'result/uml'
2020-03-22 18:55:59,876 DEBUG graphviz.backend run ['dot', '-Tpng', '-O', 'uml']
2020-03-22 18:55:59,895 ERROR __main__ 2uml
Traceback (most recent call last):
  File "/Users/chenjiadong/Documents/funnyCode/PythonRepo/pyuml/main.py", line 89, in do_2uml
    self._render_with_graphviz(dot_string)
  File "/Users/chenjiadong/Documents/funnyCode/PythonRepo/pyuml/main.py", line 151, in _render_with_graphviz
    src.render(format='png', filename="result/uml")
  File "/Users/chenjiadong/Documents/funnyCode/PythonRepo/pyuml/venv/lib/python3.7/site-packages/graphviz/files.py", line 209, in render
    quiet=quiet)
  File "/Users/chenjiadong/Documents/funnyCode/PythonRepo/pyuml/venv/lib/python3.7/site-packages/graphviz/backend.py", line 206, in render
    run(cmd, capture_output=True, cwd=cwd, check=True, quiet=quiet)
  File "/Users/chenjiadong/Documents/funnyCode/PythonRepo/pyuml/venv/lib/python3.7/site-packages/graphviz/backend.py", line 172, in run
    output=out, stderr=err)
graphviz.backend.CalledProcessError: Command '['dot', '-Tpng', '-O', 'uml']' returned non-zero exit status 1. [stderr: b'Error: uml: syntax error in line 2 scanning a quoted string (missing endquote? longer than 16384?)\nString starting:"];\n}\n\n']
2020-03-22 19:07:36,204 DEBUG graphviz.files write 677 bytes to 'result/uml'
2020-03-22 19:07:36,206 DEBUG graphviz.backend run ['dot', '-Tpng', '-O', 'uml']
2020-03-22 19:07:36,308 DEBUG graphviz.files write 68 bytes to 'result/uml'
2020-03-22 19:07:36,308 DEBUG graphviz.backend run ['dot', '-Tpng', '-O', 'uml']
2020-03-22 19:07:36,321 ERROR __main__ 2uml
Traceback (most recent call last):
  File "/Users/chenjiadong/Documents/funnyCode/PythonRepo/pyuml/main.py", line 89, in do_2uml
    self._render_with_graphviz(dot_string)
  File "/Users/chenjiadong/Documents/funnyCode/PythonRepo/pyuml/main.py", line 151, in _render_with_graphviz
    src.render(format='png', filename="result/uml")
  File "/Users/chenjiadong/Documents/funnyCode/PythonRepo/pyuml/venv/lib/python3.7/site-packages/graphviz/files.py", line 209, in render
    quiet=quiet)
  File "/Users/chenjiadong/Documents/funnyCode/PythonRepo/pyuml/venv/lib/python3.7/site-packages/graphviz/backend.py", line 206, in render
    run(cmd, capture_output=True, cwd=cwd, check=True, quiet=quiet)
  File "/Users/chenjiadong/Documents/funnyCode/PythonRepo/pyuml/venv/lib/python3.7/site-packages/graphviz/backend.py", line 172, in run
    output=out, stderr=err)
graphviz.backend.CalledProcessError: Command '['dot', '-Tpng', '-O', 'uml']' returned non-zero exit status 1. [stderr: b'Error: uml: syntax error in line 2 scanning a quoted string (missing endquote? longer than 16384?)\nString starting:"];\n}\n\n']
2020-03-22 19:15:55,722 DEBUG graphviz.files write 677 bytes to 'result/uml'
2020-03-22 19:15:55,725 DEBUG graphviz.backend run ['dot', '-Tpng', '-O', 'uml']
2020-03-22 19:15:55,821 DEBUG graphviz.files write 68 bytes to 'result/uml'
2020-03-22 19:15:55,822 DEBUG graphviz.backend run ['dot', '-Tpng', '-O', 'uml']
2020-03-22 19:15:55,833 ERROR __main__ 2uml
Traceback (most recent call last):
  File "/Users/chenjiadong/Documents/funnyCode/PythonRepo/pyuml/main.py", line 89, in do_2uml
    self._render_with_graphviz(dot_string)
  File "/Users/chenjiadong/Documents/funnyCode/PythonRepo/pyuml/main.py", line 151, in _render_with_graphviz
    src.render(format='png', filename="result/uml")
  File "/Users/chenjiadong/Documents/funnyCode/PythonRepo/pyuml/venv/lib/python3.7/site-packages/graphviz/files.py", line 209, in render
    quiet=quiet)
  File "/Users/chenjiadong/Documents/funnyCode/PythonRepo/pyuml/venv/lib/python3.7/site-packages/graphviz/backend.py", line 206, in render
    run(cmd, capture_output=True, cwd=cwd, check=True, quiet=quiet)
  File "/Users/chenjiadong/Documents/funnyCode/PythonRepo/pyuml/venv/lib/python3.7/site-packages/graphviz/backend.py", line 172, in run
    output=out, stderr=err)
graphviz.backend.CalledProcessError: Command '['dot', '-Tpng', '-O', 'uml']' returned non-zero exit status 1. [stderr: b'Error: uml: syntax error in line 2 scanning a quoted string (missing endquote? longer than 16384?)\nString starting:"];\n}\n\n']
2020-03-22 19:19:56,943 DEBUG graphviz.files write 677 bytes to 'result/uml0'
2020-03-22 19:19:56,945 DEBUG graphviz.backend run ['dot', '-Tpng', '-O', 'uml0']
2020-03-22 19:19:57,020 DEBUG graphviz.files write 68 bytes to 'result/uml1'
2020-03-22 19:19:57,020 DEBUG graphviz.backend run ['dot', '-Tpng', '-O', 'uml1']
2020-03-22 19:19:57,031 ERROR __main__ 2uml
Traceback (most recent call last):
  File "/Users/chenjiadong/Documents/funnyCode/PythonRepo/pyuml/main.py", line 90, in do_2uml
    self._render_with_graphviz(index, dot_string)
  File "/Users/chenjiadong/Documents/funnyCode/PythonRepo/pyuml/main.py", line 150, in _render_with_graphviz
    src.render(format='png', filename="result/uml{}".format(index))
  File "/Users/chenjiadong/Documents/funnyCode/PythonRepo/pyuml/venv/lib/python3.7/site-packages/graphviz/files.py", line 209, in render
    quiet=quiet)
  File "/Users/chenjiadong/Documents/funnyCode/PythonRepo/pyuml/venv/lib/python3.7/site-packages/graphviz/backend.py", line 206, in render
    run(cmd, capture_output=True, cwd=cwd, check=True, quiet=quiet)
  File "/Users/chenjiadong/Documents/funnyCode/PythonRepo/pyuml/venv/lib/python3.7/site-packages/graphviz/backend.py", line 172, in run
    output=out, stderr=err)
graphviz.backend.CalledProcessError: Command '['dot', '-Tpng', '-O', 'uml1']' returned non-zero exit status 1. [stderr: b'Error: uml1: syntax error in line 2 scanning a quoted string (missing endquote? longer than 16384?)\nString starting:"];\n}\n\n']
2020-03-22 20:04:10,735 DEBUG graphviz.files write 677 bytes to 'result/uml0'
2020-03-22 20:04:10,738 DEBUG graphviz.backend run ['dot', '-Tpng', '-O', 'uml0']
2020-03-22 20:04:10,856 DEBUG graphviz.files write 69 bytes to 'result/uml1'
2020-03-22 20:04:10,858 DEBUG graphviz.backend run ['dot', '-Tpng', '-O', 'uml1']
2020-03-22 20:04:48,751 DEBUG graphviz.files write 677 bytes to 'result/uml0'
2020-03-22 20:04:48,753 DEBUG graphviz.backend run ['dot', '-Tpng', '-O', 'uml0']
2020-03-22 20:04:48,810 DEBUG graphviz.files write 69 bytes to 'result/uml1'
2020-03-22 20:04:48,810 DEBUG graphviz.backend run ['dot', '-Tpng', '-O', 'uml1']
2020-03-22 20:53:49,390 ERROR __main__ 2uml
Traceback (most recent call last):
  File "/Users/chenjiadong/Documents/funnyCode/PythonRepo/pyuml/main.py", line 91, in do_2uml
    self._render_with_graphviz(index, dot_string)
TypeError: _render_with_graphviz() missing 1 required positional argument: 'dot'
2020-03-22 20:55:16,792 DEBUG graphviz.files write 69 bytes to '/uml0'
2020-03-22 20:55:16,793 ERROR __main__ 2uml
Traceback (most recent call last):
  File "/Users/chenjiadong/Documents/funnyCode/PythonRepo/pyuml/main.py", line 91, in do_2uml
    self._render_with_graphviz(output_path, index, dot_string)
  File "/Users/chenjiadong/Documents/funnyCode/PythonRepo/pyuml/main.py", line 151, in _render_with_graphviz
    src.render(format='png', filename=os.path.join(output_path, "/uml{}".format(index)))
  File "/Users/chenjiadong/Documents/funnyCode/PythonRepo/pyuml/venv/lib/python3.7/site-packages/graphviz/files.py", line 202, in render
    filepath = self.save(filename, directory)
  File "/Users/chenjiadong/Documents/funnyCode/PythonRepo/pyuml/venv/lib/python3.7/site-packages/graphviz/files.py", line 166, in save
    with io.open(filepath, 'w', encoding=self.encoding) as fd:
PermissionError: [Errno 13] Permission denied: '/uml0'
2020-03-22 20:58:30,651 DEBUG graphviz.files write 69 bytes to '/Users/chenjiadong/Documents/funnyCode/PythonRepo/pyuml/test/test_dot_code/uml0'
2020-03-22 20:58:30,654 DEBUG graphviz.backend run ['dot', '-Tpng', '-O', 'uml0']
2020-03-22 20:58:30,726 DEBUG graphviz.files write 179 bytes to '/Users/chenjiadong/Documents/funnyCode/PythonRepo/pyuml/test/test_dot_code/uml1'
2020-03-22 20:58:30,726 DEBUG graphviz.backend run ['dot', '-Tpng', '-O', 'uml1']
2020-03-22 20:58:30,757 DEBUG graphviz.files write 81 bytes to '/Users/chenjiadong/Documents/funnyCode/PythonRepo/pyuml/test/test_dot_code/uml2'
2020-03-22 20:58:30,758 DEBUG graphviz.backend run ['dot', '-Tpng', '-O', 'uml2']
2020-03-22 20:58:30,789 DEBUG graphviz.files write 450 bytes to '/Users/chenjiadong/Documents/funnyCode/PythonRepo/pyuml/test/test_dot_code/uml3'
2020-03-22 20:58:30,790 DEBUG graphviz.backend run ['dot', '-Tpng', '-O', 'uml3']
2020-03-22 20:58:30,821 DEBUG graphviz.files write 677 bytes to '/Users/chenjiadong/Documents/funnyCode/PythonRepo/pyuml/test/test_dot_code/uml4'
2020-03-22 20:58:30,821 DEBUG graphviz.backend run ['dot', '-Tpng', '-O', 'uml4']
2020-03-22 20:58:30,861 DEBUG graphviz.files write 167 bytes to '/Users/chenjiadong/Documents/funnyCode/PythonRepo/pyuml/test/test_dot_code/uml5'
2020-03-22 20:58:30,861 DEBUG graphviz.backend run ['dot', '-Tpng', '-O', 'uml5']
2020-03-22 20:58:30,889 DEBUG graphviz.files write 69 bytes to '/Users/chenjiadong/Documents/funnyCode/PythonRepo/pyuml/test/test_dot_code/uml6'
2020-03-22 20:58:30,889 DEBUG graphviz.backend run ['dot', '-Tpng', '-O', 'uml6']
2020-03-22 21:00:17,358 ERROR __main__ 2uml
Traceback (most recent call last):
  File "/Users/chenjiadong/Documents/funnyCode/PythonRepo/pyuml/main.py", line 87, in do_2uml
    code_string_list = loader.load_from_file_or_directory(input_path)
  File "/Users/chenjiadong/Documents/funnyCode/PythonRepo/pyuml/core/loader.py", line 9, in load_from_file_or_directory
    raise IOError
OSError
2020-03-22 21:09:28,035 DEBUG graphviz.files write 69 bytes to '/Users/chenjiadong/Documents/funnyCode/PythonRepo/pyuml/result/uml0'
2020-03-22 21:09:28,039 DEBUG graphviz.backend run ['dot', '-Tpng', '-O', 'uml0']
2020-03-22 21:09:28,126 DEBUG graphviz.files write 179 bytes to '/Users/chenjiadong/Documents/funnyCode/PythonRepo/pyuml/result/uml1'
2020-03-22 21:09:28,127 DEBUG graphviz.backend run ['dot', '-Tpng', '-O', 'uml1']
2020-03-22 21:09:28,156 DEBUG graphviz.files write 81 bytes to '/Users/chenjiadong/Documents/funnyCode/PythonRepo/pyuml/result/uml2'
2020-03-22 21:09:28,156 DEBUG graphviz.backend run ['dot', '-Tpng', '-O', 'uml2']
2020-03-22 21:09:28,183 DEBUG graphviz.files write 450 bytes to '/Users/chenjiadong/Documents/funnyCode/PythonRepo/pyuml/result/uml3'
2020-03-22 21:09:28,183 DEBUG graphviz.backend run ['dot', '-Tpng', '-O', 'uml3']
2020-03-22 21:09:28,213 DEBUG graphviz.files write 677 bytes to '/Users/chenjiadong/Documents/funnyCode/PythonRepo/pyuml/result/uml4'
2020-03-22 21:09:28,214 DEBUG graphviz.backend run ['dot', '-Tpng', '-O', 'uml4']
2020-03-22 21:09:28,250 DEBUG graphviz.files write 167 bytes to '/Users/chenjiadong/Documents/funnyCode/PythonRepo/pyuml/result/uml5'
2020-03-22 21:09:28,250 DEBUG graphviz.backend run ['dot', '-Tpng', '-O', 'uml5']
2020-03-22 21:09:28,281 DEBUG graphviz.files write 69 bytes to '/Users/chenjiadong/Documents/funnyCode/PythonRepo/pyuml/result/uml6'
2020-03-22 21:09:28,282 DEBUG graphviz.backend run ['dot', '-Tpng', '-O', 'uml6']
2020-03-22 21:10:41,552 DEBUG graphviz.files write 677 bytes to '/Users/chenjiadong/Documents/funnyCode/PythonRepo/pyuml/result/uml0'
2020-03-22 21:10:41,555 DEBUG graphviz.backend run ['dot', '-Tpng', '-O', 'uml0']
2020-03-22 21:32:22,340 ERROR __main__ 2uml
Traceback (most recent call last):
  File "/Users/chenjiadong/Documents/funnyCode/PythonRepo/pyuml/main.py", line 90, in do_2uml
    dot_string = self._parse_to_dot(code_string)
  File "/Users/chenjiadong/Documents/funnyCode/PythonRepo/pyuml/main.py", line 142, in _parse_to_dot
    class_parser = self._parse_to_class_recoard(code_string)
  File "/Users/chenjiadong/Documents/funnyCode/PythonRepo/pyuml/main.py", line 148, in _parse_to_class_recoard
    tree = ast3.parse(code_string)
  File "/Users/chenjiadong/Documents/funnyCode/PythonRepo/pyuml/venv/lib/python3.7/site-packages/typed_ast/ast3.py", line 62, in parse
    return _ast3._parse(source, filename, mode, feature_version)
  File "<unknown>", line 1
    class ErrorClass
                   ^
SyntaxError: invalid syntax
2020-03-22 21:38:35,162 ERROR __main__ 2uml
Traceback (most recent call last):
  File "/Users/chenjiadong/Documents/funnyCode/PythonRepo/pyuml/main.py", line 91, in do_2uml
    self._render_with_graphviz(output_path, index, dot_string)
  File "/Users/chenjiadong/Documents/funnyCode/PythonRepo/pyuml/main.py", line 155, in _render_with_graphviz
    src.render(format='png', filename='uml{}'.format(index), directory=output_path)
  File "/Users/chenjiadong/Documents/funnyCode/PythonRepo/pyuml/venv/lib/python3.7/site-packages/graphviz/files.py", line 202, in render
    filepath = self.save(filename, directory)
  File "/Users/chenjiadong/Documents/funnyCode/PythonRepo/pyuml/venv/lib/python3.7/site-packages/graphviz/files.py", line 161, in save
    tools.mkdirs(filepath)
  File "/Users/chenjiadong/Documents/funnyCode/PythonRepo/pyuml/venv/lib/python3.7/site-packages/graphviz/tools.py", line 31, in mkdirs
    _compat.makedirs(dirname, mode=mode, exist_ok=True)
  File "/Users/chenjiadong/Documents/funnyCode/PythonRepo/pyuml/venv/lib/python3.7/site-packages/graphviz/_compat.py", line 57, in makedirs
    return os.makedirs(name, mode, exist_ok=exist_ok)
  File "/usr/local/Cellar/python/3.7.7/Frameworks/Python.framework/Versions/3.7/lib/python3.7/os.py", line 223, in makedirs
    mkdir(name, mode)
FileExistsError: [Errno 17] File exists: '/Users/chenjiadong/Documents/funnyCode/PythonRepo/pyuml/test/test_py_code/OOPBasicClass.py'
2020-03-22 21:39:25,956 DEBUG graphviz.files write 677 bytes to '/Users/chenjiadong/Documents/funnyCode/PythonRepo/pyuml/test/test_py_code/OOPBasicClass.p/uml0'
2020-03-22 21:39:25,957 DEBUG graphviz.backend run ['dot', '-Tpng', '-O', 'uml0']
2020-03-22 21:53:33,637 DEBUG graphviz.files write 722 bytes to '/Users/chenjiadong/Documents/funnyCode/PythonRepo/pyuml/result/uml0'
2020-03-22 21:53:33,643 DEBUG graphviz.backend run ['dot', '-Tpng', '-O', 'uml0']
2020-03-22 21:54:34,673 DEBUG graphviz.files write 743 bytes to '/Users/chenjiadong/Documents/funnyCode/PythonRepo/pyuml/result/uml0'
2020-03-22 21:54:34,674 DEBUG graphviz.backend run ['dot', '-Tpng', '-O', 'uml0']
2020-03-22 21:55:28,889 DEBUG graphviz.files write 743 bytes to '/Users/chenjiadong/Documents/funnyCode/PythonRepo/pyuml/result/uml0'
2020-03-22 21:55:28,890 DEBUG graphviz.backend run ['dot', '-Tpng', '-O', 'uml0']
2020-03-22 21:55:32,903 ERROR __main__ 2uml
Traceback (most recent call last):
  File "/Users/chenjiadong/Documents/funnyCode/PythonRepo/pyuml/main.py", line 82, in do_2uml
    splitargs = parser.parse_args(shlex.split(args))
  File "/usr/local/Cellar/python/3.7.7/Frameworks/Python.framework/Versions/3.7/lib/python3.7/argparse.py", line 1755, in parse_args
    args, argv = self.parse_known_args(args, namespace)
  File "/usr/local/Cellar/python/3.7.7/Frameworks/Python.framework/Versions/3.7/lib/python3.7/argparse.py", line 1787, in parse_known_args
    namespace, args = self._parse_known_args(args, namespace)
  File "/usr/local/Cellar/python/3.7.7/Frameworks/Python.framework/Versions/3.7/lib/python3.7/argparse.py", line 2022, in _parse_known_args
    ', '.join(required_actions))
  File "/usr/local/Cellar/python/3.7.7/Frameworks/Python.framework/Versions/3.7/lib/python3.7/argparse.py", line 2508, in error
    self.exit(2, _('%(prog)s: error: %(message)s\n') % args)
  File "/usr/local/Cellar/python/3.7.7/Frameworks/Python.framework/Versions/3.7/lib/python3.7/argparse.py", line 2495, in exit
    _sys.exit(status)
SystemExit: 2
2020-03-22 21:55:35,148 ERROR __main__ 2uml
Traceback (most recent call last):
  File "/Users/chenjiadong/Documents/funnyCode/PythonRepo/pyuml/main.py", line 82, in do_2uml
    splitargs = parser.parse_args(shlex.split(args))
  File "/usr/local/Cellar/python/3.7.7/Frameworks/Python.framework/Versions/3.7/lib/python3.7/argparse.py", line 1755, in parse_args
    args, argv = self.parse_known_args(args, namespace)
  File "/usr/local/Cellar/python/3.7.7/Frameworks/Python.framework/Versions/3.7/lib/python3.7/argparse.py", line 1787, in parse_known_args
    namespace, args = self._parse_known_args(args, namespace)
  File "/usr/local/Cellar/python/3.7.7/Frameworks/Python.framework/Versions/3.7/lib/python3.7/argparse.py", line 2022, in _parse_known_args
    ', '.join(required_actions))
  File "/usr/local/Cellar/python/3.7.7/Frameworks/Python.framework/Versions/3.7/lib/python3.7/argparse.py", line 2508, in error
    self.exit(2, _('%(prog)s: error: %(message)s\n') % args)
  File "/usr/local/Cellar/python/3.7.7/Frameworks/Python.framework/Versions/3.7/lib/python3.7/argparse.py", line 2495, in exit
    _sys.exit(status)
SystemExit: 2
2020-03-22 21:55:43,770 ERROR __main__ 2uml
Traceback (most recent call last):
  File "/Users/chenjiadong/Documents/funnyCode/PythonRepo/pyuml/main.py", line 82, in do_2uml
    splitargs = parser.parse_args(shlex.split(args))
  File "/usr/local/Cellar/python/3.7.7/Frameworks/Python.framework/Versions/3.7/lib/python3.7/argparse.py", line 1755, in parse_args
    args, argv = self.parse_known_args(args, namespace)
  File "/usr/local/Cellar/python/3.7.7/Frameworks/Python.framework/Versions/3.7/lib/python3.7/argparse.py", line 1787, in parse_known_args
    namespace, args = self._parse_known_args(args, namespace)
  File "/usr/local/Cellar/python/3.7.7/Frameworks/Python.framework/Versions/3.7/lib/python3.7/argparse.py", line 2022, in _parse_known_args
    ', '.join(required_actions))
  File "/usr/local/Cellar/python/3.7.7/Frameworks/Python.framework/Versions/3.7/lib/python3.7/argparse.py", line 2508, in error
    self.exit(2, _('%(prog)s: error: %(message)s\n') % args)
  File "/usr/local/Cellar/python/3.7.7/Frameworks/Python.framework/Versions/3.7/lib/python3.7/argparse.py", line 2495, in exit
    _sys.exit(status)
SystemExit: 2
2020-03-23 09:29:39,791 ERROR __main__ 2uml
Traceback (most recent call last):
  File "/Users/chenjiadong/Documents/funnyCode/PythonRepo/pyuml/main.py", line 88, in do_2uml
    code_string_list = loader.load_from_file_or_directory(input_path)
  File "/Users/chenjiadong/Documents/funnyCode/PythonRepo/pyuml/core/loader.py", line 9, in load_from_file_or_directory
    raise IOError
OSError
2020-03-23 09:30:52,115 ERROR __main__ 2uml
Traceback (most recent call last):
  File "/Users/chenjiadong/Documents/funnyCode/PythonRepo/pyuml/main.py", line 88, in do_2uml
    code_string_list = loader.load_from_file_or_directory(input_path)
  File "/Users/chenjiadong/Documents/funnyCode/PythonRepo/pyuml/main.py", line 88, in do_2uml
    code_string_list = loader.load_from_file_or_directory(input_path)
  File "_pydevd_bundle/pydevd_cython_darwin_37_64.pyx", line 1470, in _pydevd_bundle.pydevd_cython_darwin_37_64.ThreadTracer.__call__
  File "_pydevd_bundle/pydevd_cython_darwin_37_64.pyx", line 855, in _pydevd_bundle.pydevd_cython_darwin_37_64.PyDBFrame.trace_dispatch
  File "_pydevd_bundle/pydevd_cython_darwin_37_64.pyx", line 846, in _pydevd_bundle.pydevd_cython_darwin_37_64.PyDBFrame.trace_dispatch
  File "_pydevd_bundle/pydevd_cython_darwin_37_64.pyx", line 288, in _pydevd_bundle.pydevd_cython_darwin_37_64.PyDBFrame.do_wait_suspend
  File "/Applications/PyCharm CE.app/Contents/plugins/python-ce/helpers/pydev/pydevd.py", line 1099, in do_wait_suspend
    self._do_wait_suspend(thread, frame, event, arg, suspend_type, from_this_thread)
  File "/Applications/PyCharm CE.app/Contents/plugins/python-ce/helpers/pydev/pydevd.py", line 1114, in _do_wait_suspend
    time.sleep(0.01)
KeyboardInterrupt
2020-03-23 09:31:00,042 ERROR __main__ 2uml
Traceback (most recent call last):
  File "/Users/chenjiadong/Documents/funnyCode/PythonRepo/pyuml/main.py", line 83, in do_2uml
    splitargs = parser.parse_args(shlex.split(args))
  File "/usr/local/Cellar/python/3.7.7/Frameworks/Python.framework/Versions/3.7/lib/python3.7/argparse.py", line 1758, in parse_args
    self.error(msg % ' '.join(argv))
  File "/usr/local/Cellar/python/3.7.7/Frameworks/Python.framework/Versions/3.7/lib/python3.7/argparse.py", line 2508, in error
    self.exit(2, _('%(prog)s: error: %(message)s\n') % args)
  File "/usr/local/Cellar/python/3.7.7/Frameworks/Python.framework/Versions/3.7/lib/python3.7/argparse.py", line 2495, in exit
    _sys.exit(status)
SystemExit: 2
2020-03-23 09:31:19,617 ERROR __main__ 2uml
Traceback (most recent call last):
  File "/Users/chenjiadong/Documents/funnyCode/PythonRepo/pyuml/main.py", line 83, in do_2uml
    splitargs = parser.parse_args(shlex.split(args))
  File "/usr/local/Cellar/python/3.7.7/Frameworks/Python.framework/Versions/3.7/lib/python3.7/argparse.py", line 1758, in parse_args
    self.error(msg % ' '.join(argv))
  File "/usr/local/Cellar/python/3.7.7/Frameworks/Python.framework/Versions/3.7/lib/python3.7/argparse.py", line 2508, in error
    self.exit(2, _('%(prog)s: error: %(message)s\n') % args)
  File "/usr/local/Cellar/python/3.7.7/Frameworks/Python.framework/Versions/3.7/lib/python3.7/argparse.py", line 2495, in exit
    _sys.exit(status)
SystemExit: 2
2020-03-23 09:42:53,680 DEBUG graphviz.files write 69 bytes to '/Users/chenjiadong/Documents/uml0'
2020-03-23 09:42:53,682 DEBUG graphviz.backend run ['dot', '-Tpng', '-O', 'uml0']
2020-03-23 09:42:53,762 DEBUG graphviz.files write 179 bytes to '/Users/chenjiadong/Documents/uml1'
2020-03-23 09:42:53,764 DEBUG graphviz.backend run ['dot', '-Tpng', '-O', 'uml1']
2020-03-23 09:42:53,793 DEBUG graphviz.files write 81 bytes to '/Users/chenjiadong/Documents/uml2'
2020-03-23 09:42:53,794 DEBUG graphviz.backend run ['dot', '-Tpng', '-O', 'uml2']
2020-03-23 09:42:53,820 DEBUG graphviz.files write 450 bytes to '/Users/chenjiadong/Documents/uml3'
2020-03-23 09:42:53,824 DEBUG graphviz.backend run ['dot', '-Tpng', '-O', 'uml3']
2020-03-23 09:42:53,854 ERROR __main__ 2uml
Traceback (most recent call last):
  File "/Users/chenjiadong/Documents/funnyCode/PythonRepo/pyuml/main.py", line 90, in do_2uml
    dot_string = self._parse_to_dot(code_string)
  File "/Users/chenjiadong/Documents/funnyCode/PythonRepo/pyuml/main.py", line 148, in _parse_to_dot
    class_parser = self._parse_to_class_recoard(code_string)
  File "/Users/chenjiadong/Documents/funnyCode/PythonRepo/pyuml/main.py", line 161, in _parse_to_class_recoard
    tree = ast3.parse(code_string)
  File "/Users/chenjiadong/Documents/funnyCode/PythonRepo/pyuml/venv/lib/python3.7/site-packages/typed_ast/ast3.py", line 62, in parse
    return _ast3._parse(source, filename, mode, feature_version)
  File "<unknown>", line 1
    class ErrorClass
                   ^
SyntaxError: invalid syntax
2020-03-23 09:43:38,139 DEBUG graphviz.files write 743 bytes to '/Users/chenjiadong/Documents/uml0'
2020-03-23 09:43:38,140 DEBUG graphviz.backend run ['dot', '-Tpng', '-O', 'uml0']
2020-03-23 09:44:18,379 ERROR __main__ 2uml
Traceback (most recent call last):
  File "/Users/chenjiadong/Documents/funnyCode/PythonRepo/pyuml/main.py", line 90, in do_2uml
    dot_string = self._parse_to_dot(code_string)
  File "/Users/chenjiadong/Documents/funnyCode/PythonRepo/pyuml/main.py", line 149, in _parse_to_dot
    self._persistent_to_file(class_parser.classes_list)
  File "/Users/chenjiadong/Documents/funnyCode/PythonRepo/pyuml/main.py", line 157, in _persistent_to_file
    serializer.serialize(obj)
TypeError: serialize() missing 1 required positional argument: 'obj'
2020-03-23 09:45:27,754 ERROR __main__ 2uml
Traceback (most recent call last):
  File "/Users/chenjiadong/Documents/funnyCode/PythonRepo/pyuml/main.py", line 90, in do_2uml
    dot_string = self._parse_to_dot(code_string)
  File "/Users/chenjiadong/Documents/funnyCode/PythonRepo/pyuml/main.py", line 149, in _parse_to_dot
    self._persistent_to_file(class_parser.classes_list)
  File "/Users/chenjiadong/Documents/funnyCode/PythonRepo/pyuml/main.py", line 158, in _persistent_to_file
    raise SystemError
SystemError
2020-03-23 09:50:14,403 ERROR __main__ load
Traceback (most recent call last):
  File "/usr/local/Cellar/python/3.7.7/Frameworks/Python.framework/Versions/3.7/lib/python3.7/shelve.py", line 111, in __getitem__
    value = self.cache[key]
KeyError: 'Car'

During handling of the above exception, another exception occurred:

Traceback (most recent call last):
  File "/Users/chenjiadong/Documents/funnyCode/PythonRepo/pyuml/main.py", line 108, in do_Load
    result = serializer.deserilize(splitargs.Input)
  File "/Users/chenjiadong/Documents/funnyCode/PythonRepo/pyuml/core/serializer.py", line 18, in deserilize
    data = db[path]
  File "/usr/local/Cellar/python/3.7.7/Frameworks/Python.framework/Versions/3.7/lib/python3.7/shelve.py", line 113, in __getitem__
    f = BytesIO(self.dict[key.encode(self.keyencoding)])
KeyError: b'Car'
2020-03-23 09:51:35,864 DEBUG graphviz.files write 743 bytes to '/Users/chenjiadong/Documents/uml0'
2020-03-23 09:51:35,866 DEBUG graphviz.backend run ['dot', '-Tpng', '-O', 'uml0']
2020-03-23 09:51:52,610 ERROR __main__ load
Traceback (most recent call last):
  File "/Users/chenjiadong/Documents/funnyCode/PythonRepo/pyuml/main.py", line 106, in do_Load
    splitargs = parser.parse_args(shlex.split(args))
  File "/usr/local/Cellar/python/3.7.7/Frameworks/Python.framework/Versions/3.7/lib/python3.7/argparse.py", line 1755, in parse_args
    args, argv = self.parse_known_args(args, namespace)
  File "/usr/local/Cellar/python/3.7.7/Frameworks/Python.framework/Versions/3.7/lib/python3.7/argparse.py", line 1787, in parse_known_args
    namespace, args = self._parse_known_args(args, namespace)
  File "/usr/local/Cellar/python/3.7.7/Frameworks/Python.framework/Versions/3.7/lib/python3.7/argparse.py", line 1993, in _parse_known_args
    start_index = consume_optional(start_index)
  File "/usr/local/Cellar/python/3.7.7/Frameworks/Python.framework/Versions/3.7/lib/python3.7/argparse.py", line 1933, in consume_optional
    take_action(action, args, option_string)
  File "/usr/local/Cellar/python/3.7.7/Frameworks/Python.framework/Versions/3.7/lib/python3.7/argparse.py", line 1861, in take_action
    action(self, namespace, argument_values, option_string)
  File "/usr/local/Cellar/python/3.7.7/Frameworks/Python.framework/Versions/3.7/lib/python3.7/argparse.py", line 1044, in __call__
    parser.exit()
  File "/usr/local/Cellar/python/3.7.7/Frameworks/Python.framework/Versions/3.7/lib/python3.7/argparse.py", line 2495, in exit
    _sys.exit(status)
SystemExit: 0
2020-03-23 09:52:55,726 ERROR __main__ load
Traceback (most recent call last):
  File "/usr/local/Cellar/python/3.7.7/Frameworks/Python.framework/Versions/3.7/lib/python3.7/shelve.py", line 111, in __getitem__
    value = self.cache[key]
KeyError: 'Car'

During handling of the above exception, another exception occurred:

Traceback (most recent call last):
  File "/Users/chenjiadong/Documents/funnyCode/PythonRepo/pyuml/main.py", line 108, in do_Load
    result = serializer.deserilize(splitargs.Input)
  File "/Users/chenjiadong/Documents/funnyCode/PythonRepo/pyuml/core/serializer.py", line 19, in deserilize
    data = db[name]
  File "/usr/local/Cellar/python/3.7.7/Frameworks/Python.framework/Versions/3.7/lib/python3.7/shelve.py", line 113, in __getitem__
    f = BytesIO(self.dict[key.encode(self.keyencoding)])
KeyError: b'Car'
2020-03-23 09:53:19,226 DEBUG graphviz.files write 743 bytes to '/Users/chenjiadong/Documents/uml0'
2020-03-23 09:53:19,226 DEBUG graphviz.backend run ['dot', '-Tpng', '-O', 'uml0']
2020-03-23 10:09:57,409 ERROR __main__ 2uml
Traceback (most recent call last):
  File "/Users/chenjiadong/Documents/funnyCode/PythonRepo/pyuml/main.py", line 90, in do_2uml
    dot_string = self._parse_to_dot(code_string)
  File "/Users/chenjiadong/Documents/funnyCode/PythonRepo/pyuml/main.py", line 126, in _parse_to_dot
    self._persistent_to_file(class_parser.classes_list)
  File "/Users/chenjiadong/Documents/funnyCode/PythonRepo/pyuml/main.py", line 134, in _persistent_to_file
    serializer.serialize(obj)
  File "/Users/chenjiadong/Documents/funnyCode/PythonRepo/pyuml/core/serializer.py", line 13, in serialize
    with shelve.open(self._path) as db:
  File "/usr/local/Cellar/python/3.7.7/Frameworks/Python.framework/Versions/3.7/lib/python3.7/shelve.py", line 243, in open
    return DbfilenameShelf(filename, flag, protocol, writeback)
  File "/usr/local/Cellar/python/3.7.7/Frameworks/Python.framework/Versions/3.7/lib/python3.7/shelve.py", line 227, in __init__
    Shelf.__init__(self, dbm.open(filename, flag), protocol, writeback)
  File "/usr/local/Cellar/python/3.7.7/Frameworks/Python.framework/Versions/3.7/lib/python3.7/dbm/__init__.py", line 94, in open
    return mod.open(file, flag, mode)
_gdbm.error: [Errno 2] No such file or directory
2020-03-23 10:11:54,807 DEBUG graphviz.files write 743 bytes to '/Users/chenjiadong/Documents/uml0'
2020-03-23 10:11:54,810 DEBUG graphviz.backend run ['dot', '-Tpng', '-O', 'uml0']
